Workbook

Sheet Respostas ao formulário 1
A1: Carimbo de data/hora | B1: Endereço de e-mail | C1: Nome Completo: | D1: CPF | E1: Data de Nascimento | F1: Telefone (XX)XXXXX-XXXX | G1: Município que representa: | H1: Você faz parte do: | I1: Que cargo você ocupa na gestão municipal? | J1: Prezado(a) Gestor(a), Se existe algum caso de sucesso da gestão do transporte escolar no seu município, gostaríamos conhecer mais um pouco ao respeito. Por favor, relate de forma sucinta o caso de sucesso no espaço a seguir: | K1: Que cargo você ocupa no CACS-FUNDEB? | L1: Dia | M1: Coluna 1
A2: 45910.6 | B2: moisesco2009@gmail.com | C2: Moises Correia de Oliveira | D2: 001.805.551-62 | E2: 30577 | F2: (66)98452-0550 | G2: Nova Xavantina (MT) | H2: Gestão municipal | I2: Divisão de Manutenção da Frota | L2: =VLOOKUP(G2,'Lista de Cidade'!$A$1:$B$31,2,FALSE) -> 45925 | M2: =IF(D2=D3,1,0) -> 0
A3: 45908.474 | B3: marcosrachid93@gmail.com | C3: Marcos Luiz de Jesus Silva Rachid | D3: 002.145.951-70 | E3: 31275 | F3: (66)99979-9371 | G3: São Félix do Araguaia (MT) | H3: CACS-FUNDEB | K3: Vice presidente | L3: =VLOOKUP(G3,'Lista de Cidade'!$A$1:$B$31,2,FALSE) -> 45925 | M3: =IF(D3=D4,1,0) -> 0
A4: 45916.682 | B4: Wecton.gomes@gmail.com | C4: Wecton Ramos Gomes | D4: 002.528.391-02 | E4: 30535 | F4: (66)99654-9895 | G4: Querência (MT) | H4: Gestão municipal | I4: coordenador de transporte escolar | L4: =VLOOKUP(G4,'Lista de Cidade'!$A$1:$B$31,2,FALSE) -> 45924 | M4: =IF(D4=D5,1,0) -> 0
A5: 45925.358 | B5: josimeire_quimica2011@hotmail.com | C5: Josimeire de Souza Ramos Resende | D5: 004.763.191-02 | E5: 30616 | F5: (66)98433-8186 | G5: Canabrava do Norte (MT) | H5: Gestão municipal | I5: Secretária Municipal de Educação | L5: =VLOOKUP(G5,'Lista de Cidade'!$A$1:$B$31,2,FALSE) -> 45925 | M5: =IF(D5=D6,1,0) -> 0
A6: 45908.654 | B6: rosane.cacs@canarana.edu.mt.gov.br | C6: Rosane Fries | D6: 005.341.921-90 | E6: 29948 | F6: (66)99611-2019 | G6: Canarana (MT) | H6: CACS-FUNDEB | K6: Secretaria | L6: =VLOOKUP(G6,'Lista de Cidade'!$A$1:$B$31,2,FALSE) -> 45924 | M6: =IF(D6=D7,1,0) -> 0
A7: 45908.479 | B7: americoandreia48@gmail.com | C7: Andreia Arruda Américo | D7: 009.151.451-70 | E7: 30150 | F7: (66)98426-3841 | G7: São Félix do Araguaia (MT) | H7: Gestão municipal | I7: Técnica Administrativa do Transporte Escolar | L7: =VLOOKUP(G7,'Lista de Cidade'!$A$1:$B$31,2,FALSE) -> 45925 | M7: =IF(D7=D8,1,0) -> 0
A8: 45910.576 | B8: elisabeteherrmann@gmail.com | C8: Elisabete Rosália Herrmann Brito | D8: 009.756.161-45 | E8: 31291 | F8: (66)98425-1993 | G8: Vila Rica (MT) | H8: CACS-FUNDEB | K8: Membro | L8: =VLOOKUP(G8,'Lista de Cidade'!$A$1:$B$31,2,FALSE) -> 45925 | M8: =IF(D8=D9,1,0) -> 0
A9: 45912.518 | B9: 999214662abc@gmail.com | C9: João Paulo de Sousa | D9: 011.848.541-57 | E9: 29917 | F9: (66)98432-9186 | G9: Água Boa (MT) | H9: Gestão municipal | I9: Gerente Transporte Escolar | J9: Fazer um transporte com qualidade mediante a lei | L9: =VLOOKUP(G9,'Lista de Cidade'!$A$1:$B$31,2,FALSE) -> 45924 | M9: =IF(D9=D10,1,0) -> 0
A10: 45916.686 | B10: prestacaocontas.semec@querencia.mt.gov.br | C10: Leandra Roberta Brum Stefanello | D10: 012.833.230-10 | E10: 31013 | F10: (66)98410-9727 | G10: Querência (MT) | H10: CACS-FUNDEB | K10: Presidente CACS - FUNDEB | L10: =VLOOKUP(G10,'Lista de Cidade'!$A$1:$B$31,2,FALSE) -> 45924 | M10: =IF(D10=D11,1,0) -> 0
A11: 45922.39 | B11: andrea_hora21@hotmail.com | C11: Andrea Paciente Hora | D11: 013.540.821-09 | E11: 31739 | F11: (66)98425-6888 | G11: Vila Rica (MT) | H11: CACS-FUNDEB | K11: Membro | L11: =VLOOKUP(G11,'Lista de Cidade'!$A$1:$B$31,2,FALSE) -> 45925 | M11: =IF(D11=D12,1,0) -> 0
A12: 45918.643 | B12: lidiane.silva@vilarica.edu.mt.gov.br | C12: Lidiane Heimerdinger Silva | D12: 021.210.741-04 | E12: 31683 | F12: (66)98423-5177 | G12: Vila Rica (MT) | H12: Gestão municipal | I12: Técnica | L12: =VLOOKUP(G12,'Lista de Cidade'!$A$1:$B$31,2,FALSE) -> 45925 | M12: =IF(D12=D13,1,0) -> 0
A13: 45910.575 | B13: gleidiane.cruz@luciara.edu.mt.gov.br | C13: Gleidiane Ferreira da Cruz | D13: 021.594.611-13 | E13: 32006 | F13: (66)98427-5175 | G13: Luciara (MT) | H13: CACS-FUNDEB | K13: Presidente do conselho do TRANSPORTE ESCOLAR | L13: =VLOOKUP(G13,'Lista de Cidade'!$A$1:$B$31,2,FALSE) -> 45925 | M13: =IF(D13=D14,1,0) -> 0
A14: 45915.571 | B14: gerayneaquinocorrea@gmail.com | C14: Gerayne Aquino Corrêa | D14: 024.883.761-32 | E14: 32412 | F14: (66)98422-7979 | G14: Araguaiana (MT) | H14: Gestão municipal | I14: secretaria de educação | L14: =VLOOKUP(G14,'Lista de Cidade'!$A$1:$B$31,2,FALSE) -> 45925 | M14: =IF(D14=D15,1,0) -> 0
A15: 45917.361 | B15: daianagym20@hotmail.com | C15: DAIANA AMORIM CUNHA | D15: 031.632.791-39 | E15: 32481 | F15: (66)98439-1428 | G15: Serra Nova Dourada (MT) | H15: Gestão municipal | I15: TECNICA MUNICIPAL DA SME | L15: =VLOOKUP(G15,'Lista de Cidade'!$A$1:$B$31,2,FALSE) -> 45925 | M15: =IF(D15=D16,1,0) -> 0
A16: 45910.396 | B16: thaisensj@hotmail.com | C16: THAISE GEOVANNA PEREIRA SOBRINHO | D16: 038.182.931-63 | E16: 34050 | F16: (66)97400-5419 | G16: Novo São Joaquim (MT) | H16: CACS-FUNDEB | K16: RESPONSAVEL PRESTAÇÃO DE CONTAS | L16: =VLOOKUP(G16,'Lista de Cidade'!$A$1:$B$31,2,FALSE) -> 45924 | M16: =IF(D16=D17,1,0) -> 0
A17: 45916.69 | B17: kellenkleinrossato@gmail.com | C17: , | D17: 038.713.381-09 | E17: 33507 | F17: (66)99714-0657 | G17: Querência (MT) | H17: CACS-FUNDEB | K17: VICE PRESIDENTE | L17: =VLOOKUP(G17,'Lista de Cidade'!$A$1:$B$31,2,FALSE) -> 45924 | M17: =IF(D17=D18,1,0) -> 0
A18: 45924.673 | B18: lorennasouza09.ls@gmail.com | C18: Lorena Pereira de Souza | D18: 042.254.611-90 | E18: 34029 | F18: (66)99241-6958 | G18: Barra do Garças (MT) | H18: Gestão municipal | I18: setor de prestação de contas | L18: =VLOOKUP(G18,'Lista de Cidade'!$A$1:$B$31,2,FALSE) -> 45925 | M18: =IF(D18=D19,1,0) -> 0
A19: 45905.42 | B19: murilovassis@hotmail.com | C19: Murilo Vieira Assis | D19: 043.855.311-02 | E19: 36102 | F19: (66)99664-4772 | G19: Baliza (GO) | H19: Gestão municipal | I19: Assiste Administrativo - Prestação de conta | L19: =VLOOKUP(G19,'Lista de Cidade'!$A$1:$B$31,2,FALSE) -> 45924 | M19: =IF(D19=D20,1,0) -> 0
A20: 45909.384 | B20: joaocarlos.ac621@gmail.com | C20: João Carlos Araujo Rodrigues | D20: 048.318.311-31 | E20: 35699 | F20: (66)99698-6788 | G20: Confresa (MT) | H20: Gestão municipal | I20: Coordenador | L20: =VLOOKUP(G20,'Lista de Cidade'!$A$1:$B$31,2,FALSE) -> 45924 | M20: =IF(D20=D21,1,0) -> 0
A21: 45914.652 | B21: jaklynny2009@hotmail.com | C21: Ketlen Jaklynny Alves dos Santos | D21: 053.782.371-90 | E21: 34708 | F21: (66)99964-3865 | G21: Água Boa (MT) | H21: Gestão municipal | I21: Gerente de projetos e convênios da educação | L21: =VLOOKUP(G21,'Lista de Cidade'!$A$1:$B$31,2,FALSE) -> 45924 | M21: =IF(D21=D22,1,0) -> 0
A22: 45917.364 | B22: caiquematheussnd1@gmail.com | C22: CAIQUE MATHEUS DA SILVA | D22: 055.960.981-75 | E22: 34279 | F22: (66)98446-6322 | G22: Serra Nova Dourada (MT) | H22: CACS-FUNDEB | K22: VICE PRESIDENTE | L22: =VLOOKUP(G22,'Lista de Cidade'!$A$1:$B$31,2,FALSE) -> 45925 | M22: =IF(D22=D23,1,0) -> 0
A23: 45916.687 | B23: kamilifitdance@gmail.com | C23: kamili alexandre | D23: 060.440.811-09 | E23: 38005 | F23: (66)99204-7193 | G23: Querência (MT) | H23: Gestão municipal | I23: técnico administrativo | L23: =VLOOKUP(G23,'Lista de Cidade'!$A$1:$B$31,2,FALSE) -> 45924 | M23: =IF(D23=D24,1,0) -> 0
A24: 45910.434 | B24: osmarilda.teixeira@vilarica.edu.mt.gov.br | C24: Osmarilda Souza Teixeira | D24: 244.225.922-20 | E24: 26199 | F24: (66)98448-5767 | G24: Vila Rica (MT) | H24: CACS-FUNDEB | K24: Membro | L24: =VLOOKUP(G24,'Lista de Cidade'!$A$1:$B$31,2,FALSE) -> 45925 | M24: =IF(D24=D25,1,0) -> 0
A25: 45912.664 | B25: vanianevessilva@hotmail.com | C25: Vânia Aparecida Neves Nogueira | D25: 357.876.668-28 | E25: 32775 | F25: (66)99931-2629 | G25: Água Boa (MT) | H25: CACS-FUNDEB | K25: Tecnica prestação de contas transporte escolar | L25: =VLOOKUP(G25,'Lista de Cidade'!$A$1:$B$31,2,FALSE) -> 45924 | M25: =IF(D25=D26,1,0) -> 0
A26: 45917.469 | B26: lidiaarraes01@hotmail.com | C26: Lídia Arraes de Oliveira | D26: 395.707.701-04 | E26: 22070 | F26: (66)98422-5865 | G26: Araguaiana (MT) | H26: CACS-FUNDEB | K26: Secretaria | L26: =VLOOKUP(G26,'Lista de Cidade'!$A$1:$B$31,2,FALSE) -> 45925 | M26: =IF(D26=D27,1,0) -> 0
A27: 45909.732 | B27: profanilza99@gmail.com | C27: Nilza Darc Rosa | D27: 435.840.551-72 | E27: 24773 | F27: (66)98129-2310 | G27: Novo São Joaquim (MT) | H27: CACS-FUNDEB | K27: Presidente | L27: =VLOOKUP(G27,'Lista de Cidade'!$A$1:$B$31,2,FALSE) -> 45924 | M27: =IF(D27=D28,1,0) -> 0
A28: 45905.633 | B28: elenirafonso@portoalegredonorte.gov.br | C28: Elenir Afonso da Silva | D28: 468.615.561-49 | E28: 45684 | F28: (66)98429-0137 | G28: Porto Alegre do Norte (MT) | H28: Gestão municipal | I28: dirigente municipal | L28: =VLOOKUP(G28,'Lista de Cidade'!$A$1:$B$31,2,FALSE) -> 45924 | M28: =IF(D28=D29,1,0) -> 0
A29: 45917.324 | B29: delcimarvieira2@hotmail.com | C29: Delcimar Vieira Lima | D29: 474.491.361-04 | E29: 24860 | F29: (66)98452-9107 | G29: Canabrava do Norte (MT) | H29: Gestão municipal | I29: Responsavel pelo programa Geoter | L29: =VLOOKUP(G29,'Lista de Cidade'!$A$1:$B$31,2,FALSE) -> 45925 | M29: =IF(D29=D30,1,0) -> 0
A30: 45908.476 | B30: nilusawi@hotmail.com | C30: Nilson Barbosa da Silva | D30: 487.041.561-53 | E30: 25598 | F30: (66)99231-1210 | G30: Santo Antônio do Leste (MT) | H30: Gestão municipal | I30: Secretário Municipal de Educação | L30: =VLOOKUP(G30,'Lista de Cidade'!$A$1:$B$31,2,FALSE) -> 45925 | M30: =IF(D30=D31,1,0) -> 0
A31: 45905.418 | B31: divinomaia13@hotmail.com | C31: Divino Francisco Martins Maia | D31: 514.293.571-34 | E31: 25379 | F31: (66)99603-3961 | G31: Baliza (GO) | H31: CACS-FUNDEB | K31: Técnico da Assessoria pedagógica - membro do CACS Fundeb. | L31: =VLOOKUP(G31,'Lista de Cidade'!$A$1:$B$31,2,FALSE) -> 45924 | M31: =IF(D31=D32,1,0) -> 0
A32: 45905.354 | B32: lisianebionxx@gmail.com | C32: Lisiane Berghahn | D32: 550.245.801-68 | E32: 27515 | F32: (66)99998-9701 | G32: Nova Xavantina (MT) | H32: Gestão municipal | I32: Gerente de Transporte | L32: =VLOOKUP(G32,'Lista de Cidade'!$A$1:$B$31,2,FALSE) -> 45925 | M32: =IF(D32=D33,1,0) -> 0
A33: 45909.424 | B33: coelhocassiogc@gmail.com | C33: Cássio Gomes Coelho | D33: 550.868.881-15 | E33: 25140 | F33: (66)99980-2994 | G33: Confresa (MT) | H33: Gestão municipal | I33: Diretor de transporte escolar | L33: =VLOOKUP(G33,'Lista de Cidade'!$A$1:$B$31,2,FALSE) -> 45924 | M33: =IF(D33=D34,1,0) -> 0
A34: 45909.446 | B34: alexcristian2312@gmail.com | C34: Cristian Alex Lopes de Souza | D34: 555.206.261-20 | E34: 27408 | F34: (66)99975-7560 | G34: Confresa (MT) | H34: CACS-FUNDEB | K34: Conselheiro | L34: =VLOOKUP(G34,'Lista de Cidade'!$A$1:$B$31,2,FALSE) -> 45924 | M34: =IF(D34=D35,1,0) -> 0
A35: 45910.569 | B35: jamil.sales@luciara.mt.edu.gov.br | C35: Jamil Taverny Sales | D35: 569.035.881-91 | E35: 28425 | F35: (66)98458-0193 | G35: Luciara (MT) | H35: Gestão municipal | I35: Secretário Municipal de Educação | J35: O atendimento de todo o corpo dicente do bosso municipio através do transporte escolar. | L35: =VLOOKUP(G35,'Lista de Cidade'!$A$1:$B$31,2,FALSE) -> 45925 | M35: =IF(D35=D36,1,0) -> 0
A36: 45905.432 | B36: lanusseblz@hotmail.com | C36: Alexandre Lanusse Pereira Dias | D36: 617.215.221-15 | E36: 26507 | F36: (66)99988-9196 | G36: Baliza (GO) | H36: Gestão municipal | I36: Tecnico Operador: SETE Transporte escolar | L36: =VLOOKUP(G36,'Lista de Cidade'!$A$1:$B$31,2,FALSE) -> 45924 | M36: =IF(D36=D37,1,0) -> 0
A37: 45911.548 | B37: mcgfabio@gmail.com | C37: Fábio Pinto de Oliveira | D37: 643.714.921-34 | E37: 26116 | F37: (62)99987-2626 | G37: Montes Claros de Goiás (GO) | H37: CACS-FUNDEB | K37: vice presidente | L37: =VLOOKUP(G37,'Lista de Cidade'!$A$1:$B$31,2,FALSE) -> 45924 | M37: =IF(D37=D38,1,0) -> 0
A38: 45908.361 | B38: ronnysantos4@hotmail.com | C38: Ronivaldo Assis Santos | D38: 713.542.636-34 | E38: 24930 | F38: (62)99804-9680 | G38: Montes Claros de Goiás (GO) | H38: Gestão municipal | I38: Coordenador do Transporte Escolar | J38: Não tenho | L38: =VLOOKUP(G38,'Lista de Cidade'!$A$1:$B$31,2,FALSE) -> 45924 | M38: =IF(D38=D39,1,0) -> 0
A39: 45905.706 | B39: clayton.oliva@edu.mt.gov.br | C39: Clayton Gonçalves Oliva | D39: 719.914.681-72 | E39: 29615 | F39: (66)98447-3124 | G39: Novo Santo Antônio (MT) | H39: Gestão municipal | I39: Coordenador de Transporte Escolar | L39: =VLOOKUP(G39,'Lista de Cidade'!$A$1:$B$31,2,FALSE) -> 45925 | M39: =IF(D39=D40,1,0) -> 0
A40: 45918.886 | B40: Katereginaps2@hotmail.com | C40: Kate Regina Paulo da Silva | D40: 762.162.171-00 | E40: 27522 | F40: (66)98437-1064 | G40: Bom Jesus do Araguaia (MT) | H40: Gestão municipal | I40: Técnico Administrativo | L40: =VLOOKUP(G40,'Lista de Cidade'!$A$1:$B$31,2,FALSE) -> 45925 | M40: =IF(D40=D41,1,0) -> 0
...

Sheet Confirmação
A1: Carimbo de data/hora | B1: Endereço de e-mail | C1: Nome Completo: | D1: CPF | E1: Data de Nascimento | F1: Telefone (XX)XXXXX-XXXX | G1: Município que representa: | H1: Você faz parte do: | I1: Que cargo você ocupa na gestão municipal? | J1: Prezado(a) Gestor(a), Se existe algum caso de sucesso da gestão do transporte escolar no seu município, gostaríamos conhecer mais um pouco ao respeito. Por favor, relate de forma sucinta o caso de sucesso no espaço a seguir: | K1: Que cargo você ocupa no CACS-FUNDEB? | L1: Dia
A2: 45905.418 | B2: divinomaia13@hotmail.com | C2: Divino Francisco Martins Maia | D2: 514.293.571-34 | E2: 25379 | F2: (66)99603-3961 | G2: Baliza (GO) | H2: CACS-FUNDEB | K2: Técnico da Assessoria pedagógica - membro do CACS Fundeb. | L2: 45924
A3: 45905.42 | B3: murilovassis@hotmail.com | C3: Murilo Vieira Assis | D3: 043.855.311-02 | E3: 36102 | F3: (66)99664-4772 | G3: Baliza (GO) | H3: Gestão municipal | I3: Assiste Administrativo - Prestação de conta | L3: 45924
A4: 45905.432 | B4: lanusseblz@hotmail.com | C4: Alexandre Lanusse Pereira Dias | D4: 617.215.221-15 | E4: 26507 | F4: (66)99988-9196 | G4: Baliza (GO) | H4: Gestão municipal | I4: Tecnico Operador: SETE Transporte escolar | L4: 45924
A5: 45905.593 | B5: cintiaraimundo70@gmail.com | C5: Cintia de Almeida Oliveira Raimundo | D5: 956.523.701-06 | E5: 30047 | F5: (66)99978-8010 | G5: Canarana (MT) | H5: Gestão municipal | I5: Gestor Educacional (técnica do Transporte Escolar) | L5: 45924
A6: 45905.597 | B6: admin.transporte@canarana.edu.mt.gov.br | C6: Gabriel Kasprczak da Silva | D6: 935.418.991-15 | E6: 30299 | F6: (66)99982-2518 | G6: Canarana (MT) | H6: Gestão municipal | I6: Coordenador Transporte Escolar | L6: 45924
A7: 45905.633 | B7: elenirafonso@portoalegredonorte.gov.br | C7: Elenir Afonso da Silva | D7: 468.615.561-49 | E7: 45684 | F7: (66)98429-0137 | G7: Porto Alegre do Norte (MT) | H7: Gestão municipal | I7: dirigente municipal | L7: 45924
A8: 45908.361 | B8: ronnysantos4@hotmail.com | C8: Ronivaldo Assis Santos | D8: 713.542.636-34 | E8: 24930 | F8: (62)99804-9680 | G8: Montes Claros de Goiás (GO) | H8: Gestão municipal | I8: Coordenador do Transporte Escolar | J8: Não tenho | L8: 45924
A9: 45908.654 | B9: rosane.cacs@canarana.edu.mt.gov.br | C9: Rosane Fries | D9: 005.341.921-90 | E9: 29948 | F9: (66)99611-2019 | G9: Canarana (MT) | H9: CACS-FUNDEB | K9: Secretaria | L9: 45924
A10: 45908.665 | B10: cintiaraimundo70@gmail.com | C10: Cintia de Almeida Oliveira Raimundo | D10: 956.523.701-06 | E10: 30047 | F10: (66)99978-8010 | G10: Canarana (MT) | H10: Gestão municipal | I10: Gestor Educacional (Técnico do Transporte Escolar) | L10: 45924
A11: 45908.671 | B11: admin.transporte@canarana.edu.mt.gov.br | C11: Gabriel Kasprczak da Silva | D11: 935.418.991-15 | E11: 30299 | F11: (66)99982-2518 | G11: Canarana (MT) | H11: Gestão municipal | I11: Coordenador Transporte Escolar | L11: 45924
A12: 45909.384 | B12: joaocarlos.ac621@gmail.com | C12: João Carlos Araujo Rodrigues | D12: 048.318.311-31 | E12: 35699 | F12: (66)99698-6788 | G12: Confresa (MT) | H12: Gestão municipal | I12: Coordenador | L12: 45924
A13: 45909.424 | B13: coelhocassiogc@gmail.com | C13: Cássio Gomes Coelho | D13: 550.868.881-15 | E13: 25140 | F13: (66)99980-2994 | G13: Confresa (MT) | H13: Gestão municipal | I13: Diretor de transporte escolar | L13: 45924
A14: 45909.446 | B14: alexcristian2312@gmail.com | C14: Cristian Alex Lopes de Souza | D14: 555.206.261-20 | E14: 27408 | F14: (66)99975-7560 | G14: Confresa (MT) | H14: CACS-FUNDEB | K14: Conselheiro | L14: 45924
A15: 45909.587 | B15: celsonsousadasilva@hotmail.com | C15: Celson Sousa da Silva | D15: 951.230.831-20 | E15: 29800 | F15: (66)98445-7805 | G15: Confresa (MT) | H15: CACS-FUNDEB | K15: Conselheiro | L15: 45924
A16: 45909.732 | B16: profanilza99@gmail.com | C16: Nilza Darc Rosa | D16: 435.840.551-72 | E16: 24773 | F16: (66)98129-2310 | G16: Novo São Joaquim (MT) | H16: CACS-FUNDEB | K16: Presidente | L16: 45924
A17: 45910.396 | B17: thaisensj@hotmail.com | C17: THAISE GEOVANNA PEREIRA SOBRINHO | D17: 038.182.931-63 | E17: 34050 | F17: (66)97400-5419 | G17: Novo São Joaquim (MT) | H17: CACS-FUNDEB | K17: RESPONSAVEL PRESTAÇÃO DE CONTAS | L17: 45924
A18: 45910.404 | B18: thiagonsj@gmail.com | C18: THIAGO DE MACEDO FIGUEIRA | D18: 999.089.301-25 | E18: 31175 | F18: (66)98140-9218 | G18: Novo São Joaquim (MT) | H18: Gestão municipal | I18: SECRETARIO MUNICIPAL DE EDUCAÇÃO E CULTURA | L18: 45924
A19: 45910.412 | B19: aguiarrosirene8@gmail.com | C19: Rosirene Alves Martins Aguiar | D19: 921.708.031-49 | E19: 27490 | F19: (66)98147-1011 | G19: Novo São Joaquim (MT) | H19: Gestão municipal | I19: Responsavel pelo sistema do transporte escolar | L19: 45924
A20: 45910.439 | B20: valfliene@gmail.com | C20: Valfliene Aparecida de Melo Bética | D20: 889.447.351-15 | E20: 29786 | F20: (66)99984-4248 | G20: Ribeirão Cascalheira (MT) | H20: Gestão municipal | I20: Técnica Administrativa Escolar | L20: 45924
A21: 45910.461 | B21: rejanebgd@hotmail.com | C21: Rejane Evangelista Galvão | D21: 978.403.941-91 | E21: 30307 | F21: (66)99221-1130 | G21: Pontal do Araguaia (MT) | H21: CACS-FUNDEB | K21: Representante dos Técnicos Administrativos das Escolas Publicas | L21: 45924
A22: 45911.307 | B22: santosmachado3@hotmail.com | C22: Mauro Machado dos Santos | D22: 884.725.401-97 | E22: 27731 | F22: (66)99977-1054 | G22: Ribeirão Cascalheira (MT) | H22: CACS-FUNDEB | K22: Conselheiro | L22: 45924
A23: 45911.548 | B23: mcgfabio@gmail.com | C23: Fábio Pinto de Oliveira | D23: 643.714.921-34 | E23: 26116 | F23: (62)99987-2626 | G23: Montes Claros de Goiás (GO) | H23: CACS-FUNDEB | K23: vice presidente | L23: 45924
A24: 45912.431 | B24: marialeandro@portoalegredonorte.mt.gov.br | C24: MARIA JOSE LEANDRO DE ALMEIDA OLIVEIRA | D24: 987.429.811-15 | E24: 30578 | F24: (66)98418-4363 | G24: Porto Alegre do Norte (MT) | H24: CACS-FUNDEB | K24: Representante de Servidor técnico administrativo | L24: 45924
A25: 45912.518 | B25: 999214662abc@gmail.com | C25: João Paulo de Sousa | D25: 011.848.541-57 | E25: 29917 | F25: (66)98432-9186 | G25: Água Boa (MT) | H25: Gestão municipal | I25: Gerente Transporte Escolar | J25: Fazer um transporte com qualidade mediante a lei | L25: 45924
A26: 45912.664 | B26: vanianevessilva@hotmail.com | C26: Vânia Aparecida Neves Nogueira | D26: 357.876.668-28 | E26: 32775 | F26: (66)99931-2629 | G26: Água Boa (MT) | H26: CACS-FUNDEB | K26: Tecnica prestação de contas transporte escolar | L26: 45924
A27: 45914.652 | B27: jaklynny2009@hotmail.com | C27: Ketlen Jaklynny Alves dos Santos | D27: 053.782.371-90 | E27: 34708 | F27: (66)99964-3865 | G27: Água Boa (MT) | H27: Gestão municipal | I27: Gerente de projetos e convênios da educação | L27: 45924
A28: 45915.37 | B28: elainecintia2015@gmail.com | C28: Elaine Cintia de Souza | D28: 982.434.111-00 | E28: 30146 | F28: (66)99204-2256 | G28: Pontal do Araguaia (MT) | H28: Gestão municipal | I28: Assessora Pedagógica | L28: 45924
A29: 45916.682 | B29: Wecton.gomes@gmail.com | C29: Wecton Ramos Gomes | D29: 002.528.391-02 | E29: 30535 | F29: (66)99654-9895 | G29: Querência (MT) | H29: Gestão municipal | I29: coordenador de transporte escolar | L29: 45924
A30: 45916.686 | B30: prestacaocontas.semec@querencia.mt.gov.br | C30: Leandra Roberta Brum Stefanello | D30: 012.833.230-10 | E30: 31013 | F30: (66)98410-9727 | G30: Querência (MT) | H30: CACS-FUNDEB | K30: Presidente CACS - FUNDEB | L30: 45924
A31: 45916.687 | B31: kamilifitdance@gmail.com | C31: kamili alexandre | D31: 060.440.811-09 | E31: 38005 | F31: (66)99204-7193 | G31: Querência (MT) | H31: Gestão municipal | I31: técnico administrativo | L31: 45924
A32: 45916.69 | B32: kellenkleinrossato@gmail.com | C32: , | D32: 038.713.381-09 | E32: 33507 | F32: (66)99714-0657 | G32: Querência (MT) | H32: CACS-FUNDEB | K32: VICE PRESIDENTE | L32: 45924
A33: 45917.324 | B33: delcimarvieira2@hotmail.com | C33: Delcimar Vieira Lima | D33: 474.491.361-04 | E33: 24860 | F33: (66)98452-9107 | G33: Canabrava do Norte (MT) | H33: Gestão municipal | I33: Responsavel pelo programa Geoter | L33: 45924
A34: 45919.583 | B34: simonerego_cbn@hotmail.com | C34: Simone da Silva Rêgo de Sousa | D34: 767.007.393-49 | E34: 27939 | F34: (66)98126-3476 | G34: Canabrava do Norte (MT) | H34: CACS-FUNDEB | K34: Suplente | L34: 45924
A35: 45905.354 | B35: lisianebionxx@gmail.com | C35: Lisiane Berghahn | D35: 550.245.801-68 | E35: 27515 | F35: (66)99998-9701 | G35: Nova Xavantina (MT) | H35: Gestão municipal | I35: Gerente de Transporte | L35: 45925
A36: 45905.706 | B36: clayton.oliva@edu.mt.gov.br | C36: Clayton Gonçalves Oliva | D36: 719.914.681-72 | E36: 29615 | F36: (66)98447-3124 | G36: Novo Santo Antônio (MT) | H36: Gestão municipal | I36: Coordenador de Transporte Escolar | L36: 45925
A37: 45908.469 | B37: marcosrachid93@gmail.com | C37: Marcos Luiz de Jesus Silva Rachid | D37: 002.145.951-70 | E37: 31275 | F37: (66)98426-3841 | G37: São Félix do Araguaia (MT) | H37: CACS-FUNDEB | K37: Vice Presidente | L37: 45925
A38: 45908.474 | B38: marcosrachid93@gmail.com | C38: Marcos Luiz de Jesus Silva Rachid | D38: 002.145.951-70 | E38: 31275 | F38: (66)99979-9371 | G38: São Félix do Araguaia (MT) | H38: CACS-FUNDEB | K38: Vice presidente | L38: 45925
A39: 45908.476 | B39: nilusawi@hotmail.com | C39: Nilson Barbosa da Silva | D39: 487.041.561-53 | E39: 25598 | F39: (66)99231-1210 | G39: Santo Antônio do Leste (MT) | H39: Gestão municipal | I39: Secretário Municipal de Educação | L39: 45925
A40: 45908.479 | B40: americoandreia48@gmail.com | C40: Andreia Arruda Américo | D40: 009.151.451-70 | E40: 30150 | F40: (66)98426-3841 | G40: São Félix do Araguaia (MT) | H40: Gestão municipal | I40: Técnica Administrativa do Transporte Escolar | L40: 45925
...

Sheet Lista de Cidade
A1: Cidade | B1: Data
A2: Aragarças (GO) | B2: 45924
A3: Baliza (GO) | B3: 45924
A4: Bom Jardim de Goiás (GO) | B4: 45924
A5: Montes Claros de Goiás (GO) | B5: 45924
A6: Água Boa (MT) | B6: 45924
A7: Canabrava do Norte (MT) | B7: 45925
A8: Canarana (MT) | B8: 45924
A9: Cocalinho (MT) | B9: 45924
A10: Confresa (MT) | B10: 45924
A11: Gaúcha do Norte (MT) | B11: 45924
A12: Novo São Joaquim (MT) | B12: 45924
A13: Pontal do Araguaia (MT) | B13: 45924
... A31: Vila Rica (MT) | B31: 45925

Sheet Controle
A1: ID | B1: NOME | C1: DIST(km) | D1: CACS-FUNDEB | E1: Gestão municipal | H1: Responsável | I1: Situação
B2: Água Boa (MT) | D2: =COUNTIFS('Respostas ao formulário 1'!$H$2:$H$121,$D$1,'Respostas ao formulário 1'!$G$2:$G$121,$B2) -> 1 | E2: =COUNTIFS('Respostas ao formulário 1'!$H$2:$H$121,$E$1,'Respostas ao formulário 1'!$G$2:$G$121,$B2) -> 2 | G2: =CONCATENATE(D2, "/", E2) -> 1/2 | H2: Ângela | I2: inscrição feita
B3: Alto Boa Vista (MT) | D3: =COUNTIFS('Respostas ao formulário 1'!$H$2:$H$121,$D$1,'Respostas ao formulário 1'!$G$2:$G$121,$B3) -> 0 | E3: =COUNTIFS('Respostas ao formulário 1'!$H$2:$H$121,$E$1,'Respostas ao formulário 1'!$G$2:$G$121,$B3) -> 0 | G3: =CONCATENATE(D3, "/", E3) -> 0/0 | H3: Ângela | I3: Contato realizado via WhatsApp
B4: Aragarças (GO) | D4: =COUNTIFS('Respostas ao formulário 1'!$H$2:$H$121,$D$1,'Respostas ao formulário 1'!$G$2:$G$121,$B4) -> 0 | E4: =COUNTIFS('Respostas ao formulário 1'!$H$2:$H$121,$E$1,'Respostas ao formulário 1'!$G$2:$G$121,$B4) -> 0 | G4: =CONCATENATE(D4, "/", E4) -> 0/0 | H4: Ângela | I4: Ligação feita em vários números, mas sem sucesso (atendimento)
B5: Araguaiana (MT) | D5: =COUNTIFS('Respostas ao formulário 1'!$H$2:$H$121,$D$1,'Respostas ao formulário 1'!$G$2:$G$121,$B5) -> 1 | E5: =COUNTIFS('Respostas ao formulário 1'!$H$2:$H$121,$E$1,'Respostas ao formulário 1'!$G$2:$G$121,$B5) -> 1 | G5: =CONCATENATE(D5, "/", E5) -> 1/1 | H5: Ângela | I5: inscrição feita | J5: E-mail geraynearquino@araguaiana.mt.gov.br
B6: Baliza (GO) | D6: =COUNTIFS('Respostas ao formulário 1'!$H$2:$H$121,$D$1,'Respostas ao formulário 1'!$G$2:$G$121,$B6) -> 1 | E6: =COUNTIFS('Respostas ao formulário 1'!$H$2:$H$121,$E$1,'Respostas ao formulário 1'!$G$2:$G$121,$B6) -> 2 | G6: =CONCATENATE(D6, "/", E6) -> 1/2 | H6: Ângela | I6: inscrição feita
B7: Barra do Garças (MT) | D7: =COUNTIFS('Respostas ao formulário 1'!$H$2:$H$121,$D$1,'Respostas ao formulário 1'!$G$2:$G$121,$B7) -> 0 | E7: =COUNTIFS('Respostas ao formulário 1'!$H$2:$H$121,$E$1,'Respostas ao formulário 1'!$G$2:$G$121,$B7) -> 1 | G7: =CONCATENATE(D7, "/", E7) -> 0/1 | H7: Ângela | I7: Ligação feita em vários números, mas sem sucesso (atendimento) | J7: smeel@barradogarcas.mt.gov.br
B8: Bom Jardim de Goiás (GO) | D8: =COUNTIFS('Respostas ao formulário 1'!$H$2:$H$121,$D$1,'Respostas ao formulário 1'!$G$2:$G$121,$B8) -> 0 | E8: =COUNTIFS('Respostas ao formulário 1'!$H$2:$H$121,$E$1,'Respostas ao formulário 1'!$G$2:$G$121,$B8) -> 0 | G8: =CONCATENATE(D8, "/", E8) -> 0/0 | H8: Ângela | I8: Ligação feita em vários números, mas sem sucesso (atendimento) | J8: cacs.fundeb@bomjardim.go.gov.br
B9: Bom Jesus do Araguaia (MT) | D9: =COUNTIFS('Respostas ao formulário 1'!$H$2:$H$121,$D$1,'Respostas ao formulário 1'!$G$2:$G$121,$B9) -> 0 | E9: =COUNTIFS('Respostas ao formulário 1'!$H$2:$H$121,$E$1,'Respostas ao formulário 1'!$G$2:$G$121,$B9) -> 3 | G9: =CONCATENATE(D9, "/", E9) -> 0/3 | H9: Ângela | I9: inscrição feita
B10: Campinápolis (MT) | D10: =COUNTIFS('Respostas ao formulário 1'!$H$2:$H$121,$D$1,'Respostas ao formulário 1'!$G$2:$G$121,$B10) -> 0 | E10: =COUNTIFS('Respostas ao formulário 1'!$H$2:$H$121,$E$1,'Respostas ao formulário 1'!$G$2:$G$121,$B10) -> 0 | G10: =CONCATENATE(D10, "/", E10) -> 0/0 | H10: Ângela | I10: Ligação feita em vários números, mas sem sucesso (atendimento) | J10: cacscamp@hotmail.com
B11: Canabrava do Norte (MT) | D11: =COUNTIFS('Respostas ao formulário 1'!$H$2:$H$121,$D$1,'Respostas ao formulário 1'!$G$2:$G$121,$B11) -> 1 | E11: =COUNTIFS('Respostas ao formulário 1'!$H$2:$H$121,$E$1,'Respostas ao formulário 1'!$G$2:$G$121,$B11) -> 2 | G11: =CONCATENATE(D11, "/", E11) -> 1/2 | H11: Ângela | I11: inscrição feita
B12: Canarana (MT) | D12: =COUNTIFS('Respostas ao formulário 1'!$H$2:$H$121,$D$1,'Respostas ao formulário 1'!$G$2:$G$121,$B12) -> 1 | E12: =COUNTIFS('Respostas ao formulário 1'!$H$2:$H$121,$E$1,'Respostas ao formulário 1'!$G$2:$G$121,$B12) -> 2 | G12: =CONCATENATE(D12, "/", E12) -> 1/2 | H12: Ana Paula | I12: inscrição feita
B13: Cocalinho (MT) | D13: =COUNTIFS('Respostas ao formulário 1'!$H$2:$H$121,$D$1,'Respostas ao formulário 1'!$G$2:$G$121,$B13) -> 0 | E13: =COUNTIFS('Respostas ao formulário 1'!$H$2:$H$121,$E$1,'Respostas ao formulário 1'!$G$2:$G$121,$B13) -> 0 | G13: =CONCATENATE(D13, "/", E13) -> 0/0 | H13: Ana Paula | I13: Ligação feita em vários números, mas sem sucesso (atendimento)
B14: Confresa (MT) | D14: =COUNTIFS('Respostas ao formulário 1'!$H$2:$H$121,$D$1,'Respostas ao formulário 1'!$G$2:$G$121,$B14) -> 2 | E14: =COUNTIFS('Respostas ao formulário 1'!$H$2:$H$121,$E$1,'Respostas ao formulário 1'!$G$2:$G$121,$B14) -> 2 | G14: =CONCATENATE(D14, "/", E14) -> 2/2 | H14: Ana Paula | I14: Situação
B15: Gaúcha do Norte (MT) | D15: =COUNTIFS('Respostas ao formulário 1'!$H$2:$H$121,$D$1,'Respostas ao formulário 1'!$G$2:$G$121,$B15) -> 0 | E15: =COUNTIFS('Respostas ao formulário 1'!$H$2:$H$121,$E$1,'Respostas ao formulário 1'!$G$2:$G$121,$B15) -> 0 | G15: =CONCATENATE(D15, "/", E15) -> 0/0 | H15: Ana Paula | I15: Ligação feita em vários números, mas sem sucesso (atendimento)
B16: General Carneiro (MT) | D16: =COUNTIFS('Respostas ao formulário 1'!$H$2:$H$121,$D$1,'Respostas ao formulário 1'!$G$2:$G$121,$B16) -> 0 | E16: =COUNTIFS('Respostas ao formulário 1'!$H$2:$H$121,$E$1,'Respostas ao formulário 1'!$G$2:$G$121,$B16) -> 0 | G16: =CONCATENATE(D16, "/", E16) -> 0/0 | H16: Ana Paula | I16: Ligação feita em vários números, mas sem sucesso (atendimento)
B17: Luciara (MT) | D17: =COUNTIFS('Respostas ao formulário 1'!$H$2:$H$121,$D$1,'Respostas ao formulário 1'!$G$2:$G$121,$B17) -> 1 | E17: =COUNTIFS('Respostas ao formulário 1'!$H$2:$H$121,$E$1,'Respostas ao formulário 1'!$G$2:$G$121,$B17) -> 1 | G17: =CONCATENATE(D17, "/", E17) -> 1/1 | H17: Ana Paula | I17: Ligação feita em vários números, mas sem sucesso (atendimento)
B18: Montes Claros de Goiás (GO) | D18: =COUNTIFS('Respostas ao formulário 1'!$H$2:$H$121,$D$1,'Respostas ao formulário 1'!$G$2:$G$121,$B18) -> 1 | E18: =COUNTIFS('Respostas ao formulário 1'!$H$2:$H$121,$E$1,'Respostas ao formulário 1'!$G$2:$G$121,$B18) -> 1 | G18: =CONCATENATE(D18, "/", E18) -> 1/1 | H18: Ana Paula | I18: inscrição feita
B19: Nova Nazaré (MT) | D19: =COUNTIFS('Respostas ao formulário 1'!$H$2:$H$121,$D$1,'Respostas ao formulário 1'!$G$2:$G$121,$B19) -> 0 | E19: =COUNTIFS('Respostas ao formulário 1'!$H$2:$H$121,$E$1,'Respostas ao formulário 1'!$G$2:$G$121,$B19) -> 0 | G19: =CONCATENATE(D19, "/", E19) -> 0/0 | H19: Ana Paula
B20: Nova Xavantina (MT) | D20: =COUNTIFS('Respostas ao formulário 1'!$H$2:$H$121,$D$1,'Respostas ao formulário 1'!$G$2:$G$121,$B20) -> 0 | E20: =COUNTIFS('Respostas ao formulário 1'!$H$2:$H$121,$E$1,'Respostas ao formulário 1'!$G$2:$G$121,$B20) -> 2 | G20: =CONCATENATE(D20, "/", E20) -> 0/2 | H20: Ana Paula | I20: inscrição feita
B21: Novo Santo Antônio (MT) | D21: =COUNTIFS('Respostas ao formulário 1'!$H$2:$H$121,$D$1,'Respostas ao formulário 1'!$G$2:$G$121,$B21) -> 0 | E21: =COUNTIFS('Respostas ao formulário 1'!$H$2:$H$121,$E$1,'Respostas ao formulário 1'!$G$2:$G$121,$B21) -> 1 | G21: =CONCATENATE(D21, "/", E21) -> 0/1 | H21: Ana Paula | I21: inscrição feita
B22: Novo São Joaquim (MT) | D22: =COUNTIFS('Respostas ao formulário 1'!$H$2:$H$121,$D$1,'Respostas ao formulário 1'!$G$2:$G$121,$B22) -> 2 | E22: =COUNTIFS('Respostas ao formulário 1'!$H$2:$H$121,$E$1,'Respostas ao formulário 1'!$G$2:$G$121,$B22) -> 2 | G22: =CONCATENATE(D22, "/", E22) -> 2/2 | H22: Kariny | I22: Contato realizado via Whatzapp aguardando retorno.
B23: Pontal do Araguaia (MT) | D23: =COUNTIFS('Respostas ao formulário 1'!$H$2:$H$121,$D$1,'Respostas ao formulário 1'!$G$2:$G$121,$B23) -> 1 | E23: =COUNTIFS('Respostas ao formulário 1'!$H$2:$H$121,$E$1,'Respostas ao formulário 1'!$G$2:$G$121,$B23) -> 1 | G23: =CONCATENATE(D23, "/", E23) -> 1/1 | H23: Kariny | I23: Contato via WhatsApp, Aguardando autorização do Prefeito para concessão de diárias, necessária ao deslocamento da gestão do município a capacitação.
B24: Porto Alegre do Norte (MT) | D24: =COUNTIFS('Respostas ao formulário 1'!$H$2:$H$121,$D$1,'Respostas ao formulário 1'!$G$2:$G$121,$B24) -> 1 | E24: =COUNTIFS('Respostas ao formulário 1'!$H$2:$H$121,$E$1,'Respostas ao formulário 1'!$G$2:$G$121,$B24) -> 1 | G24: =CONCATENATE(D24, "/", E24) -> 1/1 | H24: Kariny
B25: Querência (MT) | D25: =COUNTIFS('Respostas ao formulário 1'!$H$2:$H$121,$D$1,'Respostas ao formulário 1'!$G$2:$G$121,$B25) -> 2 | E25: =COUNTIFS('Respostas ao formulário 1'!$H$2:$H$121,$E$1,'Respostas ao formulário 1'!$G$2:$G$121,$B25) -> 2 | G25: =CONCATENATE(D25, "/", E25) -> 2/2 | H25: Kariny | I25: Sem contato, tentativas via telefone, Whatzapp e Instagram.
B26: Ribeirão Cascalheira (MT) | D26: =COUNTIFS('Respostas ao formulário 1'!$H$2:$H$121,$D$1,'Respostas ao formulário 1'!$G$2:$G$121,$B26) -> 1 | E26: =COUNTIFS('Respostas ao formulário 1'!$H$2:$H$121,$E$1,'Respostas ao formulário 1'!$G$2:$G$121,$B26) -> 1 | G26: =CONCATENATE(D26, "/", E26) -> 1/1 | H26: Kariny | I26: Sem contato, tentativas via telefone e Instagram.
B27: Santa Terezinha (MT) | D27: =COUNTIFS('Respostas ao formulário 1'!$H$2:$H$121,$D$1,'Respostas ao formulário 1'!$G$2:$G$121,$B27) -> 0 | E27: =COUNTIFS('Respostas ao formulário 1'!$H$2:$H$121,$E$1,'Respostas ao formulário 1'!$G$2:$G$121,$B27) -> 0 | G27: =CONCATENATE(D27, "/", E27) -> 0/0 | H27: Kariny | I27: Contato realizado via Whatzapp aguardando retorno
B28: Santo Antônio do Leste (MT) | D28: =COUNTIFS('Respostas ao formulário 1'!$H$2:$H$121,$D$1,'Respostas ao formulário 1'!$G$2:$G$121,$B28) -> 0 | E28: =COUNTIFS('Respostas ao formulário 1'!$H$2:$H$121,$E$1,'Respostas ao formulário 1'!$G$2:$G$121,$B28) -> 1 | G28: =CONCATENATE(D28, "/", E28) -> 0/1 | H28: Kariny | I28: Contato realizado via Whatzapp inscrição realizada.
B29: São Félix do Araguaia (MT) | D29: =COUNTIFS('Respostas ao formulário 1'!$H$2:$H$121,$D$1,'Respostas ao formulário 1'!$G$2:$G$121,$B29) -> 1 | E29: =COUNTIFS('Respostas ao formulário 1'!$H$2:$H$121,$E$1,'Respostas ao formulário 1'!$G$2:$G$121,$B29) -> 1 | G29: =CONCATENATE(D29, "/", E29) -> 1/1 | H29: Kariny
B30: Serra Nova Dourada (MT) | D30: =COUNTIFS('Respostas ao formulário 1'!$H$2:$H$121,$D$1,'Respostas ao formulário 1'!$G$2:$G$121,$B30) -> 1 | E30: =COUNTIFS('Respostas ao formulário 1'!$H$2:$H$121,$E$1,'Respostas ao formulário 1'!$G$2:$G$121,$B30) -> 1 | G30: =CONCATENATE(D30, "/", E30) -> 1/1 | H30: Kariny | I30: Contato realizado via Whatzapp aguardando retorno.
B31: Vila Rica (MT) | D31: =COUNTIFS('Respostas ao formulário 1'!$H$2:$H$121,$D$1,'Respostas ao formulário 1'!$G$2:$G$121,$B31) -> 3 | E31: =COUNTIFS('Respostas ao formulário 1'!$H$2:$H$121,$E$1,'Respostas ao formulário 1'!$G$2:$G$121,$B31) -> 3 | G31: =CONCATENATE(D31, "/", E31) -> 3/3 | H31: Kariny | I31: Contato realizado via Whatzapp, inscrições dos gestores foram realizadas.
D34: CACS | E34: Gestão municipal
A35: Municípios com representante inscrito | D35: =COUNTIF(D2:D31,">0") -> 16 | E35: =COUNTIF(E2:E31,">0") -> 21
A36: Pessoas Inscritas | D36: =SUM(D2:D31) -> 21 | E36: =SUM(E2:E31) -> 33
