Workbook

Sheet Respostas ao formulário 1
A1: Carimbo de data/hora | B1: Nome Completo: | C1: CPF: XXX.XXX.XXX-XX | D1: Telefone: (DD)XXXXX-XXXX | E1: E-mail: xxxxxxx@xxxmail.com | F1: Você já está inscrito no Curso de Capacitação em Transporte Escolar? | G1: Data de Nascimento | H1: Telefone (XX)XXXXX-XXXX | I1: Município que representa: | J1: Você faz parte do: | K1: Que cargo você ocupa na gestão municipal? | L1: Prezado(a) Gestor(a), Se existe algum caso de sucesso da gestão do transporte escolar no seu município, gostaríamos conhecer mais um pouco ao respeito. Por favor, relate de forma sucinta o caso de sucesso no espaço a seguir: | M1: Que cargo você ocupa no CACS-FUNDEB?
A2: 45987.354 | B2: Creozani Moreira Da Silva | C2: 959.503.031-72 | D2: (61)99662-8016 | E2: creozanimoreira42@gmail.com | F2: Sim | G2: =IF(F2="Sim",VLOOKUP(C2,'Inscrições'!$E$1:$N$53,2,FALSE)) -> 28656 | H2: =IF(F2="Sim",VLOOKUP(C2,'Inscrições'!$E$1:$N$53,3,FALSE)) -> (61)99662-8016 | I2: =IF(F2="Sim",VLOOKUP(C2,'Inscrições'!$E$1:$N$53,4,FALSE)) -> Água Fria de Goiás | J2: =IF(F2="Sim",VLOOKUP(C2,'Inscrições'!$E$1:$N$53,5,FALSE)) -> CACS-FUNDEB | K2: =IF(F2="Sim",VLOOKUP(C2,'Inscrições'!$E$1:$N$53,6,FALSE)) | L2: =IF(F2="Sim",VLOOKUP(C2,'Inscrições'!$E$1:$N$53,7,FALSE)) | M2: =IF(F2="Sim",VLOOKUP(C2,'Inscrições'!$E$1:$N$53,8,FALSE)) -> Conselho
A3: 45987.356 | B3: Denilson Marciano Ferreira | C3: 016.857.731-33 | D3: (61)99822-8859 | E3: cacsformosa@gmail.com | F3: Sim | G3: =IF(F3="Sim",VLOOKUP(C3,'Inscrições'!$E$1:$N$53,2,FALSE)) -> 32326 | H3: =IF(F3="Sim",VLOOKUP(C3,'Inscrições'!$E$1:$N$53,3,FALSE)) -> (61)99822-8859 | I3: =IF(F3="Sim",VLOOKUP(C3,'Inscrições'!$E$1:$N$53,4,FALSE)) -> Formosa | J3: =IF(F3="Sim",VLOOKUP(C3,'Inscrições'!$E$1:$N$53,5,FALSE)) -> CACS-FUNDEB | K3: =IF(F3="Sim",VLOOKUP(C3,'Inscrições'!$E$1:$N$53,6,FALSE)) | L3: =IF(F3="Sim",VLOOKUP(C3,'Inscrições'!$E$1:$N$53,7,FALSE)) | M3: =IF(F3="Sim",VLOOKUP(C3,'Inscrições'!$E$1:$N$53,8,FALSE)) -> Presidente
A4: 45987.356 | B4: Carla Silvério da Silva | C4: 837.722.351-15 | D4: (61)98475-2438 | E4: carlasilverio.silva@gmail.com | F4: Sim | G4: =IF(F4="Sim",VLOOKUP(C4,'Inscrições'!$E$1:$N$53,2,FALSE)) -> 28573 | H4: =IF(F4="Sim",VLOOKUP(C4,'Inscrições'!$E$1:$N$53,3,FALSE)) -> (61)98475-2438 | I4: =IF(F4="Sim",VLOOKUP(C4,'Inscrições'!$E$1:$N$53,4,FALSE)) -> Santo Antônio do Descoberto | J4: =IF(F4="Sim",VLOOKUP(C4,'Inscrições'!$E$1:$N$53,5,FALSE)) -> Gestão municipal | K4: =IF(F4="Sim",VLOOKUP(C4,'Inscrições'!$E$1:$N$53,6,FALSE)) -> Diretora de Transporte Escolar | L4: =IF(F4="Sim",VLOOKUP(C4,'Inscrições'!$E$1:$N$53,7,FALSE)) | M4: =IF(F4="Sim",VLOOKUP(C4,'Inscrições'!$E$1:$N$53,8,FALSE))
A5: 45987.356 | B5: Rozimeire de Barros Nogueira | C5: 417.678.021-53 | D5: (61)99672-0726 | E5: rozimeirenogueira@gmail.com | F5: Sim | G5: =IF(F5="Sim",VLOOKUP(C5,'Inscrições'!$E$1:$N$53,2,FALSE)) -> 24781 | H5: =IF(F5="Sim",VLOOKUP(C5,'Inscrições'!$E$1:$N$53,3,FALSE)) -> (61)99672-0726 | I5: =IF(F5="Sim",VLOOKUP(C5,'Inscrições'!$E$1:$N$53,4,FALSE)) -> Água Fria de Goiás | J5: =IF(F5="Sim",VLOOKUP(C5,'Inscrições'!$E$1:$N$53,5,FALSE)) -> Gestão municipal | K5: =IF(F5="Sim",VLOOKUP(C5,'Inscrições'!$E$1:$N$53,6,FALSE)) -> SECRETÁRIA MUNICIPAL DE EDUCAÇÃO | L5: =IF(F5="Sim",VLOOKUP(C5,'Inscrições'!$E$1:$N$53,7,FALSE)) -> O NOSO SUCESSO É SOMENTE A GARANTIA DO TRANSPORTE DIÁRIO | M5: =IF(F5="Sim",VLOOKUP(C5,'Inscrições'!$E$1:$N$53,8,FALSE))
A6: 45987.357 | B6: Silvania Souza Marins Macedo | C6: 025.266.481-73 | D6: (61)99854-1683 | E6: coordsilvania@gmail.com | F6: Sim | G6: =IF(F6="Sim",VLOOKUP(C6,'Inscrições'!$E$1:$N$53,2,FALSE)) -> 32359 | H6: =IF(F6="Sim",VLOOKUP(C6,'Inscrições'!$E$1:$N$53,3,FALSE)) -> (61)99854-1683 | I6: =IF(F6="Sim",VLOOKUP(C6,'Inscrições'!$E$1:$N$53,4,FALSE)) -> Água Fria de Goiás | J6: =IF(F6="Sim",VLOOKUP(C6,'Inscrições'!$E$1:$N$53,5,FALSE)) -> CACS-FUNDEB | K6: =IF(F6="Sim",VLOOKUP(C6,'Inscrições'!$E$1:$N$53,6,FALSE)) | L6: =IF(F6="Sim",VLOOKUP(C6,'Inscrições'!$E$1:$N$53,7,FALSE)) | M6: =IF(F6="Sim",VLOOKUP(C6,'Inscrições'!$E$1:$N$53,8,FALSE)) -> Presidente
A7: 45987.357 | B7: Raimundo Vieira Soares Neto | C7: 002.897.261-90 | D7: (61)99427-9449 | E7: raimundooneeto@gmail.com | F7: Sim | G7: =IF(F7="Sim",VLOOKUP(C7,'Inscrições'!$E$1:$N$53,2,FALSE)) -> 30555 | H7: =IF(F7="Sim",VLOOKUP(C7,'Inscrições'!$E$1:$N$53,3,FALSE)) -> (61)99427-9449 | I7: =IF(F7="Sim",VLOOKUP(C7,'Inscrições'!$E$1:$N$53,4,FALSE)) -> Santo Antônio do Descoberto | J7: =IF(F7="Sim",VLOOKUP(C7,'Inscrições'!$E$1:$N$53,5,FALSE)) -> Gestão municipal | K7: =IF(F7="Sim",VLOOKUP(C7,'Inscrições'!$E$1:$N$53,6,FALSE)) -> Assistente De Transporte Escolar | L7: =IF(F7="Sim",VLOOKUP(C7,'Inscrições'!$E$1:$N$53,7,FALSE)) -> O Transporte Escolar Rural e Urbano vem crescendo com Georeferenciamento de cada aluno, está avançando com identificação do Secretário Da Educação Elismar (Lima Vendedor) e a falta de um Responsável me indicou e deixou com essa responsabilidade aonde estamos construindo um Transporte Escolar com Transparência e Qualidade! | M7: =IF(F7="Sim",VLOOKUP(C7,'Inscrições'!$E$1:$N$53,8,FALSE))
A8: 45987.357 | B8: Ricardo Pereira de Sousa | C8: 784.099.261-72 | D8: (61)99616-1556 | E8: ricardorickdesousa@hotmail.com | F8: Sim | G8: =IF(F8="Sim",VLOOKUP(C8,'Inscrições'!$E$1:$N$53,2,FALSE)) -> 28105 | H8: =IF(F8="Sim",VLOOKUP(C8,'Inscrições'!$E$1:$N$53,3,FALSE)) -> (61)99616-1556 | I8: =IF(F8="Sim",VLOOKUP(C8,'Inscrições'!$E$1:$N$53,4,FALSE)) -> Formosa | J8: =IF(F8="Sim",VLOOKUP(C8,'Inscrições'!$E$1:$N$53,5,FALSE)) -> Gestão municipal | K8: =IF(F8="Sim",VLOOKUP(C8,'Inscrições'!$E$1:$N$53,6,FALSE)) -> Gestor do Transporte Escolar | L8: =IF(F8="Sim",VLOOKUP(C8,'Inscrições'!$E$1:$N$53,7,FALSE)) | M8: =IF(F8="Sim",VLOOKUP(C8,'Inscrições'!$E$1:$N$53,8,FALSE))
A9: 45987.358 | B9: Wanderley Fernando Silva Macedo | C9: 055.022.931-06 | D9: (61)99218-7061 | E9: wanderley-wsf@hotmail.com | F9: Sim | G9: =IF(F9="Sim",VLOOKUP(C9,'Inscrições'!$E$1:$N$53,2,FALSE)) -> 34740 | H9: =IF(F9="Sim",VLOOKUP(C9,'Inscrições'!$E$1:$N$53,3,FALSE)) -> (61)99218-7061 | I9: =IF(F9="Sim",VLOOKUP(C9,'Inscrições'!$E$1:$N$53,4,FALSE)) -> Cidade Ocidental | J9: =IF(F9="Sim",VLOOKUP(C9,'Inscrições'!$E$1:$N$53,5,FALSE)) -> Gestão municipal | K9: =IF(F9="Sim",VLOOKUP(C9,'Inscrições'!$E$1:$N$53,6,FALSE)) -> ASSESSOR (A) DE GABINETE III | L9: =IF(F9="Sim",VLOOKUP(C9,'Inscrições'!$E$1:$N$53,7,FALSE)) | M9: =IF(F9="Sim",VLOOKUP(C9,'Inscrições'!$E$1:$N$53,8,FALSE))
A10: 45987.358 | B10: Eliane Gomes de Melo | C10: 023.192.371-60 | D10: (61)99659-8818 | E10: elianegomesfsa@hotmail.com | F10: Sim | G10: =IF(F10="Sim",VLOOKUP(C10,'Inscrições'!$E$1:$N$53,2,FALSE)) -> 29934 | H10: =IF(F10="Sim",VLOOKUP(C10,'Inscrições'!$E$1:$N$53,3,FALSE)) -> (61)99659-8818 | I10: =IF(F10="Sim",VLOOKUP(C10,'Inscrições'!$E$1:$N$53,4,FALSE)) -> Formosa | J10: =IF(F10="Sim",VLOOKUP(C10,'Inscrições'!$E$1:$N$53,5,FALSE)) -> Gestão municipal | K10: =IF(F10="Sim",VLOOKUP(C10,'Inscrições'!$E$1:$N$53,6,FALSE)) -> Técnica de prestação de contas | L10: =IF(F10="Sim",VLOOKUP(C10,'Inscrições'!$E$1:$N$53,7,FALSE)) | M10: =IF(F10="Sim",VLOOKUP(C10,'Inscrições'!$E$1:$N$53,8,FALSE))
A11: 45987.363 | B11: Edite neves lima | C11: 473.897.531-53 | D11: (61)98384-4519 | E11: Editeneveslima@gmail.com | F11: Sim | G11: =IF(F11="Sim",VLOOKUP(C11,'Inscrições'!$E$1:$N$53,2,FALSE)) -> 25246 | H11: =IF(F11="Sim",VLOOKUP(C11,'Inscrições'!$E$1:$N$53,3,FALSE)) -> (61)98374-4519 | I11: =IF(F11="Sim",VLOOKUP(C11,'Inscrições'!$E$1:$N$53,4,FALSE)) -> Cidade Ocidental | J11: =IF(F11="Sim",VLOOKUP(C11,'Inscrições'!$E$1:$N$53,5,FALSE)) -> CACS-FUNDEB | K11: =IF(F11="Sim",VLOOKUP(C11,'Inscrições'!$E$1:$N$53,6,FALSE)) | L11: =IF(F11="Sim",VLOOKUP(C11,'Inscrições'!$E$1:$N$53,7,FALSE)) | M11: =IF(F11="Sim",VLOOKUP(C11,'Inscrições'!$E$1:$N$53,8,FALSE)) -> Coselheira
A12: 45987.363 | B12: Edvaldo Nunes de Amorim | C12: 516.212.151-72 | D12: (61)99525-7272 | E12: edvaldovaldinhonunesamorim@gmail.com | F12: Sim | G12: =IF(F12="Sim",VLOOKUP(C12,'Inscrições'!$E$1:$N$53,2,FALSE)) -> 25890 | H12: =IF(F12="Sim",VLOOKUP(C12,'Inscrições'!$E$1:$N$53,3,FALSE)) -> (61)99525-7272 | I12: =IF(F12="Sim",VLOOKUP(C12,'Inscrições'!$E$1:$N$53,4,FALSE)) -> Cidade Ocidental | J12: =IF(F12="Sim",VLOOKUP(C12,'Inscrições'!$E$1:$N$53,5,FALSE)) -> Gestão municipal | K12: =IF(F12="Sim",VLOOKUP(C12,'Inscrições'!$E$1:$N$53,6,FALSE)) -> COORDENADOR DE TRANSPORTE ESCOLAR | L12: =IF(F12="Sim",VLOOKUP(C12,'Inscrições'!$E$1:$N$53,7,FALSE)) | M12: =IF(F12="Sim",VLOOKUP(C12,'Inscrições'!$E$1:$N$53,8,FALSE))
A13: 45987.366 | B13: Wania Aguiar da Silva | C13: 957.507.891-87 | D13: (61)99831-3553 | E13: aguiarwania@gmail.com | F13: Sim | G13: =IF(F13="Sim",VLOOKUP(C13,'Inscrições'!$E$1:$N$53,2,FALSE)) -> 29945 | H13: =IF(F13="Sim",VLOOKUP(C13,'Inscrições'!$E$1:$N$53,3,FALSE)) -> (61)99831-3553 | I13: =IF(F13="Sim",VLOOKUP(C13,'Inscrições'!$E$1:$N$53,4,FALSE)) -> Cabeceiras | J13: =IF(F13="Sim",VLOOKUP(C13,'Inscrições'!$E$1:$N$53,5,FALSE)) -> CACS-FUNDEB | K13: =IF(F13="Sim",VLOOKUP(C13,'Inscrições'!$E$1:$N$53,6,FALSE)) | L13: =IF(F13="Sim",VLOOKUP(C13,'Inscrições'!$E$1:$N$53,7,FALSE)) | M13: =IF(F13="Sim",VLOOKUP(C13,'Inscrições'!$E$1:$N$53,8,FALSE)) -> Assistente técnica
... A32: 45987.444 | B32: Cícero Lopes Alves | C32: 635.793.321-04 | D32: (61)99330-3822 | E32: bola.alves@yahoo.com.br | F32: Sim | G32: =IF(F32="Sim",VLOOKUP(C32,'Inscrições'!$E$1:$N$53,2,FALSE)) -> 27479 | H32: =IF(F32="Sim",VLOOKUP(C32,'Inscrições'!$E$1:$N$53,3,FALSE)) -> (61)99330-3822 | I32: =IF(F32="Sim",VLOOKUP(C32,'Inscrições'!$E$1:$N$53,4,FALSE)) -> Alexânia | J32: =IF(F32="Sim",VLOOKUP(C32,'Inscrições'!$E$1:$N$53,5,FALSE)) -> Gestão municipal | K32: =IF(F32="Sim",VLOOKUP(C32,'Inscrições'!$E$1:$N$53,6,FALSE)) -> Coordenador de Transporte | L32: =IF(F32="Sim",VLOOKUP(C32,'Inscrições'!$E$1:$N$53,7,FALSE)) | M32: =IF(F32="Sim",VLOOKUP(C32,'Inscrições'!$E$1:$N$53,8,FALSE))
A33: 45987.444 | B33: Ithamires Alves de Oliveira | C33: 034.688.963-44 | D33: (61)99137-3101 | E33: ithamiresalves8@gmail.com | F33: Sim | G33: 32122 | H33: (61) 99137-3101 | I33: Águas Lindas de Goiás | J33: CACS-FUNDEB | K33: Chefe de Gestão Escolar
A34: 45987.444 | B34: Maria Elenice Albano Santos | C34: 199.838.912-04 | D34: (61)99590-6771 | E34: elenicealbano2@Gmail.co | F34: Sim | G34: =IF(F34="Sim",VLOOKUP(C34,'Inscrições'!$E$1:$N$53,2,FALSE)) -> 22478 | H34: =IF(F34="Sim",VLOOKUP(C34,'Inscrições'!$E$1:$N$53,3,FALSE)) -> (61)99590-6771 | I34: =IF(F34="Sim",VLOOKUP(C34,'Inscrições'!$E$1:$N$53,4,FALSE)) -> Valparaíso de Goiás | J34: =IF(F34="Sim",VLOOKUP(C34,'Inscrições'!$E$1:$N$53,5,FALSE)) -> CACS-FUNDEB | K34: =IF(F34="Sim",VLOOKUP(C34,'Inscrições'!$E$1:$N$53,6,FALSE)) | L34: =IF(F34="Sim",VLOOKUP(C34,'Inscrições'!$E$1:$N$53,7,FALSE)) | M34: =IF(F34="Sim",VLOOKUP(C34,'Inscrições'!$E$1:$N$53,8,FALSE)) -> Conselheira
A35: 45987.445 | B35: Valdir José Soares | C35: 577.343.301-00 | D35: (61)99148-6115 | E35: valdir.jsoares@outlook.com | F35: Sim | G35: =IF(F35="Sim",VLOOKUP(C35,'Inscrições'!$E$1:$N$53,2,FALSE)) -> 25099 | H35: =IF(F35="Sim",VLOOKUP(C35,'Inscrições'!$E$1:$N$53,3,FALSE)) -> (61)99148-6115 | I35: =IF(F35="Sim",VLOOKUP(C35,'Inscrições'!$E$1:$N$53,4,FALSE)) -> Mimoso de Goiás | J35: =IF(F35="Sim",VLOOKUP(C35,'Inscrições'!$E$1:$N$53,5,FALSE)) -> Gestão municipal | K35: =IF(F35="Sim",VLOOKUP(C35,'Inscrições'!$E$1:$N$53,6,FALSE)) -> Técnico do transporte escolar | L35: =IF(F35="Sim",VLOOKUP(C35,'Inscrições'!$E$1:$N$53,7,FALSE)) | M35: =IF(F35="Sim",VLOOKUP(C35,'Inscrições'!$E$1:$N$53,8,FALSE))
A36: 45987.457 | B36: Maria Ivanilda Gomes Soares | C36: 647.349.431-68 | D36: (61)99616-2161 | E36: maria.isoares@outlook.com | F36: Sim | G36: =IF(F36="Sim",VLOOKUP(C36,'Inscrições'!$E$1:$N$53,2,FALSE)) -> 27078 | H36: =IF(F36="Sim",VLOOKUP(C36,'Inscrições'!$E$1:$N$53,3,FALSE)) -> (61)99616-2161 | I36: =IF(F36="Sim",VLOOKUP(C36,'Inscrições'!$E$1:$N$53,4,FALSE)) -> Mimoso de Goiás | J36: =IF(F36="Sim",VLOOKUP(C36,'Inscrições'!$E$1:$N$53,5,FALSE)) -> Gestão municipal | K36: =IF(F36="Sim",VLOOKUP(C36,'Inscrições'!$E$1:$N$53,6,FALSE)) -> Secretária Municipal de Educação | L36: =IF(F36="Sim",VLOOKUP(C36,'Inscrições'!$E$1:$N$53,7,FALSE)) | M36: =IF(F36="Sim",VLOOKUP(C36,'Inscrições'!$E$1:$N$53,8,FALSE))

Sheet Inscrições
A1: Carimbo de data/hora | B1: Endereço de e-mail | C1: Nome Completo: | D1: Confirme o E-mail | E1: CPF | F1: Data de Nascimento | G1: Telefone (XX)XXXXX-XXXX | H1: Município que representa: | I1: Você faz parte do: | J1: Que cargo você ocupa na gestão municipal? | K1: Prezado(a) Gestor(a), Se existe algum caso de sucesso da gestão do transporte escolar no seu município, gostaríamos conhecer mais um pouco ao respeito. Por favor, relate de forma sucinta o caso de sucesso no espaço a seguir: | L1: Que cargo você ocupa no CACS-FUNDEB? | M1: Confirmação de veracidade dos dados | N1: Coluna 14
A2: 45968.365 | B2: dorinhajm.2015@gmail.com | C2: Francisca Teodora Monteiro de Oliveira | D2: dorinhajm.2015@gmail.com | E2: 000.253.751-64 | F2: 29643 | G2: (61)98215-2356 | H2: Valparaíso de Goiás | I2: CACS-FUNDEB | L2: Conselheiro | M2: Declaro que revisei e confirmo a veracidade de todas as informações prestadas neste formulário.
A3: 45954.914 | B3: raimundooneeto@gmail.com | C3: Raimundo Vieira Soares Neto | D3: raimundooneeto@gmail.com | E3: 002.897.261-90 | F3: 30555 | G3: (61)99427-9449 | H3: Santo Antônio do Descoberto | I3: Gestão municipal | J3: Assistente De Transporte Escolar | K3: O Transporte Escolar Rural e Urbano vem crescendo com Georeferenciamento de cada aluno, está avançando com identificação do Secretário Da Educação Elismar (Lima Vendedor) e a falta de um Responsável me indicou e deixou com essa responsabilidade aonde estamos construindo um Transporte Escolar com Transparência e Qualidade! | M3: Declaro que revisei e confirmo a veracidade de todas as informações prestadas neste formulário.
A4: 45967.571 | B4: jucienerdsa@gmail.com | C4: Juciene Rodrigues da Silva | D4: jucienerdsa@gmail.com | E4: 003.854.301-08 | F4: 30564 | G4: (61)99835-9941 | H4: Formosa | I4: Gestão municipal | J4: Técnica da prestação de contas | M4: Declaro que revisei e confirmo a veracidade de todas as informações prestadas neste formulário.
A5: 45978.388 | B5: luizinho.brandao@hotmail.com | C5: LUIZ ANTONIO ALVES BRANDAO | D5: luizinho.brandao@hotmail.com | E5: 009.719.041-11 | F5: 31577 | G5: (61)99955-3065 | H5: Cabeceiras | I5: Gestão municipal | J5: GERENTE DE AQUISIÇÃO - CHEFE DO TRANSPORTE ESCOLAR | M5: Declaro que revisei e confirmo a veracidade de todas as informações prestadas neste formulário.
A6: 45958.563 | B6: janainaricardo.21@gmail.com | C6: Janaína Ricardo da Silva | D6: janainaricardo.21@gmail.com | E6: 012.658.421-40 | F6: 31007 | G6: (61)99186-4325 | H6: Cidade Ocidental | I6: CACS-FUNDEB | L6: Vice-presidente | M6: Declaro que revisei e confirmo a veracidade de todas as informações prestadas neste formulário.
A7: 45967.578 | B7: cacsformosa@gmail.com | C7: Denilson Marciano Ferreira | D7: cacsformosa@gmail.com | E7: 016.857.731-33 | F7: 32326 | G7: (61)99822-8859 | H7: Formosa | I7: CACS-FUNDEB | L7: Presidente | M7: Declaro que revisei e confirmo a veracidade de todas as informações prestadas neste formulário.
A8: 45968.381 | B8: ediramjosilva@gmail.com | C8: Olizia Alves de Matos Silva | D8: ediramjosilva@gmail.com | E8: 024.296.126-66 | F8: 24914 | G8: (61)98425-9543 | H8: Valparaíso de Goiás | I8: CACS-FUNDEB | L8: Representante dos professores - conselheira | M8: Declaro que revisei e confirmo a veracidade de todas as informações prestadas neste formulário.
A9: 45959.607 | B9: coordsilvania@gmail.com | C9: Silvania Souza Marins Macedo | D9: coordsilvania@gmail.com | E9: 025.266.481-73 | F9: 32359 | G9: (61)99854-1683 | H9: Água Fria de Goiás | I9: CACS-FUNDEB | L9: Presidente | M9: Declaro que revisei e confirmo a veracidade de todas as informações prestadas neste formulário.
A10: 45971.481 | B10: francelino16@hotmail.com | C10: Francelino Palácio de Morais | D10: francelino16@hotmail.com | E10: 040.394.641-76 | F10: 33715 | G10: (61)99547-0786 | H10: Novo Gama | I10: Gestão municipal | J10: Diretor do Transporte Escolar | M10: Declaro que revisei e confirmo a veracidade de todas as informações prestadas neste formulário.
A11: 45968.363 | B11: FranciscaErickPietro2010@gmail.com | C11: Francisca Pereira torcato | D11: Franciscaerickpietro2010@gmail.com | E11: 052.726.111-44 | F11: 34262 | G11: (61)99355-8287 | H11: Valparaíso de Goiás | I11: CACS-FUNDEB | L11: Conselheira | M11: Declaro que revisei e confirmo a veracidade de todas as informações prestadas neste formulário.
A12: 45968.603 | B12: wanderley-wsf@hotmail.com | C12: Wanderley Fernando Silva Macedo | D12: wanderley-wsf@hotmail.com | E12: 055.022.931-06 | F12: 34740 | G12: (61)99218-7061 | H12: Cidade Ocidental | I12: Gestão municipal | J12: ASSESSOR (A) DE GABINETE III | M12: Declaro que revisei e confirmo a veracidade de todas as informações prestadas neste formulário.
A13: 45961.522 | B13: alinetransporteescolarjussara@gmail.com | C13: ALINE BARBOSA DA SILVA FERREIRA | D13: alinetrasnporteescolarjussara@gmail.com | E13: 079.311.789-55 | F13: 33455 | G13: (44)99871-5907 | H13: Jussara - PR | I13: Gestão municipal | J13: Secretária Executiva da Educação. | M13: Declaro que revisei e confirmo a veracidade de todas as informações prestadas neste formulário.
A14: 45954.595 | B14: kelledias0@gmail.com | C14: Kelle Dias Souto | D14: kelledias0@gmail.com | E14: 101.604.916-14 | F14: 33464 | G14: (61)99915-1756 | H14: Cabeceiras | I14: CACS-FUNDEB | L14: Membro | M14: Declaro que revisei e confirmo a veracidade de todas as informações prestadas neste formulário.
A15: 45968.622 | B15: fatimafau3657@gmail.com | C15: Maria de fatima alves de sales | D15: Fatimafau3657@gmail.com | E15: 153.850.511-87 | F15: 19644 | G15: (61)98682-8267 | H15: Valparaíso de Goiás | I15: CACS-FUNDEB | L15: Conselheira | M15: Declaro que revisei e confirmo a veracidade de todas as informações prestadas neste formulário.
A16: 45973.476 | B16: elenicealbano2@gmail.com | C16: Maria Elenice Albano Santos | D16: elenicealbano2@gmail.com | E16: 199.838.912-04 | F16: 22478 | G16: (61)99590-6771 | H16: Valparaíso de Goiás | I16: CACS-FUNDEB | L16: Conselheira | M16: Declaro que revisei e confirmo a veracidade de todas as informações prestadas neste formulário.
A17: 45958.508 | B17: niltonfl@yahoo.com.br | C17: Nílton Nelson Pereira da Silva | D17: niltonfl@yahoo.com.br | E17: 294.982.871-04 | F17: 23409 | G17: (61)98424-5304 | H17: Cristalina | I17: Gestão municipal | J17: Coordenador do transporte escolar do município | M17: Declaro que revisei e confirmo a veracidade de todas as informações prestadas neste formulário.
A18: 45967.637 | B18: gabinetesme5@gmail.com | C18: Maria Rita Ribeiro Guedes Frazão | D18: gabinetesme5@gmail.com | E18: 416.360.311-53 | F18: 24063 | G18: (61)98592-7624 | H18: Valparaíso de Goiás | I18: Gestão municipal | J18: Secretária de Educação | M18: Declaro que revisei e confirmo a veracidade de todas as informações prestadas neste formulário.
A19: 45959.6 | B19: rozimeirenogueira@gmail.com | C19: ROZIMEIRE DE BARROS NOGUEIRA | D19: rozimeirenogueira@gmail.com | E19: 417.678.021-53 | F19: 24781 | G19: (61)99672-0726 | H19: Água Fria de Goiás | I19: Gestão municipal | J19: SECRETÁRIA MUNICIPAL DE EDUCAÇÃO | K19: O NOSO SUCESSO É SOMENTE A GARANTIA DO TRANSPORTE DIÁRIO | M19: Declaro que revisei e confirmo a veracidade de todas as informações prestadas neste formulário.
A20: 45968.376 | B20: lucietesouza2012@gmail.com | C20: Luciete Rosa de Souza | D20: lucietesouza2012@gmail.com | E20: 471.653.911-34 | F20: 26914 | G20: (61)99260-5343 | H20: Valparaíso de Goiás | I20: CACS-FUNDEB | L20: Conselheira titular segmento administrativo | M20: Declaro que revisei e confirmo a veracidade de todas as informações prestadas neste formulário.
A21: 45958.673 | B21: editeneveslima@gmail.com | C21: Edite Neves Lima | D21: Editeneveslima@gmail.com | E21: 473.897.531-53 | F21: 25246 | G21: (61)98374-4519 | H21: Cidade Ocidental | I21: CACS-FUNDEB | L21: Coselheira | M21: Declaro que revisei e confirmo a veracidade de todas as informações prestadas neste formulário.
A22: 45958.52 | B22: copaiba1994@gmail.com | C22: Jerson Machado | D22: copaiba1994@gmail.com | E22: 476.476.391-53 | F22: 25558 | G22: (61)99632-4995 | H22: Cristalina | I22: Gestão municipal | J22: Motorista e parte de documentos do departamento | K22: Todo o município e atendido com o transporte escolar, média de 4000 alunos transportado diariamente e mais de 13 mil km percorrido por dia entre transporte público e terceirizado | M22: Declaro que revisei e confirmo a veracidade de todas as informações prestadas neste formulário.
A23: 45968.604 | B23: edvaldovaldinhonunesamorim@gmail.com | C23: Edvaldo Nunes de Amorim | D23: edvaldovaldinhonunesamorim@gmail.com | E23: 516.212.151-72 | F23: 25890 | G23: (61)99525-7272 | H23: Cidade Ocidental | I23: Gestão municipal | J23: COORDENADOR DE TRANSPORTE ESCOLAR | M23: Declaro que revisei e confirmo a veracidade de todas as informações prestadas neste formulário.
A24: 45954.557 | B24: wilkapc@gmail.com | C24: Wilka de Kássia Pereira Cardoso | D24: wilkapc@gmail.com | E24: 589.972.101-49 | F24: 27085 | G24: (61)99651-9075 | H24: Cabeceiras | I24: Gestão municipal | J24: Secretária Municipal de Educação | M24: Declaro que revisei e confirmo a veracidade de todas as informações prestadas neste formulário.
A25: 45970.342 | B25: profgizeledoaee@gmail.com | C25: Gizele Rodrigues Soares | D25: profgizeledoaee@gmail.com | E25: 618.223.701-59 | F25: 28496 | G25: (61)99640-8827 | H25: Valparaíso de Goiás | I25: CACS-FUNDEB | L25: Conselheira suplente | M25: Declaro que revisei e confirmo a veracidade de todas as informações prestadas neste formulário.
A26: 45966.658 | B26: transportesmevg@gmai.com | C26: Fabiano Galvão de Brito | D26: Transportesmevg@gmail.com | E26: 700.544.521-04 | F26: 29532 | G26: (61)99556-7427 | H26: Valparaíso de Goiás | I26: Gestão municipal | J26: Diretor de Transporte | K26: Transporte dos alunos PcDs com veículos da frota oficial | M26: Declaro que revisei e confirmo a veracidade de todas as informações prestadas neste formulário.
A27: 45958.544 | B27: franalcantara02@hotmail.com | C27: Franciene de Alcântara Nunes Sousa | D27: franalcantara02@hotmail.com | E27: 803.527.821-53 | F27: 28642 | G27: (61)98574-5969 | H27: Cristalina | I27: CACS-FUNDEB | L27: Conselheira | M27: Declaro que revisei e confirmo a veracidade de todas as informações prestadas neste formulário.
A28: 45971.701 | B28: ercules.medeiros@hotmail.com | C28: Sebastão Ercules R. Medeiros | D28: ercules.medeiros@hotmail.com | E28: 830.838.554-00 | F28: 27526 | G28: (61)99617-0044 | H28: Água Fria de Goiás | I28: Gestão municipal | J28: Coordenador de Programas Educacionais da Secretaria Municipal de Educação | K28: Nada a relatar de momento | M28: Declaro que revisei e confirmo a veracidade de todas as informações prestadas neste formulário.
A29: 45975.953 | B29: carlasilverio.silva@gmail.com | C29: Carla Silvério da Silva | D29: carlasilverio.silva@gmail.com | E29: 837.722.351-15 | F29: 28573 | G29: (61)98475-2438 | H29: Santo Antônio do Descoberto | I29: Gestão municipal | J29: Diretora de Transporte Escolar | M29: Declaro que revisei e confirmo a veracidade de todas as informações prestadas neste formulário.
A30: 45971.386 | B30: diolan21@gmail.com | C30: Diolan Batista Porto | D30: diolan21@gmail.com | E30: 959.175.001-34 | F30: 30532 | G30: (61)99908-4050 | H30: Valparaíso de Goiás | I30: CACS-FUNDEB | L30: Conselheiro | M30: Declaro que revisei e confirmo a veracidade de todas as informações prestadas neste formulário.
A31: 45974.359 | B31: creozanimoreira42@gmail.com | C31: Creozani Moreira Da Silva | D31: creozanimoreira42@gmail.com | E31: 959.503.031-72 | F31: 28656 | G31: (61)99662-8016 | H31: Água Fria de Goiás | I31: CACS-FUNDEB | L31: Conselho | M31: Declaro que revisei e confirmo a veracidade de todas as informações prestadas neste formulário.
A32: 45968.61 | B32: sousaesilva_125@hotmail.com | C32: Patricia Sousa da Silva Matos | D32: sousaesilva_125@hotmail.com | E32: 964.058.211-53 | F32: 30811 | G32: (61)98468-8699 | H32: Cidade Ocidental | I32: Gestão municipal | J32: Superintendente do Fundeb e FME | M32: Declaro que revisei e confirmo a veracidade de todas as informações prestadas neste formulário.
A33: 45978.619 | B33: bola.alves@yahoo.com.br | C33: Cícero Lopes Alves | D33: bola.alves@yahoo.com.br | E33: 635.793.321-04 | F33: 27479 | G33: (61)99330-3822 | H33: Alexânia | I33: Gestão municipal | J33: Coordenador de Transporte | M33: Declaro que revisei e confirmo a veracidade de todas as informações prestadas neste formulário.
A34: 45978.625 | B34: anayanepereiradesousa@gmail.com | C34: Anayane Pereira de Sousa | D34: anayanepereiradesousa@gmail.com | E34: 705.495.231-62 | F34: 35573 | G34: (62)99557-8844 | H34: Alexânia | I34: Gestão municipal | J34: Coordenação de transporte | M34: Declaro que revisei e confirmo a veracidade de todas as informações prestadas neste formulário.
A35: 45979.608 | B35: marcosaurelho982@gmail.com | C35: Marcos Aurelho de França Viana | D35: marcosaurelho982@gmail.com | E35: 635.523.101-34 | F35: 27063 | G35: (61)99647-2610 | H35: Cabeceiras | I35: Gestão municipal | J35: Técnico de Prestação de Contas da Secretaria Municipal de Educação | M35: Declaro que revisei e confirmo a veracidade de todas as informações prestadas neste formulário.
A36: 45979.609 | B36: transporteeducacaocampoalegre@gmail.com | C36: Guilania Pereira da Fonseca | D36: transporteeducacaocampoalegre@gmail.com | E36: 007.689.631-50 | F36: 31090 | G36: (64)99652-6159 | H36: Campo Alegre de Goiás | I36: Gestão municipal | J36: Coordenador Transporte Escolar | M36: Declaro que revisei e confirmo a veracidade de todas as informações prestadas neste formulário.
A37: 45979.653 | B37: niltonfl@yahoo.com.br | C37: Nílton Nelson Pereira da Silva | D37: niltonfl@yahoo.com.br | E37: 294.982.871-04 | F37: 23409 | G37: (61)98424-5304 | H37: Cristalina | I37: Gestão municipal | J37: Coordenador de transporte | K37: A vistoria passou 100% | M37: Declaro que revisei e confirmo a veracidade de todas as informações prestadas neste formulário.
A38: 45980.44 | B38: julianabraz10@gmail.com | C38: Juliana Silvia Braz | D38: julianabraz10@gmail.com | E38: 007.503.831-51 | F38: 30802 | G38: (61)99922-4481 | H38: Luziânia | I38: Gestão municipal | J38: Agente da Educação | M38: Declaro que revisei e confirmo a veracidade de todas as informações prestadas neste formulário.
A39: 45980.44 | B39: rosanambarreto@gmail.com | C39: Rosana Mantovani Barreto | D39: rosanambarreto@gmail.com | E39: 381.256.251-00 | F39: 24275 | G39: (61)99831-0926 | H39: Luziânia | I39: Gestão municipal | J39: Diretora da Divisão de Transportes | M39: Declaro que revisei e confirmo a veracidade de todas as informações prestadas neste formulário.
A40: 45980.445 | B40: mportela26@hotmail.com | C40: Márcia Vieira Portela | D40: mportela26@hotmail.com | E40: 844.253.931-04 | F40: 28667 | G40: (61)98525-8488 | H40: Luziânia | I40: Gestão municipal | J40: Assessora da Divisão de Transportes | M40: Declaro que revisei e confirmo a veracidade de todas as informações prestadas neste formulário.
...
