Workbook

Sheet Respostas ao formulário 1
A1: Carimbo de data/hora | B1: Nome Completo: | C1: CPF: XXX.XXX.XXX-XX | D1: Telefone: (DD)XXXXX-XXXX | E1: E-mail: xxxxxxx@xxxmail.com | F1: Você já está inscrito no Curso de Capacitação em Transporte Escolar? | G1: Data de Nascimento | H1: Telefone (XX)XXXXX-XXXX | I1: Município que representa: | J1: Você faz parte do: | K1: Que cargo você ocupa na gestão municipal? | L1: Prezado(a) Gestor(a), Se existe algum caso de sucesso da gestão do transporte escolar no seu município, gostaríamos conhecer mais um pouco ao respeito. Por favor, relate de forma sucinta o caso de sucesso no espaço a seguir: | M1: Que cargo você ocupa no CACS-FUNDEB? | O1: CPF inscrito
A2: 46100.373 | B2: Ronivaldo Marques Pinto | C2: 969.569.331-87 | D2: (66)99955-0748 | E2: ronimarquespta@gmail.com | F2: Sim | O2: =VLOOKUP(C2,'Página1'!B:I,1,FALSE()) -> 969.569.331-87
A3: 46100.379 | B3: Rudnei Moraes Sasso | C3: 991.302.971-68 | D3: (66)99630-1179 | E3: rudneimsasso@gmail.com | F3: Sim | O3: =VLOOKUP(C3,'Página1'!B:I,1,FALSE()) -> 991.302.971-68
A4: 46100.38 | B4: Josimeire da luz | C4: 028.495.521-35 | D4: (66)98421-2529 | E4: josidaluz201@gmail.com | F4: Sim | O4: =VLOOKUP(C4,'Página1'!B:I,1,FALSE()) -> 028.495.521-35
A5: 46100.38 | B5: Rosangela Cunha da Silva | C5: 231.385.802-20 | D5: (66)99220-1350 | E5: rosangelacunhadasilva2@gmail.com | F5: Sim | O5: =VLOOKUP(C5,'Página1'!B:I,1,FALSE()) -> 231.385.802-20
A6: 46100.381 | B6: Marco Antônio A. Faraco | C6: 950.825.901-97 | D6: (66)99232-4866 | E6: conselhoaltafloresta@gmail.com | F6: Sim | O6: =VLOOKUP(C6,'Página1'!B:I,1,FALSE()) -> 950.825.901-97
A7: 46100.382 | B7: Tiago Benfica de Assis | C7: 009.976.891-70 | D7: (66)98429-9272 | E7: tiagobenficadeassis@gmail.com | F7: Não | G7: 31391 | H7: (66)98429-9272 | I7: ALTA FLORESTA | J7: CACS-FUNDEB | M7: Conselheiro | O7: =VLOOKUP(C7,'Página1'!B:I,1,FALSE()) -> 009.976.891-70
A8: 46100.382 | B8: Everson Wiechorek | C8: 032.294.371-01 | D8: (66)98459-2161 | E8: Eversonwiechorek@gmail.com | F8: Sim | O8: =VLOOKUP(C8,'Página1'!B:I,1,FALSE()) -> 032.294.371-01
A9: 46100.382 | B9: Valdinei Makohin do Nascimento | C9: 011.149.971-29 | D9: (66)99919-6873 | E9: valdineimakohi1984@gmail.com | F9: Sim | O9: =VLOOKUP(C9,'Página1'!B:I,1,FALSE()) -> 011.149.971-29
A10: 46100.384 | B10: Jaqueline Leal | C10: 061.056.901-50 | D10: (66)99245-5001 | E10: jaquelineleal67@gmail.com | F10: Sim | O10: =VLOOKUP(C10,'Página1'!B:I,1,FALSE()) -> 061.056.901-50
A11: 46100.385 | B11: Cirene Aparecida da Rosa Mendes | C11: 795.415.009-78 | D11: (66)98439-2918 | E11: Cirenepinknmv@hotmail.com | F11: Sim | O11: =VLOOKUP(C11,'Página1'!B:I,1,FALSE()) -> 795.415.009-78
A12: 46100.387 | B12: ELIZEU DA SILVA BAIOCO | C12: 025.590.831-83 | D12: (66)98436-4794 | E12: Elizeubaioco@hotmail.com | F12: Sim | O12: =VLOOKUP(C12,'Página1'!B:I,1,FALSE()) -> 025.590.831-83
A13: 46100.387 | B13: JOUSE MARIA CONRADO | C13: 894.899.451-34 | D13: (66)99204-5216 | E13: jouseconrado8@gmail.com | F13: Sim | G13: 28899 | H13: (66)99204-5216 | I13: Alta Floresta | J13: CACS-Fundeb | M13: Conselheira | O13: =VLOOKUP(C13,'Página1'!B:I,1,FALSE()) -> #N/A | P13: 1
A14: 46100.387 | B14: Irineu Santana Rauschkolb | C14: 040.738.891-50 | D14: (66)99939-9893 | E14: irineusantana814@gmail.com | F14: Sim | O14: =VLOOKUP(C14,'Página1'!B:I,1,FALSE()) -> 040.738.891-50
A15: 46100.387 | B15: Erdilene Bueno Onofre | C15: 043.728.121-32 | D15: (66)98419-2180 | E15: erdileneonofre@outlook.com | F15: Sim | O15: =VLOOKUP(C15,'Página1'!B:I,1,FALSE()) -> 043.728.121-32
A16: 46100.388 | B16: Claudia Sibeli Coelho Fiel | C16: 018.772.109-27 | D16: (66)98409-2312 | E16: claumar_fiel@hotmail.com | F16: Sim | O16: =VLOOKUP(C16,'Página1'!B:I,1,FALSE()) -> 018.772.109-27
A17: 46100.39 | B17: Talison Rafael de lima ouvernei | C17: 058.230.421-08 | D17: (66)98416-0491 | E17: Talison1478@gmail.com | F17: Sim | O17: =VLOOKUP(C17,'Página1'!B:I,1,FALSE()) -> 058.230.421-08
A18: 46100.391 | B18: Daiane Mariana da Silva Benfica | C18: 731.237.221-04 | D18: (66)98428-8628 | E18: daianemariana@msn.com | F18: Sim | O18: =VLOOKUP(C18,'Página1'!B:I,1,FALSE()) -> 731.237.221-04
A19: 46100.391 | B19: Rosângela Feitoza F. Cruz | C19: 014.272.011-96 | D19: (66)98411-3794 | E19: rosangelaffcruz@gmail.com | F19: Não | G19: 30864 | H19: (66)98411-3794 | I19: APIACÁS | J19: CACS-FUNDEB | M19: Presidente | O19: =VLOOKUP(C19,'Página1'!B:I,1,FALSE()) -> #N/A | P19: 2
A20: 46100.391 | B20: Lilian Sayuri Ono | C20: 830.654.741-15 | D20: (66)99283-0493 | E20: onolilian11@gmail.com | F20: Sim | O20: =VLOOKUP(C20,'Página1'!B:I,1,FALSE()) -> 830.654.741-15
A21: 46100.392 | B21: Sandra Ribeiro de Oliveira | C21: 844.451.571-04 | D21: (62)98293-5940 | E21: sandradeoliveirajardins@gmail.com | F21: Não | G21: 27993 | H21: (62)98293-5940 | I21: APIACÁS | J21: Gestão municipal | K21: Técnico ADM Educacional | L21: Não existe | O21: =VLOOKUP(C21,'Página1'!B:I,1,FALSE()) -> #N/A | P21: 3
A22: 46100.392 | B22: Aparecida Salete Pires Pereira | C22: 502.883.931-04 | D22: (65)99988-1574 | E22: salethpires@gmail.com | F22: Sim | O22: =VLOOKUP(C22,'Página1'!B:I,1,FALSE()) -> 502.883.931-04
A23: 46100.393 | B23: Mariangela Morgan Feitosa | C23: 897.789.781-91 | D23: (66)98439-1840 | E23: mari-feitosa@hotmail.com | F23: Não | G23: 29393 | H23: (66)98439-1840 | I23: Nova Monte Verde | J23: CACS-Fundeb | M23: conselheira | O23: =VLOOKUP(C23,'Página1'!B:I,1,FALSE()) -> #N/A | P23: 4
A24: 46100.393 | B24: Rosilda Ribeiro Chagas | C24: 957.003.829-20 | D24: (66)99685-5867 | E24: rosildaeve@outlook.com | F24: Sim | O24: =VLOOKUP(C24,'Página1'!B:I,1,FALSE()) -> 957.003.829-20
A25: 46100.458 | B25: Fernanda Rodrigues Máximo | C25: 772.752.841-20 | D25: (66)99962-5625 | E25: ferrodrigues@novacanaadonorte.edu.mt.gov.br | F25: Sim | O25: =VLOOKUP(C25,'Página1'!B:I,1,FALSE()) -> 772.752.841-20

Sheet Página1
A1: Carimbo de data/hora | B1: CPF | C1: Endereço de e-mail | D1: Nome Completo: | E1: Confirme o E-mail | F1: Data de Nascimento | G1: Telefone (XX)XXXXX-XXXX | H1: Município que representa: | I1: Você faz parte do: | J1: Que cargo você ocupa na gestão municipal? | K1: Prezado(a) Gestor(a), Se existe algum caso de sucesso da gestão do transporte escolar no seu município, gostaríamos conhecer mais um pouco ao respeito. Por favor, relate de forma sucinta o caso de sucesso no espaço a seguir: | L1: Que cargo você ocupa no CACS-FUNDEB? | M1: Confirmação de veracidade dos dados
A2: 46073.598 | B2: 028.495.521-35 | C2: josidaluz201@gmail.com | D2: Josimeire da luz | E2: josidaluz201@gmail.com | F2: 32718 | G2: (66)98421-2529 | H2: ALTA FLORESTA | I2: Gestão municipal | J2: Técnico Administrativo Educacional | M2: Declaro que revisei e confirmo a veracidade de todas as informações prestadas neste formulário.
A3: 46073.611 | B3: 011.149.971-29 | C3: valdineimakohi1984@gmail.com | D3: Valdinei Makohin do Nascimento | E3: valdineimakohi1984@gmail.com | F3: 30705 | G3: (66)99919-6873 | H3: PARANAÍTA | I3: Gestão municipal | J3: Motorista escolar, e gestor veículo escolar | K3: Transporte escolar sistematizado e organizado | M3: Declaro que revisei e confirmo a veracidade de todas as informações prestadas neste formulário.
A4: 46073.642 | B4: 794.483.211-04 | C4: elisandrosilva12@hotmail.com | D4: Elisandro da Silva | E4: elisandrosilva12@hotmail.com | F4: 27782 | G4: (66)98457-2467 | H4: CARLINDA | I4: CACS-FUNDEB | L4: Presidente | M4: Declaro que revisei e confirmo a veracidade de todas as informações prestadas neste formulário.
A5: 46073.648 | B5: 040.738.891-50 | C5: irineusantana814@gmail.com | D5: IRINEU SANTANA RAUSCHKOLB | E5: irineusantana814@gmail.com | F5: 33569 | G5: (66)99939-9893 | H5: APIACÁS | I5: Gestão municipal | J5: TECNICO ADMINISTRATIVO E FINANCEIRO | M5: Declaro que revisei e confirmo a veracidade de todas as informações prestadas neste formulário.
A6: 46073.658 | B6: 650.632.441-49 | C6: secretaria@novacanaadonorte.mt.gov.br | D6: Genize Luna de Carvalho | E6: secretaria@novacanaadonorte.mt.gov.br | F6: 25764 | G6: (66)99995-7128 | H6: NOVA CANAÃ DO NORTE | I6: Gestão municipal | J6: Coordenador de Transporte Escolar | K6: Pela primeira vez, foi editado no município a Resolução com normas para o uso e disponibilidade do Transporte Escolar, pois até o ano de 2025, seguiamos regras e normas federais e estadual. RESOLUÇÃO Nº001/2026/CME/NCN Regulamenta as normas e procedimentos para gerenciamento e controle do Transporte Escolar em atendimento aos estudantes devidamente matriculados nas escolas da rede pública de ensino do Município de Nova Canaã do Norte-MT https://drive.google.com/file/d/1hzQz0YCXjcTmaDJR9XEqc5BdF7UStnaK/view?usp=sharing | M6: Declaro que revisei e confirmo a veracidade de todas as informações prestadas neste formulário.
A7: 46073.762 | B7: 090.833.181-92 | C7: luanasenaaraujjo@gmail.com | D7: LUANA DE SENA DE ARAÚJO | E7: luanasenaaraujjo@gmail.com | F7: 37494 | G7: (66)98412-4076 | H7: APIACÁS | I7: CACS-FUNDEB | L7: VICE - PRESIDENTE | M7: Declaro que revisei e confirmo a veracidade de todas as informações prestadas neste formulário.
A8: 46073.764 | B8: 176.154.818-21 | C8: zeapiacas@hotmail.com | D8: JOSÉ ROBERTO PEREIRA DA SILVA | E8: zeapiacas@hotmail.com | F8: 26992 | G8: (66)98422-9843 | H8: APIACÁS | I8: Gestão municipal | J8: SECRETÁRIO MUNICIPAL DE EDUCAÇÃO | M8: Declaro que revisei e confirmo a veracidade de todas as informações prestadas neste formulário.
A9: 46077.352 | B9: 998.947.421-49 | C9: elaine.souza@carlinda.edu.mt.gov.br | D9: Elaine Batista Costa de Souza | E9: elaine.souza@carlinda.edu.mt.gov.br | F9: 30394 | G9: (66)98404-0221 | H9: CARLINDA | I9: Gestão municipal | J9: Secretária Municipal de Educação | K9: Utilizamos o Transcolar Rural, tem nos ajudado a mapear rotas, sendo este uma exigência do governo do estado. | M9: Declaro que revisei e confirmo a veracidade de todas as informações prestadas neste formulário.
A10: 46077.36 | B10: 794.483.211-04 | C10: elisandrosilva12@hotmail.com | D10: Elisandro da Silva | E10: elisandrosilva12@hotmail.com | F10: 27782 | G10: (66)98457-2467 | H10: CARLINDA | I10: CACS-FUNDEB | L10: Presidente | M10: Declaro que revisei e confirmo a veracidade de todas as informações prestadas neste formulário.
A11: 46079.484 | B11: 731.237.221-04 | C11: daianemariana@gmail.com | D11: Daiane Mariana da Silva Benfica | E11: daianemariana@gmail.com | F11: 31772 | G11: (66)98428-8628 | H11: CARLINDA | I11: Gestão municipal | J11: Coordenadora Administrativa | M11: Declaro que revisei e confirmo a veracidade de todas as informações prestadas neste formulário.
A12: 46080.362 | B12: 020.147.301-13 | C12: altamiromizuc@gmail.com | D12: Altamiro Corrêa Leite Junior | E12: altamiromizuc@gmail.com | F12: 31829 | G12: (66)98432-1656 | H12: SANTA CRUZ DO XINGU | I12: Gestão municipal | J12: Secretario Municipal de Educação | K12: apoio com a DRE regional nos municipios, incentivo ao transporte. | M12: Declaro que revisei e confirmo a veracidade de todas as informações prestadas neste formulário.
A13: 46080.364 | B13: 011.797.911-26 | C13: bianorodrigues85@gmail.com | D13: Fabiano Jose Rodrigues | E13: bianorodrigues85@gmail.com | F13: 31121 | G13: (66)98408-1719 | H13: SANTA CRUZ DO XINGU | I13: Gestão municipal | J13: Supervivão e controle de Frotas Municipal da Educação | M13: Declaro que revisei e confirmo a veracidade de todas as informações prestadas neste formulário.
A14: 46083.61 | B14: 980.192.281-87 | C14: ildooliveiradasilva814@gmail.com | D14: Ildo Oliveira da Silva | E14: ildooliveiradasilva814@gmail.com | F14: 30380 | G14: (66)99915-6672 | H14: PARANAÍTA | I14: Gestão municipal | J14: diretor escolar | M14: Declaro que revisei e confirmo a veracidade de todas as informações prestadas neste formulário.
A15: 46083.611 | B15: 015.753.371-93 | C15: alicebrito88@hotmail.com | D15: Alice Maria Santos Brito | E15: alicebrito88@hotmail.com | F15: 31064 | G15: (66)99669-8224 | H15: PARANAÍTA | I15: CACS-FUNDEB | L15: Representante pais | M15: Declaro que revisei e confirmo a veracidade de todas as informações prestadas neste formulário.
A16: 46084.508 | B16: 688.369.021-20 | C16: maria.cavichia@novacanaadonorte.edu.mt.gov.br | D16: MARIA HELENA CAVICHIA | E16: maria.cavichia@novacanaadonorte.edu.mt.gov.br | F16: 26549 | G16: (66)99959-3564 | H16: NOVA CANAÃ DO NORTE | I16: CACS-FUNDEB | L16: PRESIDENTE | M16: Declaro que revisei e confirmo a veracidade de todas as informações prestadas neste formulário.
A17: 46084.556 | B17: 970.283.631-04 | C17: joselaine.sanches@edu.mt.gov.br | D17: Joselaine Bezerra Sanches | E17: Joselaine.sanches@edu.mt.gov.br | F17: 30804 | G17: (66)99923-6024 | H17: NOVA CANAÃ DO NORTE | I17: CACS-FUNDEB | L17: Presidente do transporte | M17: Declaro que revisei e confirmo a veracidade de todas as informações prestadas neste formulário.
A18: 46085.668 | B18: 957.003.829-20 | C18: rosildaeve@outlook.com | D18: ROSILDA RIBEIRO CHAGAS | E18: rosildaeve@outlook.com | F18: 27429 | G18: (66)99685-5867 | H18: NOVA CANAÃ DO NORTE | I18: CACS-FUNDEB | L18: REPRESENTANTE TITULAR DO EXECUTIVO | M18: Declaro que revisei e confirmo a veracidade de todas as informações prestadas neste formulário.
A19: 46087.601 | B19: 857.649.141-91 | C19: andreoliveiralima@hotmail.com | D19: André Oliveira Lima | E19: andreoliveiralima@hotmail.com | F19: 28359 | G19: (94)98413-5970 | H19: ALTA FLORESTA | I19: CACS-FUNDEB | L19: Presidente | M19: Declaro que revisei e confirmo a veracidade de todas as informações prestadas neste formulário.
A20: 46087.67 | B20: 830.654.741-15 | C20: onolilian11@gmail.com | D20: Lilian Sayuri Ono | E20: onolilian11@gmail.com | F20: 29016 | G20: (66)99283-0493 | H20: ALTA FLORESTA | I20: CACS-FUNDEB | L20: Conselheira CACS -FUNDEB | M20: Declaro que revisei e confirmo a veracidade de todas as informações prestadas neste formulário.
A21: 46087.671 | B21: 231.385.802-20 | C21: rosangelacunhadasilva2@gmail.com | D21: Rosangela Cunha da Silva | E21: rosangelacunhadasilva2@gmail.com | F21: 25060 | G21: (66)99220-1350 | H21: ALTA FLORESTA | I21: CACS-FUNDEB | L21: Conselheiro | M21: Declaro que revisei e confirmo a veracidade de todas as informações prestadas neste formulário.
A22: 46087.672 | B22: 894.809.451-34 | C22: conselhoaltafloresta@gmail.com | D22: JOUSE MARIA CONRADO | E22: conselhoaltafloresta@gmail.com | F22: 28899 | G22: (66)99204-5216 | H22: ALTA FLORESTA | I22: CACS-FUNDEB | L22: CONSELHEIRA | M22: Declaro que revisei e confirmo a veracidade de todas as informações prestadas neste formulário.
A23: 46087.675 | B23: 090.050.678-45 | C23: marcelo.bruno@ifmt.edu.br | D23: Marcelo Alexandre Bruno | E23: marcelo.bruno@ifmt.edu.br | F23: 25075 | G23: (66)98427-2859 | H23: ALTA FLORESTA | I23: CACS-FUNDEB | L23: Suplente educação superior | M23: Declaro que revisei e confirmo a veracidade de todas as informações prestadas neste formulário.
A24: 46087.757 | B24: 848.226.941-00 | C24: neu_caf@hotmail.com | D24: Neuzira Rosa de Brito | E24: neu_caf@hotmail.com | F24: 28454 | G24: (66)99242-3526 | H24: ALTA FLORESTA | I24: CACS-FUNDEB | L24: Conselheira titular | M24: Declaro que revisei e confirmo a veracidade de todas as informações prestadas neste formulário.
A25: 46087.787 | B25: 830.654.741-15 | C25: onolilian11@gmail.com | D25: Lilian Sayuri Ono | E25: onolilian11@gmail.com | F25: 29016 | G25: (66)99283-0493 | H25: ALTA FLORESTA | I25: CACS-FUNDEB | L25: Consslheira | M25: Declaro que revisei e confirmo a veracidade de todas as informações prestadas neste formulário.
A26: 46090.435 | B26: 009.976.891-70 | C26: tiagobenficadeassis@gmail.com | D26: Tiago Benfica de Assis | E26: tiagobenficadeassis@gmail.com | F26: 31391 | G26: (66)98429-9272 | H26: ALTA FLORESTA | I26: CACS-FUNDEB | L26: CONSELHEIRO DA CÂMARA DO FUNDEB - REPRESENTANTE DO EXECUTIVO | M26: Declaro que revisei e confirmo a veracidade de todas as informações prestadas neste formulário.
A27: 46090.627 | B27: 991.302.971-68 | C27: sasso.123@hotmail.com | D27: Rudnei Moraes Sasso | E27: sasso.123@hotmail.com | F27: 29332 | G27: (66)99630-1179 | H27: ALTA FLORESTA | I27: Gestão municipal | J27: Motorista Escola | M27: Declaro que revisei e confirmo a veracidade de todas as informações prestadas neste formulário.
A28: 46090.933 | B28: 969.569.331-87 | C28: roni_nx@hotmail.com | D28: Ronivaldo Marques Pinto | E28: roni_nx@hotmail.com | F28: 30631 | G28: (66)99955-0748 | H28: PARANAÍTA | I28: Gestão municipal | J28: Condutor de Veículo Escolar | K28: . | M28: Declaro que revisei e confirmo a veracidade de todas as informações prestadas neste formulário.
A29: 46091.714 | B29: 032.294.371-01 | C29: everson.wiechorek@novabandeirantes.edu.mt.gov.br | D29: Everson Wiechorek | E29: everson.wiechorek@novabandeirantes.edu.mt.gov.br | F29: 32775 | G29: (66)98459-2161 | H29: NOVA BANDEIRANTES | I29: Gestão municipal | J29: Técnico do Transporte Escolar | M29: Declaro que revisei e confirmo a veracidade de todas as informações prestadas neste formulário.
A30: 46091.719 | B30: 025.590.831-83 | C30: elizeubaioco88@gmail.com | D30: Elizeu da Silva Baioco | E30: elizeubaioco88@gmail.com | F30: 32231 | G30: (66)98436-4794 | H30: NOVA BANDEIRANTES | I30: CACS-FUNDEB | L30: Presidente | M30: Declaro que revisei e confirmo a veracidade de todas as informações prestadas neste formulário.
A31: 46093.518 | B31: 043.728.121-32 | C31: erdileneonofre@outlook.com | D31: Erdilene Bueno Onofre | E31: erdileneonofre@outlook.com | F31: 33990 | G31: (66)98419-2180 | H31: APIACÁS | I31: CACS-FUNDEB | L31: Secretária | M31: Declaro que revisei e confirmo a veracidade de todas as informações prestadas neste formulário.
A32: 46093.621 | B32: 018.772.109-27 | C32: claumar_fiel@hotmail.com | D32: Claudia Sibeli Coelho Fiel | E32: claumar_fiel@hotmail.com | F32: 28564 | G32: (66)98409-2312 | H32: NOVA BANDEIRANTES | I32: Gestão municipal | J32: Técnica municipal | M32: Declaro que revisei e confirmo a veracidade de todas as informações prestadas neste formulário.
A33: 46094.697 | B33: 041.306.701-74 | C33: rogerio@edu.novamonteverde.mt.gov.br | D33: ROGERIO BRITO DOS SANTOS | E33: rogerio@edu.novamonteverde.mt.gov.br | F33: 33399 | G33: (66)98467-9451 | H33: NOVA MONTE VERDE | I33: Gestão municipal | J33: TÉCNICO TRANSCOLAR | M33: Declaro que revisei e confirmo a veracidade de todas as informações prestadas neste formulário.
A34: 46097.481 | B34: 897.709.781-91 | C34: mari-feitosa@hotmail.com | D34: Mariangela Morgan Feitosa | E34: mari-feitosa@hotmail.com | F34: 29393 | G34: (66)98439-1840 | H34: NOVA MONTE VERDE | I34: CACS-FUNDEB | L34: conselheiro | M34: Declaro que revisei e confirmo a veracidade de todas as informações prestadas neste formulário.
A35: 46098.622 | B35: 058.230.421-08 | C35: Talison1478@gmail.com | D35: Talison rafael de lima ouvernei | E35: Talison1478@gmail.com | F35: 36055 | G35: (66)98416-0491 | H35: NOVA MONTE VERDE | I35: Gestão municipal | J35: Assessor Administrativo da Secretaria de Educação | M35: Declaro que revisei e confirmo a veracidade de todas as informações prestadas neste formulário.
A36: 46098.615 | B36: 795.415.009-78 | C36: cirenepinknmv@hotmail.com | D36: Cirene Aparecida da Rosa Mendes | E36: cirenepinknmv@hotmail.com | F36: 25252 | G36: (66)98439-2918 | H36: NOVA MONTE VERDE | I36: CACS-FUNDEB | L36: Presidente | M36: Declaro que revisei e confirmo a veracidade de todas as informações prestadas neste formulário.
A37: 46098.735 | B37: 061.056.901-50 | C37: jaquelineleal67@gmail.com | D37: Jaqueline Leal | E37: jaquelineleal67@gmail.com | F37: 36116 | G37: (66)99245-5001 | H37: ALTA FLORESTA | I37: CACS-FUNDEB | L37: Assessora Pedagógica do CME | M37: Declaro que revisei e confirmo a veracidade de todas as informações prestadas neste formulário.
A38: 46099.416 | B38: 772.752.841-20 | C38: ferrodrigues@novacanaadonorte.edu.mt.gov.br | D38: Fernanda Rodrigues Maximo | E38: ferrodrigues@novacanaadonorte.edu.mt.gov.br | F38: 28284 | G38: (66)99962-5625 | H38: NOVA CANAÃ DO NORTE | I38: Gestão municipal | J38: AA - Secretaria de Transporte Escolar | K38: Responsável por alimentar o Sistema Ômega/Operacional | M38: Declaro que revisei e confirmo a veracidade de todas as informações prestadas neste formulário.
A39: 46099.519 | B39: 950.825.901-97 | C39: conselhoaltafloresta@gmail.com | D39: Marco Antonio A. Faraco | E39: conselhoaltafloresta@gmail.com | F39: 24591 | G39: (66)99232-4866 | H39: ALTA FLORESTA | I39: CACS-FUNDEB | L39: Assessoria Pedagógica | M39: Declaro que revisei e confirmo a veracidade de todas as informações prestadas neste formulário.
A40: 46099.743 | B40: 502.883.931-04 | C40: salethpires@gmail.com | D40: Aparecida Salete Pires Pereira | E40: salethpires@gmail.com | F40: 25796 | G40: (65)99988-1574 | H40: ALTA FLORESTA | I40: CACS-FUNDEB | L40: Sou do assessoramento técnico | M40: Declaro que revisei e confirmo a veracidade de todas as informações prestadas neste formulário.
...
