Workbook

Sheet Respostas ao formulário 1
A1: Carimbo de data/hora | B1: Endereço de e-mail | C1: Nome Completo: | D1: Confirme o E-mail | E1: CPF | F1: Data de Nascimento | G1: Telefone (XX)XXXXX-XXXX | H1: Município que representa: | I1: Você faz parte do: | J1: Que cargo você ocupa na gestão municipal? | K1: Prezado(a) Gestor(a), Se existe algum caso de sucesso da gestão do transporte escolar no seu município, gostaríamos conhecer mais um pouco ao respeito. Por favor, relate de forma sucinta o caso de sucesso no espaço a seguir: | L1: Que cargo você ocupa no CACS-FUNDEB? | M1: Confirmação de veracidade dos dados
A2: 46107.681 | B2: smedoverlandia@gmail.com | C2: ALZIRO ZARU PIRES DA SILVA | D2: smedoverlandia@gmail.com | E2: 323.377.011-15 | F2: 23085 | G2: (64)98431-9400 | H2: Doverlândia (GO) | I2: Gestão municipal | J2: Chefe dos Transportadores | M2: Declaro que revisei e confirmo a veracidade de todas as informações prestadas neste formulário.
A3: 46107.711 | B3: sec.educacao@cachoeiraalta.go.gov.br | C3: luciene guimarães franco | D3: sec.educacao@cachoeiraalta.go.gov.br | E3: 576.203.931-53 | F3: 25800 | G3: (64)99615-0014 | H3: Cachoeira Alta (GO) | I3: CACS-FUNDEB | L3: gestora municipal de educação e cultura | M3: Declaro que revisei e confirmo a veracidade de todas as informações prestadas neste formulário.
A4: 46108.34 | B4: aparecidat197@gmail.com | C4: TANIA APARECIDA NASCIMENTO PELISARI | D4: aparecidat197@gmail.com | E4: 037.474.671-05 | F4: 32715 | G4: (66)99982-0064 | H4: Santa Rita do Araguaia (GO) | I4: CACS-FUNDEB | L4: REPRESENTANTE DA SECRETARIA MUNICIPAL DE EDUCAÇÃO | M4: Declaro que revisei e confirmo a veracidade de todas as informações prestadas neste formulário.
A5: 46108.364 | B5: dorvalino1987@hotmail.com | C5: Dorvalino Ferreira Barros | D5: dorvalino1987@hotmail.com | E5: 016.281.851-39 | F5: 32037 | G5: (64)99907-0479 | H5: Caiapônia (GO) | I5: Gestão municipal | J5: Coordenador do Transporte Escolar | M5: Declaro que revisei e confirmo a veracidade de todas as informações prestadas neste formulário.
A6: 46108.367 | B6: dorvalino1987@hotmail.com | C6: Dorvalino Ferreira Barros | D6: dorvalino1987@hotmail.com | E6: 016.281.851-39 | F6: 32037 | G6: (64)99907-0479 | H6: Caiapônia (GO) | I6: Gestão municipal | J6: Coordenador do Transporte Escolar | M6: Declaro que revisei e confirmo a veracidade de todas as informações prestadas neste formulário.
A7: 46108.389 | B7: helrigle@gnsil.com | C7: Meire Helrigle Goulart e Carvalho | D7: helrigle@gmail.com | E7: 347.109.141-68 | F7: 23711 | G7: (64)99626-7735 | H7: Caiapônia (GO) | I7: Gestão municipal | J7: Dirigente municipal | M7: Declaro que revisei e confirmo a veracidade de todas as informações prestadas neste formulário.
A8: 46108.394 | B8: helrigle@gmail.com | C8: Meire Helrigle Goulart e Carvalho | D8: helrigle@gmail.com | E8: 357.209.141-68 | F8: 23711 | G8: (64)99626-7735 | H8: Caiapônia (GO) | I8: Gestão municipal | J8: Dirigente municipal | M8: Declaro que revisei e confirmo a veracidade de todas as informações prestadas neste formulário.
A9: 46108.458 | B9: billtransporte2025@hotmail.com | C9: Edilson Silva Alarcão | D9: billtransporte2025@hotmail.com | E9: 617.753.201-20 | F9: 25729 | G9: (64)99947-2552 | H9: Cachoeira Alta (GO) | I9: Gestão municipal | J9: secretário de transporte | M9: Declaro que revisei e confirmo a veracidade de todas as informações prestadas neste formulário.
A10: 46108.623 | B10: transporteescolar@cachoeiraalta.go.gov.br | C10: Matheus Vinícius Vieira Santos | D10: transporteescolar@cachoeiraalta.go.gov.br | E10: 041.321.081-20 | F10: 35017 | G10: (64)98133-1281 | H10: Cachoeira Alta (GO) | I10: Gestão municipal | J10: Coordenador de Transporte | M10: Declaro que revisei e confirmo a veracidade de todas as informações prestadas neste formulário.
A11: 46108.809 | B11: iraneidemms@outlook.com | C11: Iraneide Maria de Morais Silveira | D11: Iraneidemms@outlook.com | E11: 597.611.801-15 | F11: 26391 | G11: (64)99976-5379 | H11: Cachoeira Alta (GO) | I11: CACS-FUNDEB | L11: Presidente | M11: Declaro que revisei e confirmo a veracidade de todas as informações prestadas neste formulário.
A12: 46109.798 | B12: leomarinacio22@hotmail.com | C12: Leomar Inácio da Silva | D12: leomarinacio22@hotmail.com | E12: 698.382.671-04 | F12: 29265 | G12: (66)99622-5784 | H12: Santa Rita do Araguaia (GO) | I12: Gestão municipal | J12: Coordenador do Transporte Escolar | M12: Declaro que revisei e confirmo a veracidade de todas as informações prestadas neste formulário.
A13: 46112.385 | B13: Iraneidemms@outlook.com | C13: Iraneide Maria de Morais Silveira | D13: Iraneidemms@outlook.com | E13: 597.611.801-15 | F13: 26391 | G13: (64)99976-5379 | H13: Cachoeira Alta (GO) | I13: CACS-FUNDEB | L13: presidente | M13: Declaro que revisei e confirmo a veracidade de todas as informações prestadas neste formulário.
A14: 46112.391 | B14: lilianalves_pedro@hotmail.com | C14: Lilian Lemes Silva | D14: lilianalves_pedro@hotmail.com | E14: 916.647.051-04 | F14: 29337 | G14: (64)99329-9420 | H14: Porteirão (GO) | I14: Gestão municipal | J14: Tecnica da Secretaria Municipal de Educação | M14: Declaro que revisei e confirmo a veracidade de todas as informações prestadas neste formulário.
A15: 46112.393 | B15: lilianalves_pedro@hotmail.com | C15: Lilian Lemes Silva | D15: lilianalves_pedro@hotmail.com | E15: 916.647.051-04 | F15: 29337 | G15: (64)99329-9420 | H15: Porteirão (GO) | I15: Gestão municipal | J15: Técnica da Secretaria Municipal de Educação | M15: Declaro que revisei e confirmo a veracidade de todas as informações prestadas neste formulário.
A16: 46112.646 | B16: m.lucia34@hotmail.com | C16: Maria Lúcia Pereira dps Santos | D16: m.lucia34@hotmail.com | E16: 712.177.031-87 | F16: 28162 | G16: (64)99318-3209 | H16: Perolândia (GO) | I16: Gestão municipal | J16: Coordenadora do Transporte escolar | M16: Declaro que revisei e confirmo a veracidade de todas as informações prestadas neste formulário.
A17: 46112.649 | B17: m.lucia34@hotmail.com | C17: Maria Lúcia Pereira dos Santos | D17: m.lucia34@hotmail.com | E17: 712.177.031-87 | F17: 28162 | G17: (64)99318-3209 | H17: Perolândia (GO) | I17: Gestão municipal | J17: Coordenador do Transporte Escolar | M17: Declaro que revisei e confirmo a veracidade de todas as informações prestadas neste formulário.
A18: 46112.651 | B18: eugeniapereira845@gmail.com | C18: Eugenia Pereira dos Santos Souza | D18: eugeniapereira845@gmail.com | E18: 877.708.651-15 | F18: 29359 | G18: (64)99320-5025 | H18: Perolândia (GO) | I18: CACS-FUNDEB | L18: Conselheira | M18: Declaro que revisei e confirmo a veracidade de todas as informações prestadas neste formulário.
A19: 46112.654 | B19: eugeniapereira845@gmail.com | C19: Eugenia Pereira dos Santos Souza | D19: eugeniapereira845@gmail.com | E19: 877.708.651-15 | F19: 29359 | G19: (64)99320-5025 | H19: Perolândia (GO) | I19: CACS-FUNDEB | L19: Conselheira | M19: Declaro que revisei e confirmo a veracidade de todas as informações prestadas neste formulário.
A20: 46118.331 | B20: andreoliveiralima@hormail.com | C20: Andre Oliveira Lima | D20: andreoliveiralima@hotmail.com | E20: 857.649.141-91 | F20: 28359 | G20: (94)98413-5970 | H20: Araguainha (MT) | I20: CACS-FUNDEB | L20: Presidência do Cacs Fundeb | M20: Declaro que revisei e confirmo a veracidade de todas as informações prestadas neste formulário.
A21: 46118.538 | B21: patysousaguerreiro@hotmail.com | C21: Patrícia de Sousa Guerreiro | D21: patysousaguerreiro@hotmail.com | E21: 928.754.321-68 | F21: 28668 | G21: (62)98603-4910 | H21: São Simão (GO) | I21: Gestão municipal | J21: Coordenadora Transporte Escolar | M21: Declaro que revisei e confirmo a veracidade de todas as informações prestadas neste formulário.
A22: 46118.57 | B22: rosangelacarolisa@hotmail.com | C22: Rosângela Carvalho de Oliveira Santos | D22: rosangelacarolisa@hotmail.com | E22: 089.354.908-81 | F22: 24713 | G22: (66)99903-2946 | H22: Alto Taquari (MT) | I22: Gestão municipal | J22: Coordenadora | M22: Declaro que revisei e confirmo a veracidade de todas as informações prestadas neste formulário.
A23: 46118.582 | B23: joaodias.dsm@gmail.com | C23: Joao Dias de Freitas | D23: joaodias.dsm@gmail.com | E23: 437.518.811-15 | F23: 25051 | G23: (66)99986-8259 | H23: Alto Araguaia (MT) | I23: Gestão municipal | J23: Secretario Administrativo | M23: Declaro que revisei e confirmo a veracidade de todas as informações prestadas neste formulário.
A24: 46118.583 | B24: keiko0cmbr@gmail.com | C24: Thalya Aparecida Viana da silva | D24: keiko0cmbr@gmail.com | E24: 066.707.531-36 | F24: 36317 | G24: (66)99928-8083 | H24: Alto Araguaia (MT) | I24: Gestão municipal | J24: coordenadora geoter | M24: Declaro que revisei e confirmo a veracidade de todas as informações prestadas neste formulário.
A25: 46118.601 | B25: keilafreitas.pohlman@gmail.com | C25: Keila Martins de Freitas e Zurita Pohlman | D25: keilafreitas.pohlman@gmail.com | E25: 001.547.661-86 | F25: 30414 | G25: (66)99634-3309 | H25: Ponte Branca (MT) | I25: Gestão municipal | J25: Direção escolar | M25: Declaro que revisei e confirmo a veracidade de todas as informações prestadas neste formulário.
A26: 46118.61 | B26: fbnicodemos@gmail.com | C26: Fábio Nicodemos Domingues Moura | D26: fbnicodemos@gmail.com | E26: 886.767.261-68 | F26: 29307 | G26: (65)99998-5617 | H26: Ponte Branca (MT) | I26: Gestão municipal | J26: Técnico administrativo educacional | M26: Declaro que revisei e confirmo a veracidade de todas as informações prestadas neste formulário.
A27: 46119.371 | B27: daynamota321@gmail.com | C27: Dayana Cristina Mota | D27: dayanamota321@gmail.com | E27: 016.291.261-79 | F27: 31369 | G27: (64)98125-4179 | H27: Amorinópolis (GO) | I27: Gestão municipal | J27: Secretaria Municipal de Educação | M27: Declaro que revisei e confirmo a veracidade de todas as informações prestadas neste formulário.
A28: 46119.666 | B28: mauricelianfarias@gmail.com | C28: MAURICÉLIA DO NASCIMENTO FARIAS | D28: mauricelianfarias@gmail.com | E28: 938.154.091-87 | F28: 29387 | G28: (64)99606-1526 | H28: Montividiu (GO) | I28: Gestão municipal | J28: SECRETÁRIA DE EDUCAÇÃO | M28: Declaro que revisei e confirmo a veracidade de todas as informações prestadas neste formulário.
A29: 46119.671 | B29: carvalhopedagoga@hotmail.com | C29: Vanea Martins de Carvalho | D29: carvalhopedagoga@hotmail.com | E29: 409.576.161-04 | F29: 24867 | G29: (64)99259-8515 | H29: Aparecida do Rio Doce (GO) | I29: Gestão municipal | J29: Secretaria Municipal de Educação | M29: Declaro que revisei e confirmo a veracidade de todas as informações prestadas neste formulário.
A30: 46119.676 | B30: neuma_mtv@hotmail.com | C30: NEUMA ANDRADE DOS SANTOS SOUZA | D30: neuma_mtv@hotmail.com | E30: 001.371.251-30 | F30: 30351 | G30: (64)99932-4754 | H30: Montividiu (GO) | I30: Gestão municipal | J30: COORDENADORA DE GESTÃO EDUCACIONAL | M30: Declaro que revisei e confirmo a veracidade de todas as informações prestadas neste formulário.
A31: 46119.698 | B31: ted.mtv@hotmail.com | C31: ELIAS DIAS DOS SANTOS | D31: ted.mtv@hotmail.com | E31: 921.116.961-53 | F31: 28128 | G31: (64)99611-0557 | H31: Montividiu (GO) | I31: Gestão municipal | J31: MOTORISTA | M31: Declaro que revisei e confirmo a veracidade de todas as informações prestadas neste formulário.
A32: 46119.705 | B32: salesduda369@gmail.com | C32: MARIA EDUARDA DE SALES GOUVEIA DANTAS | D32: salesduda369@gmail.com | E32: 088.166.151-17 | F32: 38419 | G32: (64)99968-6217 | H32: Montividiu (GO) | I32: Gestão municipal | J32: DIRETORA DO TRANSPORTE ESCOLAR | M32: Declaro que revisei e confirmo a veracidade de todas as informações prestadas neste formulário.
A33: 46120.411 | B33: cacildahborges@gmail.com | C33: Cacilda Helena Borges | D33: Cacildahborges@gmail.com | E33: 418.241.301-63 | F33: 24684 | G33: (64)99931-2442 | H33: Bom Jesus de Goiás (GO) | I33: Gestão municipal | J33: Coordenadora Pedagógica do Transporte Escolar | M33: Declaro que revisei e confirmo a veracidade de todas as informações prestadas neste formulário.
A34: 46120.434 | B34: educacao@bomjesus.go.gov.br | C34: IRACILDA MARIA NUNES VELUTA ALVES | D34: educacao@bomjesus.go.gov.br | E34: 576.372.531-04 | F34: 26564 | G34: (64)98167-9305 | H34: Bom Jesus de Goiás (GO) | I34: CACS-FUNDEB | L34: assessora administrativa | M34: Declaro que revisei e confirmo a veracidade de todas as informações prestadas neste formulário.
A35: 46120.438 | B35: educacao@bomjesus.go.gov.br | C35: ELIENE MIRANDA DA HORA | D35: educacao@bomjesus.go.gov.br | E35: 859.778.961-15 | F35: 28103 | G35: (64)98134-4141 | H35: Bom Jesus de Goiás (GO) | I35: Gestão municipal | J35: SECRETÁRIA MUNICIPAL DE EDUCAÇÃO | M35: Declaro que revisei e confirmo a veracidade de todas as informações prestadas neste formulário.
A36: 46121.685 | B36: karyne.semedcr@gmail.com | C36: Karyne Lourraine Almeida Pádua | D36: karyne.semedcr@gmail.com | E36: 051.206.131-95 | F36: 34809 | G36: (67)98220-8179 | H36: Costa Rica (MS) | I36: Gestão municipal | J36: Alimentação do sistema sete e prestação de convênios do estado | M36: Declaro que revisei e confirmo a veracidade de todas as informações prestadas neste formulário.
A37: 46121.687 | B37: secretariaeducacao@cassilandia.ms.gov.br | C37: Gabriel Wanderley de Mendonça | D37: secretariaeducacao@cassilandia.ms.gov.br | E37: 000.596.861-54 | F37: 30385 | G37: (67)98104-4997 | H37: Cassilândia (MS) | I37: Gestão municipal | J37: Assessor Escolar | M37: Declaro que revisei e confirmo a veracidade de todas as informações prestadas neste formulário.
A38: 46121.697 | B38: transporteescolardecassilandia@gmail.com | C38: Romeu Goulart da Silva | D38: transporteescolardecassilandia@gmail.com | E38: 312.097.501-04 | F38: 22943 | G38: (67)98129-2310 | H38: Cassilândia (MS) | I38: Gestão municipal | J38: Escriturário | M38: Declaro que revisei e confirmo a veracidade de todas as informações prestadas neste formulário.
A39: 46121.705 | B39: franzwillians@gmail.com | C39: FRANZ WILLIANS COIMBRA MARTINS | D39: franzwillians@gmail.com | E39: 851.073.361-91 | F39: 28648 | G39: (67)99337-0272 | H39: Cassilândia (MS) | I39: Gestão municipal | J39: CHEFE DE DIVISÃO DO TRANSPORTE ESCOLAR | M39: Declaro que revisei e confirmo a veracidade de todas as informações prestadas neste formulário.
A40: 46122.379 | B40: keily_nunes@hotmail.com | C40: Keily Junior Almeida Nunes | D40: Keily_nunes@hotmail.com | E40: 977.467.621-15 | F40: 30211 | G40: (67)99603-1501 | H40: Costa Rica (MS) | I40: Gestão municipal | J40: Coordenador transporte escolar | K40: Oficina própria | M40: Declaro que revisei e confirmo a veracidade de todas as informações prestadas neste formulário.
...

Sheet Inscritos
A1: Município | B1: Inscritos | C1: CACS-FUNDEB | D1: Gestão municipal | E1: Data
A2: Alcinópolis (MS) | B2: =COUNTIF('Respostas ao formulário 1'!$H$2:$H$207,A2) -> 1 | C2: =COUNTIFS('Respostas ao formulário 1'!$H$2:$H$182,$A2,'Respostas ao formulário 1'!$I$2:$I$182,C$1) -> 0 | D2: =COUNTIFS('Respostas ao formulário 1'!$H$2:$H$182,$A2,'Respostas ao formulário 1'!$I$2:$I$182,D$1) -> 1 | E2: =VLOOKUP(A2,Datas!A:B,2,FALSE) -> 46142
A3: Alto Araguaia (MT) | B3: =COUNTIF('Respostas ao formulário 1'!$H$2:$H$207,A3) -> 2 | C3: =COUNTIFS('Respostas ao formulário 1'!$H$2:$H$182,$A3,'Respostas ao formulário 1'!$I$2:$I$182,C$1) -> 0 | D3: =COUNTIFS('Respostas ao formulário 1'!$H$2:$H$182,$A3,'Respostas ao formulário 1'!$I$2:$I$182,D$1) -> 2 | E3: =VLOOKUP(A3,Datas!A:B,2,FALSE) -> 46142
A4: Alto Garças (MT) | B4: =COUNTIF('Respostas ao formulário 1'!$H$2:$H$207,A4) -> 2 | C4: =COUNTIFS('Respostas ao formulário 1'!$H$2:$H$182,$A4,'Respostas ao formulário 1'!$I$2:$I$182,C$1) -> 0 | D4: =COUNTIFS('Respostas ao formulário 1'!$H$2:$H$182,$A4,'Respostas ao formulário 1'!$I$2:$I$182,D$1) -> 2 | E4: =VLOOKUP(A4,Datas!A:B,2,FALSE) -> 46142
A5: Alto Taquari (MT) | B5: =COUNTIF('Respostas ao formulário 1'!$H$2:$H$207,A5) -> 1 | C5: =COUNTIFS('Respostas ao formulário 1'!$H$2:$H$182,$A5,'Respostas ao formulário 1'!$I$2:$I$182,C$1) -> 0 | D5: =COUNTIFS('Respostas ao formulário 1'!$H$2:$H$182,$A5,'Respostas ao formulário 1'!$I$2:$I$182,D$1) -> 1 | E5: =VLOOKUP(A5,Datas!A:B,2,FALSE) -> 46142
A6: Amorinópolis (GO) | B6: =COUNTIF('Respostas ao formulário 1'!$H$2:$H$207,A6) -> 6 | C6: =COUNTIFS('Respostas ao formulário 1'!$H$2:$H$182,$A6,'Respostas ao formulário 1'!$I$2:$I$182,C$1) -> 1 | D6: =COUNTIFS('Respostas ao formulário 1'!$H$2:$H$182,$A6,'Respostas ao formulário 1'!$I$2:$I$182,D$1) -> 5 | E6: =VLOOKUP(A6,Datas!A:B,2,FALSE) -> 46142
A7: Aparecida do Rio Doce (GO) | B7: =COUNTIF('Respostas ao formulário 1'!$H$2:$H$207,A7) -> 1 | C7: =COUNTIFS('Respostas ao formulário 1'!$H$2:$H$182,$A7,'Respostas ao formulário 1'!$I$2:$I$182,C$1) -> 0 | D7: =COUNTIFS('Respostas ao formulário 1'!$H$2:$H$182,$A7,'Respostas ao formulário 1'!$I$2:$I$182,D$1) -> 1 | E7: =VLOOKUP(A7,Datas!A:B,2,FALSE) -> 46142
A8: Aparecida do Taboado (MS) | B8: =COUNTIF('Respostas ao formulário 1'!$H$2:$H$207,A8) -> 0 | C8: =COUNTIFS('Respostas ao formulário 1'!$H$2:$H$182,$A8,'Respostas ao formulário 1'!$I$2:$I$182,C$1) -> 0 | D8: =COUNTIFS('Respostas ao formulário 1'!$H$2:$H$182,$A8,'Respostas ao formulário 1'!$I$2:$I$182,D$1) -> 0 | E8: =VLOOKUP(A8,Datas!A:B,2,FALSE) -> 46142
A9: Aporé (GO) | B9: =COUNTIF('Respostas ao formulário 1'!$H$2:$H$207,A9) -> 2 | C9: =COUNTIFS('Respostas ao formulário 1'!$H$2:$H$182,$A9,'Respostas ao formulário 1'!$I$2:$I$182,C$1) -> 0 | D9: =COUNTIFS('Respostas ao formulário 1'!$H$2:$H$182,$A9,'Respostas ao formulário 1'!$I$2:$I$182,D$1) -> 2 | E9: =VLOOKUP(A9,Datas!A:B,2,FALSE) -> 46142
A10: Araguainha (MT) | B10: =COUNTIF('Respostas ao formulário 1'!$H$2:$H$207,A10) -> 1 | C10: =COUNTIFS('Respostas ao formulário 1'!$H$2:$H$182,$A10,'Respostas ao formulário 1'!$I$2:$I$182,C$1) -> 1 | D10: =COUNTIFS('Respostas ao formulário 1'!$H$2:$H$182,$A10,'Respostas ao formulário 1'!$I$2:$I$182,D$1) -> 0 | E10: =VLOOKUP(A10,Datas!A:B,2,FALSE) -> 46142
A11: Arenópolis (GO) | B11: =COUNTIF('Respostas ao formulário 1'!$H$2:$H$207,A11) -> 0 | C11: =COUNTIFS('Respostas ao formulário 1'!$H$2:$H$182,$A11,'Respostas ao formulário 1'!$I$2:$I$182,C$1) -> 0 | D11: =COUNTIFS('Respostas ao formulário 1'!$H$2:$H$182,$A11,'Respostas ao formulário 1'!$I$2:$I$182,D$1) -> 0 | E11: =VLOOKUP(A11,Datas!A:B,2,FALSE) -> 46142
A12: Bom Jesus de Goiás (GO) | B12: =COUNTIF('Respostas ao formulário 1'!$H$2:$H$207,A12) -> 3 | C12: =COUNTIFS('Respostas ao formulário 1'!$H$2:$H$182,$A12,'Respostas ao formulário 1'!$I$2:$I$182,C$1) -> 1 | D12: =COUNTIFS('Respostas ao formulário 1'!$H$2:$H$182,$A12,'Respostas ao formulário 1'!$I$2:$I$182,D$1) -> 2 | E12: =VLOOKUP(A12,Datas!A:B,2,FALSE) -> #N/A
A13: Cachoeira Alta (GO) | B13: =COUNTIF('Respostas ao formulário 1'!$H$2:$H$207,A13) -> 5 | C13: =COUNTIFS('Respostas ao formulário 1'!$H$2:$H$182,$A13,'Respostas ao formulário 1'!$I$2:$I$182,C$1) -> 3 | D13: =COUNTIFS('Respostas ao formulário 1'!$H$2:$H$182,$A13,'Respostas ao formulário 1'!$I$2:$I$182,D$1) -> 2 | E13: =VLOOKUP(A13,Datas!A:B,2,FALSE) -> 46142
... A57: SÃO JOSÉ DO XINGU | B57: =COUNTIF('Respostas ao formulário 1'!$H$2:$H$207,A57) -> 0 | C57: =COUNTIFS('Respostas ao formulário 1'!$H$2:$H$182,$A57,'Respostas ao formulário 1'!$I$2:$I$182,C$1) -> 0 | D57: =COUNTIFS('Respostas ao formulário 1'!$H$2:$H$182,$A57,'Respostas ao formulário 1'!$I$2:$I$182,D$1) -> 0 | E57: =VLOOKUP(A57,Datas!A:B,2,FALSE) -> #N/A
A58: Total | B58: =SUM(B2:B57) -> 109 | C58: =SUM(C5:C57) -> 21 | D58: =SUM(D2:D57) -> 88 | F58: =SUM(C28:C52) -> 10 | G58: =SUM(D28:D52) -> 50 | H58: =SUM(C2:C11,C13:C27) -> 10 | I58: =SUM(D2:D11,D13:D27) -> 36 | J58: =SUM(C12,C53:C57) -> 1 | K58: =SUM(D12,D53:D57) -> 2
A59: Munípios Inscritos | C59: =COUNTIF(C2:C57,">0") -> 17 | D59: =COUNTIF(D2:D57,">0") -> 40
B60: Inscritos | C60: CACS-FUNDEB | D60: Gestão municipal | F60: CACs - Data 29/04/2026 | G60: Gestores - Data 29/04/2026 | H60: CACs - Data 30/04/2026 | I60: Gestores - Data 30/04/2026 | J60: CACs - Sem data | K60: Gestores -Sem data

Sheet Datas
A1: Munícipip | B1: Data
A2: Jataí (GO) | B2: 46141
A3: Lagoa Santa (GO) | B3: 46141
A4: Maurilândia (GO) | B4: 46141
A5: Mineiros (GO) | B5: 46141
A6: Montividiu (GO) | B6: 46141
A7: Palestina de Goiás (GO) | B7: 46141
A8: Paraíso das Águas (MS) | B8: 46141
A9: Paranaíba (MS) | B9: 46141
A10: Paranaiguara (GO) | B10: 46141
A11: Perolândia (GO) | B11: 46141
A12: Piranhas (GO) | B12: 46141
A13: Ponte Branca (MT) | B13: 46141
... A51: Itarumã (GO) | B51: 46142
