Workbook

Sheet Respostas ao formulário 1
A1: Carimbo de data/hora | B1: Endereço de e-mail | C1: Nome Completo: | D1: CPF | E1: Data de Nascimento | F1: Telefone (XX)XXXXX-XXXX | G1: Município que representa: | H1: Você faz parte do: | I1: Que cargo você ocupa na gestão municipal? | J1: Prezado(a) Gestor(a), Se existe algum caso de sucesso da gestão do transporte escolar no seu município, gostaríamos conhecer mais um pouco ao respeito. Por favor, relate de forma sucinta o caso de sucesso no espaço a seguir: | K1: Que cargo você ocupa no CACS-FUNDEB? | L1: Dia
A2: 45737.473 | B2: carmemkaio@hotmail.com | C2: Carmem Lúcia Lopes da Silva | D2: 929.329.591-15 | E2: 29703 | F2: (67)99694-5535 | G2: Amambai | H2: Gestão municipal | I2: Técnica de convênios e prestação de contas/membros do Cacs-Fundeb também | J2: Garantia de transporte a todos | L2: =VLOOKUP(G2,Datas!$A$1:$B$50,2,FALSE) -> 45749
A3: 45741.438 | B3: edinaldo_s_silva@hotmail.com | C3: Edinaldo Silva | D3: 830.554.871-68 | E3: 28265 | F3: (67)99649-7035 | G3: Amambai | H3: CACS-FUNDEB | K3: presidente | L3: =VLOOKUP(G3,Datas!$A$1:$B$50,2,FALSE) -> 45749
A4: 45737.543 | B4: profosmar@hotmail.com | C4: Osmar Aparecido Delvecchio | D4: 319.591.219-87 | E4: 21421 | F4: (67)99852-3057 | G4: Amambai | H4: CACS-FUNDEB | K4: Conselheiro | L4: =VLOOKUP(G4,Datas!$A$1:$B$50,2,FALSE) -> 45749
A5: 45748.479 | B5: tania_ruivo@hotmail.com | C5: Tania Aparecida Ruivo da Luz | D5: 017.339.721-29 | E5: 31923 | F5: (67)99253-6974 | G5: Amambai | H5: Gestão municipal | I5: Secretária de Educação | J5: Não temos ni momento | L5: =VLOOKUP(G5,Datas!$A$1:$B$50,2,FALSE) -> 45749
A6: 45747.688 | B6: valdemarantonio5@hotmail.com | C6: Valdemar Antônio de Oliveira | D6: 372.774.131-72 | E6: 24597 | F6: (67)99802-6446 | G6: Amambai | H6: Gestão municipal | I6: Gestor de Transporte Escolar | L6: =VLOOKUP(G6,Datas!$A$1:$B$50,2,FALSE) -> 45749
A7: 45747.408 | B7: transporte.escolar.amambai@hotmail.com | C7: Wender Luiz Farias Garai | D7: 971.277.281-00 | E7: 29614 | F7: (67)99108-5287 | G7: Amambai | H7: CACS-FUNDEB | K7: Coordenador de transporte escolar | L7: =VLOOKUP(G7,Datas!$A$1:$B$50,2,FALSE) -> 45749
A8: 45742.464 | B8: osmair_garcia@hotmail.com | C8: EDSON UMBELINO | D8: 554.765.201-63 | E8: 21306 | F8: (67)99835-3076 | G8: Anaurilândia | H8: Gestão municipal | I8: COORDENADOR TRANSPORTE ESCOLAR | L8: =VLOOKUP(G8,Datas!$A$1:$B$50,2,FALSE) -> 45749
A9: 45742.462 | B9: osmair_garcia@hotmail.com | C9: OSMAIR ALVES GARCIA | D9: 796.398.951-72 | E9: 28554 | F9: (67)99888-4290 | G9: Anaurilândia | H9: Gestão municipal | I9: ASSISTENTE ADMINISTRATIVO | J9: O MUNIC. CONSEGUIU TERCEIRIZAR BOA PARTE DAS LINHAS COM VEICULOS 2025! | L9: =VLOOKUP(G9,Datas!$A$1:$B$50,2,FALSE) -> 45749
A10: 45748.438 | B10: fv747993@gmail.com | C10: José Fernando Vieira da Silva | D10: 005.338.441-50 | E10: 30850 | F10: (67)99225-2689 | G10: Angélica | H10: Gestão municipal | I10: Chefe de Núcleo de Transporte Escolar | L10: =VLOOKUP(G10,Datas!$A$1:$B$50,2,FALSE) -> 45749
A11: 45748.447 | B11: ricardosm2002@hotmail.com | C11: RICARDO SOUZA MARCHINI | D11: 022.616.841-77 | E11: 37344 | F11: (67)99671-9885 | G11: Angélica | H11: Gestão municipal | I11: CONTADOR | L11: =VLOOKUP(G11,Datas!$A$1:$B$50,2,FALSE) -> 45749
A12: 45747.743 | B12: marcosantoniokol17@gmail.com | C12: Marcos Antônio Kol Rudes | D12: 088.101.191-69 | E12: 52961 | F12: (67)99991-3879 | G12: Aral Moreira | H12: Gestão municipal | I12: Assistente Administrativo | L12: =VLOOKUP(G12,Datas!$A$1:$B$50,2,FALSE) -> 45749
A13: 45748.455 | B13: martavlrigon@gmail.com | C13: Marta Vieira Leite Rigon | D13: 906.974.991-20 | E13: 29554 | F13: (67)99976-7300 | G13: Aral Moreira | H13: Gestão municipal | I13: Secretária municipal de educação | L13: =VLOOKUP(G13,Datas!$A$1:$B$50,2,FALSE) -> 45749
A14: 45743.859 | B14: alcenirlima2025semec@gmail.com | C14: Alcenir Rodrigues de Lima | D14: 365.252.431-49 | E14: 24785 | F14: (67)98192-0562 | G14: Bataguassu | H14: Gestão municipal | I14: Assessor Técnico e Pedagógico de Projetos e Convênios | L14: =VLOOKUP(G14,Datas!$A$1:$B$50,2,FALSE) -> 45749
A15: 45737.402 | B15: smec2018@outlook.com | C15: Adriana Ramos da Silva | D15: 015.884.291-05 | E15: 31964 | F15: (67)99626-6555 | G15: Batayporã | H15: Gestão municipal | I15: Técnica do Transporte Escolar | L15: =VLOOKUP(G15,Datas!$A$1:$B$50,2,FALSE) -> 45749
A16: 45737.567 | B16: leiasouzass@hotmail.com | C16: Leia Maria de Jesus Souza | D16: 797.993.701-59 | E16: 28159 | F16: (67)99912-5189 | G16: Batayporã | H16: Gestão municipal | I16: Prestação Contas | L16: =VLOOKUP(G16,Datas!$A$1:$B$50,2,FALSE) -> 45749
A17: 45737.415 | B17: cidamirandasilva@gmail.com | C17: Maria Aparecida Miranda da Silva | D17: 481.570.661-15 | E17: 1/15/0069 | F17: (67)99829-2334 | G17: Batayporã | H17: CACS-FUNDEB | K17: Vice presidente | L17: =VLOOKUP(G17,Datas!$A$1:$B$50,2,FALSE) -> 45749
A18: 45748.938 | B18: vanderleifreitas722@gmail.com | C18: Vanderlei de Freitas Santos | D18: 019.226.361-77 | E18: 32384 | F18: (67)99919-6945 | G18: Batayporã | H18: CACS-FUNDEB | K18: Presidente | L18: =VLOOKUP(G18,Datas!$A$1:$B$50,2,FALSE) -> 45749
A19: 45737.494 | B19: davi.v.lopes@hotmail.com | C19: Davi Vieira Lopes | D19: 840.823.481-15 | E19: 29349 | F19: (67)99925-9086 | G19: Caarapó | H19: CACS-FUNDEB | K19: Presidente | L19: =VLOOKUP(G19,Datas!$A$1:$B$50,2,FALSE) -> 45749
A20: 45743.547 | B20: bell-ifsm@hotmail.com | C20: Isabel Fernandes santos | D20: 876.656.541-34 | E20: 29773 | F20: (67)99627-0716 | G20: Caarapó | H20: Gestão municipal | I20: Prestação de contas | L20: =VLOOKUP(G20,Datas!$A$1:$B$50,2,FALSE) -> 45749
A21: 45736.619 | B21: josilaineneves01@gmail.com | C21: JOSILÂINE NEVES DA SILVA | D21: 032.679.841-22 | E21: 32569 | F21: (67)99101-5042 | G21: Caarapó | H21: Gestão municipal | I21: CHEFE DE DEPARTAMENTO DO TRANSPORTE ESCOLAR | L21: =VLOOKUP(G21,Datas!$A$1:$B$50,2,FALSE) -> 45749
A22: 45748.318 | B22: franzwillians@gmail.com | C22: Franz Willians Coimbra Martins | D22: 851.073.361-91 | E22: 28648 | F22: (67)99337-0272 | G22: Cassilândia | H22: Gestão municipal | I22: Gerente de frota | J22: Estamos tentando otimizar nosso transporte escolar conforme a legislação. Mas encontramos muita resistência com os pais. dos alunos. | L22: =VLOOKUP(G22,Datas!$A$1:$B$50,2,FALSE) -> 45750
A23: 45748.325 | B23: romeugoulart@gmail.com | C23: Romeu Goulart da Silva | D23: 312.097.501-04 | E23: 22943 | F23: (67)98129-2310 | G23: Cassilândia | H23: Gestão municipal | I23: Escriturário Transporte Escolar Municipal | L23: =VLOOKUP(G23,Datas!$A$1:$B$50,2,FALSE) -> 45750
A24: 45747.523 | B24: prof_jcarvalho@outlook.com | C24: Jucimar Carvalho Chaves | D24: 031.051.231-05 | E24: 32514 | F24: (67)99172-4459 | G24: Coronel Sapucaia | H24: CACS-FUNDEB | K24: Técnico | L24: =VLOOKUP(G24,Datas!$A$1:$B$50,2,FALSE) -> 45749
A25: 45747.526 | B25: rosenimartins_freitas@hotmail.com | C25: Roseni Martins Freitas | D25: 555.905.001-68 | E25: 24341 | F25: (67)99956-2977 | G25: Coronel Sapucaia | H25: Gestão municipal | I25: Secretária de Educação e Cultura | L25: =VLOOKUP(G25,Datas!$A$1:$B$50,2,FALSE) -> 45749
A26: 45747.414 | B26: cleberfaria5552@gmail.com | C26: Cleber Roza de Faria | D26: 982.073.261-15 | E26: 30821 | F26: (67)99906-3441 | G26: Deodápolis | H26: Gestão municipal | I26: Recepcionista | L26: =VLOOKUP(G26,Datas!$A$1:$B$50,2,FALSE) -> 45749
A27: 45747.359 | B27: tania.salmeida@hotmail.com | C27: TÂNIA REGINA DOS SANTOS ALMEIDA | D27: 637.035.051-68 | E27: 27738 | F27: (67)99648-1099 | G27: Douradina | H27: Gestão municipal | I27: TÉCNICO DO TRANSPORTE ESCOLAR | L27: =VLOOKUP(G27,Datas!$A$1:$B$50,2,FALSE) -> 45749
A28: 45742.395 | B28: gustavo.texeira33@gmail.com | C28: Gustavo Texeira Silva | D28: 070.308.241-80 | E28: 36763 | F28: (67)99691-2218 | G28: Dourados | H28: Gestão municipal | I28: Responsável pelo transporte Escolar da Prefeitura de Dourados | L28: =VLOOKUP(G28,Datas!$A$1:$B$50,2,FALSE) -> 45749
A29: 45743.135 | B29: luizaquevedonascimento@gmail.com | C29: Luiza Quevedo Nascimento | D29: 065.889.541-90 | E29: 36213 | F29: (67)99938-1694 | G29: Dourados | H29: Gestão municipal | I29: Assistente administrativo | L29: =VLOOKUP(G29,Datas!$A$1:$B$50,2,FALSE) -> 45749
A30: 45742.686 | B30: maria_augustha@hotmail.com | C30: Maria Augustha Espíndola Domingues | D30: 000.249.231-84 | E30: 30191 | F30: (67)99971-2118 | G30: Dourados | H30: CACS-FUNDEB | K30: Conselheira representante secretaria municipal de educação de dourados | L30: =VLOOKUP(G30,Datas!$A$1:$B$50,2,FALSE) -> 45749
A31: 45743.314 | B31: vivianne_pf@hotmail.com | C31: Viviane Mantovani | D31: 829.613.871-91 | E31: 27034 | F31: (66)99604-2529 | G31: Dourados | H31: CACS-FUNDEB | K31: Conselheiro | L31: =VLOOKUP(G31,Datas!$A$1:$B$50,2,FALSE) -> 45749
A32: 45748.494 | B32: nunesclaudinei628@gmail.com | C32: Claudinei Nunes | D32: 035.212.591-88 | E32: 33116 | F32: (67)99172-2974 | G32: Eldorado | H32: CACS-FUNDEB | K32: Vice-presidente | L32: =VLOOKUP(G32,Datas!$A$1:$B$50,2,FALSE) -> 45749
A33: 45746.59 | B33: camilosanches2247@hotmail.com | C33: José Camilo Sanches | D33: 312.780.271-49 | E33: 24117 | F33: (67)99698-7171 | G33: Eldorado | H33: Gestão municipal | I33: Diretor de Transporte | L33: =VLOOKUP(G33,Datas!$A$1:$B$50,2,FALSE) -> 45749
A34: 45742.513 | B34: professorasuelli@gmail.com | C34: Sueli Menezes da Silva | D34: 480.712.501-04 | E34: 25126 | F34: (67)99617-5907 | G34: Glória de Dourados | H34: Gestão municipal | I34: TÉCNICA | L34: =VLOOKUP(G34,Datas!$A$1:$B$50,2,FALSE) -> 45749
A35: 45748.437 | B35: maurosanp_@hotmail.com | C35: Mauro San pereira da Silva | D35: 038.697.801-85 | E35: 34377 | F35: (67)99677-7013 | G35: Iguatemi | H35: Gestão municipal | I35: Gestor transporte | L35: =VLOOKUP(G35,Datas!$A$1:$B$50,2,FALSE) -> 45749
A36: 45744.632 | B36: crodoaldosp@hotmail.com | C36: Crodoaldo Spessoto Prado | D36: 489.415.901-59 | E36: 26345 | F36: (67)99836-4443 | G36: Itaporã | H36: CACS-FUNDEB | K36: Conselho | L36: =VLOOKUP(G36,Datas!$A$1:$B$50,2,FALSE) -> 45749
A37: 45734.421 | B37: joaojoao515@gmail.com | C37: João Pereira Alves | D37: 356.418.431-72 | E37: 22821 | F37: (67)99619-8565 | G37: Itaporã | H37: Gestão municipal | I37: Diretor de Departamento deTransporte Escolar | L37: =VLOOKUP(G37,Datas!$A$1:$B$50,2,FALSE) -> 45749
A38: 45734.426 | B38: Jonsongeduita@gmail.com | C38: Jonson Carvalho Miranda | D38: 814.407.581-15 | E38: 27677 | F38: (67)99624-8316 | G38: Itaporã | H38: Gestão municipal | I38: Diretor de Departamento de Controle e Prestação de Contas | L38: =VLOOKUP(G38,Datas!$A$1:$B$50,2,FALSE) -> 45749
A39: 45734.509 | B39: milton.micco@itapora.ms.gov.br | C39: Milton Cesar de Micco | D39: 437.570.061-00 | E39: 25783 | F39: (67)99643-7631 | G39: Itaporã | H39: CACS-FUNDEB | K39: Conselheiro | L39: =VLOOKUP(G39,Datas!$A$1:$B$50,2,FALSE) -> 45749
A40: 45740.735 | B40: luzinel01@gmail.com | C40: LUZINEL SOCORRO DO NASCIMENTO | D40: 802.739.041-91 | E40: 28370 | F40: (67)98209-6325 | G40: Itaquiraí | H40: Gestão municipal | I40: AUXILIAR SERVIÇOS TÉCNICOS | L40: =VLOOKUP(G40,Datas!$A$1:$B$50,2,FALSE) -> 45749
...

Sheet Datas
A1: Cidade | B1: Data
A2: Amambai | B2: 45749
A3: Anaurilândia | B3: 45749
A4: Angélica | B4: 45749
A5: Aral Moreira | B5: 45749
A6: Bataguassu | B6: 45749
A7: Batayporã | B7: 45749
A8: Caarapó | B8: 45749
A9: Cassilândia | B9: 45750
A10: Coronel Sapucaia | B10: 45749
A11: Deodápolis | B11: 45749
A12: Douradina | B12: 45749
A13: Dourados | B13: 45749
... A37: Vicentina | B37: 45750

Sheet Confirmados Via E-mail
A1: Carimbo de data/hora | B1: Endereço de e-mail | C1: Nome Completo: | D1: CPF | E1: Data de Nascimento | F1: Telefone (XX)XXXXX-XXXX | G1: Município que representa: | H1: Você faz parte do: | I1: Que cargo você ocupa na gestão municipal? | J1: Prezado(a) Gestor(a), Se existe algum caso de sucesso da gestão do transporte escolar no seu município, gostaríamos conhecer mais um pouco ao respeito. Por favor, relate de forma sucinta o caso de sucesso no espaço a seguir: | K1: Que cargo você ocupa no CACS-FUNDEB? | L1: Dia
A2: 45734.421 | B2: joaojoao515@gmail.com | C2: João Pereira Alves | D2: 356.418.431-72 | E2: 22821 | F2: (67)99619-8565 | G2: Itaporã | H2: Gestão municipal | I2: Diretor de Departamento deTransporte Escolar | L2: 45749
A3: 45734.423 | B3: lucianomorisco@hotmail.com | C3: Luciano Morisco Rapchan | D3: 447.812.531-72 | E3: 26088 | F3: (67)99648-3181 | G3: Ivinhema | H3: Gestão municipal | I3: Assistente de Administração | L3: 45749
A4: 45734.426 | B4: Jonsongeduita@gmail.com | C4: Jonson Carvalho Miranda | D4: 814.407.581-15 | E4: 27677 | F4: (67)99624-8316 | G4: Itaporã | H4: Gestão municipal | I4: Diretor de Departamento de Controle e Prestação de Contas | L4: 45749
A5: 45734.474 | B5: narahbraguini@gmail.com | C5: Nara Henrique Braguini | D5: 023.395.351-58 | E5: 32021 | F5: (67)99971-3774 | G5: Ivinhema | H5: Gestão municipal | I5: Coordenadora | L5: 45749
A6: 45734.509 | B6: milton.micco@itapora.ms.gov.br | C6: Milton Cesar de Micco | D6: 437.570.061-00 | E6: 25783 | F6: (67)99643-7631 | G6: Itaporã | H6: CACS-FUNDEB | K6: Conselheiro | L6: 45749
A7: 45736.619 | B7: josilaineneves01@gmail.com | C7: JOSILÂINE NEVES DA SILVA | D7: 032.679.841-22 | E7: 32569 | F7: (67)99101-5042 | G7: Caarapó | H7: Gestão municipal | I7: CHEFE DE DEPARTAMENTO DO TRANSPORTE ESCOLAR | L7: 45749
A8: 45737.402 | B8: smec2018@outlook.com | C8: Adriana Ramos da Silva | D8: 015.884.291-05 | E8: 31964 | F8: (67)99626-6555 | G8: Batayporã | H8: Gestão municipal | I8: Técnica do Transporte Escolar | L8: 45749
A9: 45737.415 | B9: cidamirandasilva@gmail.com | C9: Maria Aparecida Miranda da Silva | D9: 481.570.661-15 | E9: 1/15/0069 | F9: (67)99829-2334 | G9: Batayporã | H9: CACS-FUNDEB | K9: Vice presidente | L9: 45749
A10: 45737.473 | B10: carmemkaio@hotmail.com | C10: Carmem Lúcia Lopes da Silva | D10: 929.329.591-15 | E10: 29703 | F10: (67)99694-5535 | G10: Amambai | H10: Gestão municipal | I10: Técnica de convênios e prestação de contas/membros do Cacs-Fundeb também | J10: Garantia de transporte a todos | L10: 45749
A11: 45737.494 | B11: davi.v.lopes@hotmail.com | C11: Davi Vieira Lopes | D11: 840.823.481-15 | E11: 29349 | F11: (67)99925-9086 | G11: Caarapó | H11: CACS-FUNDEB | K11: Presidente | L11: 45749
A12: 45737.543 | B12: profosmar@hotmail.com | C12: Osmar Aparecido Delvecchio | D12: 319.591.219-87 | E12: 21421 | F12: (67)99852-3057 | G12: Amambai | H12: CACS-FUNDEB | K12: Conselheiro | L12: 45749
A13: 45737.567 | B13: leiasouzass@hotmail.com | C13: Leia Maria de Jesus Souza | D13: 797.993.701-59 | E13: 28159 | F13: (67)99912-5189 | G13: Batayporã | H13: Gestão municipal | I13: Prestação Contas | L13: 45749
A14: 45740.735 | B14: luzinel01@gmail.com | C14: LUZINEL SOCORRO DO NASCIMENTO | D14: 802.739.041-91 | E14: 28370 | F14: (67)98209-6325 | G14: Itaquiraí | H14: Gestão municipal | I14: AUXILIAR SERVIÇOS TÉCNICOS | L14: 45749
A15: 45740.737 | B15: montilegal171@hotmail.com | C15: WAGNER PEREIRA FERNANDES | D15: 555.696.501-30 | E15: 26400 | F15: (67)99657-9030 | G15: Itaquiraí | H15: Gestão municipal | I15: DIRETOR DE TRANSPORTE ESCOLAR | L15: 45749
A16: 45740.743 | B16: montilegal171@hotmail.com | C16: Vagner Pereira Fernandes | D16: 555.696.501-30 | E16: 26400 | F16: (67)99657-9030 | G16: Itaquiraí | H16: Gestão municipal | I16: DIRETOR DE TRANSPORTE ESCOLAR | L16: 45749
A17: 45741.438 | B17: edinaldo_s_silva@hotmail.com | C17: Edinaldo Silva | D17: 830.554.871-68 | E17: 28265 | F17: (67)99649-7035 | G17: Amambai | H17: CACS-FUNDEB | K17: presidente | L17: 45749
A18: 45742.395 | B18: gustavo.texeira33@gmail.com | C18: Gustavo Texeira Silva | D18: 070.308.241-80 | E18: 36763 | F18: (67)99691-2218 | G18: Dourados | H18: Gestão municipal | I18: Responsável pelo transporte Escolar da Prefeitura de Dourados | L18: 45749
A19: 45742.462 | B19: osmair_garcia@hotmail.com | C19: OSMAIR ALVES GARCIA | D19: 796.398.951-72 | E19: 28554 | F19: (67)99888-4290 | G19: Anaurilândia | H19: Gestão municipal | I19: ASSISTENTE ADMINISTRATIVO | J19: O MUNIC. CONSEGUIU TERCEIRIZAR BOA PARTE DAS LINHAS COM VEICULOS 2025! | L19: 45749
A20: 45742.464 | B20: osmair_garcia@hotmail.com | C20: EDSON UMBELINO | D20: 554.765.201-63 | E20: 21306 | F20: (67)99835-3076 | G20: Anaurilândia | H20: Gestão municipal | I20: COORDENADOR TRANSPORTE ESCOLAR | L20: 45749
A21: 45742.513 | B21: professorasuelli@gmail.com | C21: Sueli Menezes da Silva | D21: 480.712.501-04 | E21: 25126 | F21: (67)99617-5907 | G21: Glória de Dourados | H21: Gestão municipal | I21: TÉCNICA | L21: 45749
A22: 45742.686 | B22: maria_augustha@hotmail.com | C22: Maria Augustha Espíndola Domingues | D22: 000.249.231-84 | E22: 30191 | F22: (67)99971-2118 | G22: Dourados | H22: CACS-FUNDEB | K22: Conselheira representante secretaria municipal de educação de dourados | L22: 45749
A23: 45743.135 | B23: luizaquevedonascimento@gmail.com | C23: Luiza Quevedo Nascimento | D23: 065.889.541-90 | E23: 36213 | F23: (67)99938-1694 | G23: Dourados | H23: Gestão municipal | I23: Assistente administrativo | L23: 45749
A24: 45743.314 | B24: vivianne_pf@hotmail.com | C24: Viviane Mantovani | D24: 829.613.871-91 | E24: 27034 | F24: (66)99604-2529 | G24: Dourados | H24: CACS-FUNDEB | K24: Conselheiro | L24: 45749
A25: 45743.547 | B25: bell-ifsm@hotmail.com | C25: Isabel Fernandes santos | D25: 876.656.541-34 | E25: 29773 | F25: (67)99627-0716 | G25: Caarapó | H25: Gestão municipal | I25: Prestação de contas | L25: 45749
A26: 45743.859 | B26: alcenirlima2025semec@gmail.com | C26: Alcenir Rodrigues de Lima | D26: 365.252.431-49 | E26: 24785 | F26: (67)98192-0562 | G26: Bataguassu | H26: Gestão municipal | I26: Assessor Técnico e Pedagógico de Projetos e Convênios | L26: 45749
A27: 45733.693 | B27: fagnergalina33@gmail.com | C27: Fagner Rodrigues Galina | D27: 046.804.109-57 | E27: 31113 | F27: (67)99653-5397 | G27: Paranhos | H27: Gestão municipal | I27: Diretor de Transporte Escolar | L27: 45750
A28: 45733.696 | B28: eliana.quadra@hotmail.com | C28: Eliana lopes Pereira | D28: 942.327.681-49 | E28: 30068 | F28: (67)99913-6007 | G28: Paranhos | H28: CACS-FUNDEB | K28: conselheira | L28: 45750
A29: 45733.699 | B29: jaque_hernacki@hotmail.com | C29: Jaqueline Hernacki | D29: 023.145.741-33 | E29: 32243 | F29: (67)99962-9226 | G29: Paranhos | H29: Gestão municipal | I29: Tecnica de prestação de contas | L29: 45750
A30: 45734.352 | B30: gabrielbcosta09091994@gmail.com | C30: Gabriel Barbosa Costa | D30: 050.776.421-84 | E30: 34586 | F30: (67)98103-8391 | G30: Maracaju | H30: Gestão municipal | I30: Prestação de Contas | J30: Houve troca de gestão, mas não teve processo de transição, a antiga gestão não nos apresentou nada | L30: 45750
A31: 45734.355 | B31: ricartegv@outlook.com.br | C31: Gabriel Vinicius Ricarte Pedrozo | D31: 070.184.021-82 | E31: 36339 | F31: (67)99178-0319 | G31: Maracaju | H31: Gestão municipal | I31: Auxiliar de secretaria do transporte | J31: Mudança de gestão e ingresso de novos servidores | L31: 45750
A32: 45734.488 | B32: ejas.emerson@gmail.com | C32: Emerson José Alves da Silva | D32: 847.122.011-34 | E32: 28948 | F32: (67)99808-1320 | G32: Nova Andradina | H32: Gestão municipal | I32: Diretor transporte escolar | L32: 45750
A33: 45735.743 | B33: carlosstabenow@hotmail.com | C33: Carlos Eduardo Stabenow Minari | D33: 931.593.741-49 | E33: 30017 | F33: (67)99965-9471 | G33: Naviraí | H33: Gestão municipal | I33: Gerente de equipe de unidades escolares | L33: 45750
A34: 45735.863 | B34: silvana.sanches@ifms.edu.br | C34: Silvana Colombelli Parra Sanches | D34: 960.116.021-34 | E34: 30230 | F34: (67)99173-0771 | G34: Nova Andradina | H34: CACS-FUNDEB | K34: Conselheira titutal sociedade civil | L34: 45750
A35: 45735.923 | B35: ricardoappaixao1979@gmail.com | C35: Ricardo Aparecido da Paixão | D35: 891.400.791-04 | E35: 28978 | F35: (67)99909-7296 | G35: Nova Andradina | H35: CACS-FUNDEB | K35: Presidente | L35: 45750
A36: 45737.482 | B36: semecel@jatei.ms.gov.br | C36: RAUL FERNANDO GARCIA | D36: 592.634.901-04 | E36: 26983 | F36: (67)99602-6840 | G36: Jateí | H36: Gestão municipal | I36: SECRETÁRIO MUNICIPAL DE EDUCAÇÃO | L36: 45750
A37: 45737.484 | B37: semecel@jatei.ms.gov.br | C37: AUTENIR RODRIGUES DE LIMA | D37: 825.762.621-04 | E37: 28418 | F37: (67)99911-2198 | G37: Jateí | H37: CACS-FUNDEB | K37: MEMBRO | L37: 45750
A38: 45737.488 | B38: semecel@jatei.ms.gov.br | C38: THIAGO RODRIGUES DOS REIS | D38: 012.494.461-20 | E38: 31446 | F38: (67)99848-6764 | G38: Jateí | H38: CACS-FUNDEB | K38: MEMBRO | L38: 45750
A39: 45740.667 | B39: anderson-2511@hotmail.com | C39: Anderson Oliveira Souza | D39: 045.727.011-05 | E39: 34298 | F39: (67)98452-5260 | G39: Novo Horizonte do Sul | H39: Gestão municipal | I39: Técnico Administrativo | L39: 45750
A40: 45740.7 | B40: patricnascimentodasilva@gmail.com | C40: Patric Nascimento da Silva | D40: 032.323.241-85 | E40: 32447 | F40: (67)99935-6261 | G40: Maracaju | H40: CACS-FUNDEB | K40: Diretor de transporte | L40: 45750
...

Sheet Controle
A1: CDM | B1: NOME | C1: DIST(km) | D1: CACS-FUNDEB | E1: Gestão municipal | G1: Todos | H1: Data | I1: Quantidade
B2: Amambai | D2: =COUNTIFS('Respostas ao formulário 1'!$H$2:$H$2054,$D$1,'Respostas ao formulário 1'!$G$2:$G$2054,$B2) -> 3 | E2: =COUNTIFS('Respostas ao formulário 1'!$H$2:$H$2054,$E$1,'Respostas ao formulário 1'!$G$2:$G$2054,$B2) -> 3 | G2: =E2+D2 -> 6 | H2: =VLOOKUP(B2,Tabela_1[],2,FALSE) -> 45749 | I2: 1
B3: Anaurilândia | D3: =COUNTIFS('Respostas ao formulário 1'!$H$2:$H$2054,$D$1,'Respostas ao formulário 1'!$G$2:$G$2054,$B3) -> 0 | E3: =COUNTIFS('Respostas ao formulário 1'!$H$2:$H$2054,$E$1,'Respostas ao formulário 1'!$G$2:$G$2054,$B3) -> 2 | G3: =E3+D3 -> 2 | H3: =VLOOKUP(B3,Tabela_1[],2,FALSE) -> 45749 | I3: 2
B4: Angélica | D4: =COUNTIFS('Respostas ao formulário 1'!$H$2:$H$2054,$D$1,'Respostas ao formulário 1'!$G$2:$G$2054,$B4) -> 0 | E4: =COUNTIFS('Respostas ao formulário 1'!$H$2:$H$2054,$E$1,'Respostas ao formulário 1'!$G$2:$G$2054,$B4) -> 2 | G4: =E4+D4 -> 2 | H4: =VLOOKUP(B4,Tabela_1[],2,FALSE) -> 45749 | I4: 3
B5: Aral Moreira | D5: =COUNTIFS('Respostas ao formulário 1'!$H$2:$H$2054,$D$1,'Respostas ao formulário 1'!$G$2:$G$2054,$B5) -> 0 | E5: =COUNTIFS('Respostas ao formulário 1'!$H$2:$H$2054,$E$1,'Respostas ao formulário 1'!$G$2:$G$2054,$B5) -> 2 | G5: =E5+D5 -> 2 | H5: =VLOOKUP(B5,Tabela_1[],2,FALSE) -> 45749 | I5: 4
B6: Bataguassu | D6: =COUNTIFS('Respostas ao formulário 1'!$H$2:$H$2054,$D$1,'Respostas ao formulário 1'!$G$2:$G$2054,$B6) -> 0 | E6: =COUNTIFS('Respostas ao formulário 1'!$H$2:$H$2054,$E$1,'Respostas ao formulário 1'!$G$2:$G$2054,$B6) -> 1 | G6: =E6+D6 -> 1 | H6: =VLOOKUP(B6,Tabela_1[],2,FALSE) -> 45749 | I6: 5
B7: Batayporã | D7: =COUNTIFS('Respostas ao formulário 1'!$H$2:$H$2054,$D$1,'Respostas ao formulário 1'!$G$2:$G$2054,$B7) -> 2 | E7: =COUNTIFS('Respostas ao formulário 1'!$H$2:$H$2054,$E$1,'Respostas ao formulário 1'!$G$2:$G$2054,$B7) -> 2 | G7: =E7+D7 -> 4 | H7: =VLOOKUP(B7,Tabela_1[],2,FALSE) -> 45749 | I7: 6
B8: Caarapó | D8: =COUNTIFS('Respostas ao formulário 1'!$H$2:$H$2054,$D$1,'Respostas ao formulário 1'!$G$2:$G$2054,$B8) -> 1 | E8: =COUNTIFS('Respostas ao formulário 1'!$H$2:$H$2054,$E$1,'Respostas ao formulário 1'!$G$2:$G$2054,$B8) -> 2 | G8: =E8+D8 -> 3 | H8: =VLOOKUP(B8,Tabela_1[],2,FALSE) -> 45749 | I8: 7
B9: Coronel Sapucaia | D9: =COUNTIFS('Respostas ao formulário 1'!$H$2:$H$2054,$D$1,'Respostas ao formulário 1'!$G$2:$G$2054,$B9) -> 1 | E9: =COUNTIFS('Respostas ao formulário 1'!$H$2:$H$2054,$E$1,'Respostas ao formulário 1'!$G$2:$G$2054,$B9) -> 1 | G9: =E9+D9 -> 2 | H9: =VLOOKUP(B9,Tabela_1[],2,FALSE) -> 45749 | I9: 8
B10: Deodápolis | D10: =COUNTIFS('Respostas ao formulário 1'!$H$2:$H$2054,$D$1,'Respostas ao formulário 1'!$G$2:$G$2054,$B10) -> 0 | E10: =COUNTIFS('Respostas ao formulário 1'!$H$2:$H$2054,$E$1,'Respostas ao formulário 1'!$G$2:$G$2054,$B10) -> 1 | G10: =E10+D10 -> 1 | H10: =VLOOKUP(B10,Tabela_1[],2,FALSE) -> 45749 | I10: 9
B11: Douradina | D11: =COUNTIFS('Respostas ao formulário 1'!$H$2:$H$2054,$D$1,'Respostas ao formulário 1'!$G$2:$G$2054,$B11) -> 0 | E11: =COUNTIFS('Respostas ao formulário 1'!$H$2:$H$2054,$E$1,'Respostas ao formulário 1'!$G$2:$G$2054,$B11) -> 1 | G11: =E11+D11 -> 1 | H11: =VLOOKUP(B11,Tabela_1[],2,FALSE) -> 45749 | I11: 10
B12: Dourados | D12: =COUNTIFS('Respostas ao formulário 1'!$H$2:$H$2054,$D$1,'Respostas ao formulário 1'!$G$2:$G$2054,$B12) -> 2 | E12: =COUNTIFS('Respostas ao formulário 1'!$H$2:$H$2054,$E$1,'Respostas ao formulário 1'!$G$2:$G$2054,$B12) -> 2 | G12: =E12+D12 -> 4 | H12: =VLOOKUP(B12,Tabela_1[],2,FALSE) -> 45749 | I12: 11
B13: Eldorado | D13: =COUNTIFS('Respostas ao formulário 1'!$H$2:$H$2054,$D$1,'Respostas ao formulário 1'!$G$2:$G$2054,$B13) -> 1 | E13: =COUNTIFS('Respostas ao formulário 1'!$H$2:$H$2054,$E$1,'Respostas ao formulário 1'!$G$2:$G$2054,$B13) -> 1 | G13: =E13+D13 -> 2 | H13: =VLOOKUP(B13,Tabela_1[],2,FALSE) -> 45749 | I13: 12
... B37: Cassilândia | D37: =COUNTIFS('Respostas ao formulário 1'!$H$2:$H$2054,$D$1,'Respostas ao formulário 1'!$G$2:$G$2054,$B37) -> 0 | E37: =COUNTIFS('Respostas ao formulário 1'!$H$2:$H$2054,$E$1,'Respostas ao formulário 1'!$G$2:$G$2054,$B37) -> 2 | G37: =E37+D37 -> 2 | H37: =VLOOKUP(B37,Tabela_1[],2,FALSE) -> 45750 | I37: 18
D40: CACS | E40: Gestão municipal | G40: Todos
A41: Municípios com representante inscrito | D41: =COUNTIF(D2:D34,">0") -> 17 | E41: =COUNTIF(E2:E34,">0") -> 31 | G41: =COUNTIF(G2:G34,">0") -> 31
A42: Pessoas Inscritas | D42: =SUM(D2:D34) -> 31 | E42: =SUM(E2:E34) -> 55 | G42: =SUM(G2:G34) -> 86
