Workbook

Sheet Respostas ao formulário 1
A1: Carimbo de data/hora | B1: Endereço de e-mail | C1: Nome Completo: | D1: CPF | E1: Você já está inscrito no Curso de Capacitação em Transporte Escolar? | F1: Data de Nascimento | G1: Telefone (XX)XXXXX-XXXX | H1: Município que representa: | I1: Você faz parte do: | J1: Que cargo você ocupa na gestão municipal? | K1: Prezado(a) Gestor(a), Se existe algum caso de sucesso da gestão do transporte escolar no seu município, gostaríamos conhecer mais um pouco ao respeito. Por favor, relate de forma sucinta o caso de sucesso no espaço a seguir: | L1: Que cargo você ocupa no CACS-FUNDEB? | M1: Cidade | N1: Função
A2: 45749.599 | B2: maria_aigustha@hormail.com | C2: Maria Augustha Espíndola Domingues | D2: 000.249.231-84 | E2: Sim | M2: =IF(E2="Não",H2,VLOOKUP(D2,'Inscrições'!D:G,4,FALSE)) -> Dourados | N2: =IF(E2="Sim",VLOOKUP(D2,'Inscrições'!D:H,5,FALSE),I2) -> CACS-FUNDEB | P2: =VLOOKUP(D2,'Inscrições'!D:H,5,FALSE) -> CACS-FUNDEB
A3: 45750.399 | B3: valdineipavanelli@hotmail.com | C3: Valdinei da Silva Pavanelli | D3: 000.371.471-37 | E3: Sim | M3: =IF(E3="Não",H3,VLOOKUP(D3,'Inscrições'!D:G,4,FALSE)) -> Japorã | N3: =IF(E3="Sim",VLOOKUP(D3,'Inscrições'!D:H,5,FALSE),I3) -> Gestão municipal
A4: 45749.406 | B4: geigyson@gmail.com | C4: Geigyson Mendonça Ribeiro | D4: 003.625.511-46 | E4: Não | F4: 30697 | G4: (67)9689-2918 | H4: Caarapó | I4: Gestão municipal | J4: Instrutor de Informática | M4: =IF(E4="Não",H4,VLOOKUP(D4,'Inscrições'!D:G,4,FALSE)) -> Caarapó | N4: =IF(E4="Sim",VLOOKUP(D4,'Inscrições'!D:H,5,FALSE),I4) -> Gestão municipal
A5: 45749.406 | B5: fv747993@gmail.com | C5: José Fernando Vieira da Silva | D5: 005.338.441-50 | E5: Sim | M5: =IF(E5="Não",H5,VLOOKUP(D5,'Inscrições'!D:G,4,FALSE)) -> Angélica | N5: =IF(E5="Sim",VLOOKUP(D5,'Inscrições'!D:H,5,FALSE),I5) -> Gestão municipal
A6: 45750.406 | B6: marisantin6@gmail.com | C6: Marilete Santin | D6: 009.602.231-00 | E6: Sim | M6: =IF(E6="Não",H6,VLOOKUP(D6,'Inscrições'!D:G,4,FALSE)) -> Rio Brilhante | N6: =IF(E6="Sim",VLOOKUP(D6,'Inscrições'!D:H,5,FALSE),I6) -> CACS-FUNDEB
A7: 45750.407 | B7: Transporteescolar@novaalvoradadosul.ms.gov.br | C7: Ozeias Morais da Silva | D7: 014.985.871-00 | E7: Sim | M7: =IF(E7="Não",H7,VLOOKUP(D7,'Inscrições'!D:G,4,FALSE)) -> Nova Alvorada do Sul | N7: =IF(E7="Sim",VLOOKUP(D7,'Inscrições'!D:H,5,FALSE),I7) -> Gestão municipal
A8: 45750.41 | B8: adalbertohonorato@hotmail.com | C8: Adalberto Honorato | D8: 015.174.281-22 | E8: Não | F8: 31509 | G8: (67)99614-9223 | H8: Nova Alvorada do Sul | I8: CACS-FUNDEB | L8: Membro Fundeb | M8: =IF(E8="Não",H8,VLOOKUP(D8,'Inscrições'!D:G,4,FALSE)) -> Nova Alvorada do Sul | N8: =IF(E8="Sim",VLOOKUP(D8,'Inscrições'!D:H,5,FALSE),I8) -> CACS-FUNDEB
A9: 45749.471 | B9: smec2018@outlook.com | C9: Adriana Ramos da Silva | D9: 015.884.291-05 | E9: Sim | M9: =IF(E9="Não",H9,VLOOKUP(D9,'Inscrições'!D:G,4,FALSE)) -> Batayporã | N9: =IF(E9="Sim",VLOOKUP(D9,'Inscrições'!D:H,5,FALSE),I9) -> Gestão municipal
A10: 45749.423 | B10: clariceeducacaof2@gmail.com | C10: Clarice de Almeida Faria | D10: 018.097.781-40 | E10: Não | F10: 31200 | G10: (67)99870-7697 | H10: Paraíso das Águas | I10: Gestão municipal | J10: Chefe da Divisão do transporte escolar | M10: =IF(E10="Não",H10,VLOOKUP(D10,'Inscrições'!D:G,4,FALSE)) -> Paraíso das Águas | N10: =IF(E10="Sim",VLOOKUP(D10,'Inscrições'!D:H,5,FALSE),I10) -> Gestão municipal
A11: 45750.401 | B11: marcio021186@gmail.com | C11: Marcio de Souza Santos | D11: 018.880.441-28 | E11: Sim | M11: =IF(E11="Não",H11,VLOOKUP(D11,'Inscrições'!D:G,4,FALSE)) -> Taquarussu | N11: =IF(E11="Sim",VLOOKUP(D11,'Inscrições'!D:H,5,FALSE),I11) -> Gestão municipal
A12: 45749.469 | B12: vanderleifreitas722@gmail.com | C12: Vanderlei de Freitas Santos | D12: 019.226.361-77 | E12: Sim | M12: =IF(E12="Não",H12,VLOOKUP(D12,'Inscrições'!D:G,4,FALSE)) -> Batayporã | N12: =IF(E12="Sim",VLOOKUP(D12,'Inscrições'!D:H,5,FALSE),I12) -> CACS-FUNDEB
A13: 45749.406 | B13: ricardosm2002@hotmail.com | C13: Ricardo Souza Marchini | D13: 022.616.841-77 | E13: Sim | M13: =IF(E13="Não",H13,VLOOKUP(D13,'Inscrições'!D:G,4,FALSE)) -> Angélica | N13: =IF(E13="Sim",VLOOKUP(D13,'Inscrições'!D:H,5,FALSE),I13) -> Gestão municipal
A14: 45749.409 | B14: anapedrodugordo12@gmail.com | C14: Ana Cecília Santos Oliveira | D14: 022.800.451-92 | E14: Não | F14: 31610 | G14: (67)99901-8178 | H14: Douradina | I14: Gestão municipal | J14: Conselheira Tutelar | M14: =IF(E14="Não",H14,VLOOKUP(D14,'Inscrições'!D:G,4,FALSE)) -> Douradina | N14: =IF(E14="Sim",VLOOKUP(D14,'Inscrições'!D:H,5,FALSE),I14) -> Gestão municipal
A15: 45749.464 | B15: anapedrodugordo12@gmail.com | C15: Ana Cecília Santos Oliveira | D15: 022.800.451-92 | E15: Não | F15: 31610 | G15: (67) 99901-8177 | H15: Douradina | I15: Gestão municipal | J15: Conselheira Tutelar | M15: =IF(E15="Não",H15,VLOOKUP(D15,'Inscrições'!D:G,4,FALSE)) -> Douradina | N15: =IF(E15="Sim",VLOOKUP(D15,'Inscrições'!D:H,5,FALSE),I15) -> Gestão municipal
A16: 45750.395 | B16: jaque_hernacki@hotmail.com | C16: Jaqueline Hernacki | D16: 023.145.741-33 | E16: Sim | M16: =IF(E16="Não",H16,VLOOKUP(D16,'Inscrições'!D:G,4,FALSE)) -> Paranhos | N16: =IF(E16="Sim",VLOOKUP(D16,'Inscrições'!D:H,5,FALSE),I16) -> Gestão municipal
A17: 45749.44 | B17: narahbraguini@gmail.com | C17: Nara Henrique Braguini | D17: 023.395.351-58 | E17: Sim | M17: =IF(E17="Não",H17,VLOOKUP(D17,'Inscrições'!D:G,4,FALSE)) -> Ivinhema | N17: =IF(E17="Sim",VLOOKUP(D17,'Inscrições'!D:H,5,FALSE),I17) -> Gestão municipal
A18: 45749.424 | B18: geovaniamachadolemos@gmail.com | C18: Geovania Machado Lemos | D18: 023.432.791-01 | E18: Não | F18: 31512 | G18: (67)99914-3233 | H18: Paraíso das Águas | I18: Gestão municipal | J18: Diretora de apoio administrativo | M18: =IF(E18="Não",H18,VLOOKUP(D18,'Inscrições'!D:G,4,FALSE)) -> Paraíso das Águas | N18: =IF(E18="Sim",VLOOKUP(D18,'Inscrições'!D:H,5,FALSE),I18) -> Gestão municipal
A19: 45749.498 | B19: rafaelfilho.sofia@gmail.com | C19: Rafael Aparecido da Silva Bezerra | D19: 028.916.671-31 | E19: Não | F19: 32475 | G19: (67) 98182-7265 | H19: Bataguassu | I19: Gestão municipal | J19: Coordenador do Transporte Escolar | M19: =IF(E19="Não",H19,VLOOKUP(D19,'Inscrições'!D:G,4,FALSE)) -> Bataguassu | N19: =IF(E19="Sim",VLOOKUP(D19,'Inscrições'!D:H,5,FALSE),I19) -> Gestão municipal
A20: 45749.399 | B20: prof_jcarvalho@outlook.com | C20: Jucimar Carvalho Chaves | D20: 031.051.231-05 | E20: Sim | M20: =IF(E20="Não",H20,VLOOKUP(D20,'Inscrições'!D:G,4,FALSE)) -> Coronel Sapucaia | N20: =IF(E20="Sim",VLOOKUP(D20,'Inscrições'!D:H,5,FALSE),I20) -> CACS-FUNDEB
A21: 45749.405 | B21: josilaineneves01@gmail.com | C21: Josilâine Neves da Silva | D21: 032.679.841-22 | E21: Sim | M21: =IF(E21="Não",H21,VLOOKUP(D21,'Inscrições'!D:G,4,FALSE)) -> Caarapó | N21: =IF(E21="Sim",VLOOKUP(D21,'Inscrições'!D:H,5,FALSE),I21) -> Gestão municipal
A22: 45750.537 | B22: simaoschuh1@gmail.com | C22: Simão Sirineu Schuh Dias | D22: 033.593.471-45 | E22: Sim | M22: =IF(E22="Não",H22,VLOOKUP(D22,'Inscrições'!D:G,4,FALSE)) -> #N/A | N22: =IF(E22="Sim",VLOOKUP(D22,'Inscrições'!D:H,5,FALSE),I22) -> #N/A
A23: 45750.405 | B23: thaine.stefani@gmail.com | C23: Thaine Stefani | D23: 034.548.621-83 | E23: Sim | M23: =IF(E23="Não",H23,VLOOKUP(D23,'Inscrições'!D:G,4,FALSE)) -> Rio Brilhante | N23: =IF(E23="Sim",VLOOKUP(D23,'Inscrições'!D:H,5,FALSE),I23) -> Gestão municipal
A24: 45749.861 | B24: profnunes11@gmail.com | C24: Claudineis Nunes | D24: 035.212.591-88 | E24: Sim | M24: =IF(E24="Não",H24,VLOOKUP(D24,'Inscrições'!D:G,4,FALSE)) -> Eldorado | N24: =IF(E24="Sim",VLOOKUP(D24,'Inscrições'!D:H,5,FALSE),I24) -> CACS-FUNDEB
A25: 45750.462 | B25: murillolima12@gmail.com | C25: Amanda Gonsales de lima | D25: 035.584.901-18 | E25: Sim | M25: =IF(E25="Não",H25,VLOOKUP(D25,'Inscrições'!D:G,4,FALSE)) -> Taquarussu | N25: =IF(E25="Sim",VLOOKUP(D25,'Inscrições'!D:H,5,FALSE),I25) -> Gestão municipal
A26: 45749.499 | B26: maurosanp_@hotmail.com | C26: Mauro San pereira da silva | D26: 038.697.801-85 | E26: Sim | M26: =IF(E26="Não",H26,VLOOKUP(D26,'Inscrições'!D:G,4,FALSE)) -> Iguatemi | N26: =IF(E26="Sim",VLOOKUP(D26,'Inscrições'!D:H,5,FALSE),I26) -> Gestão municipal
A27: 45750.413 | B27: andreluizgomes5691@gmail.com | C27: André Luiz Gomes da Silva | D27: 038.713.231-79 | E27: Sim | M27: =IF(E27="Não",H27,VLOOKUP(D27,'Inscrições'!D:G,4,FALSE)) -> Juti | N27: =IF(E27="Sim",VLOOKUP(D27,'Inscrições'!D:H,5,FALSE),I27) -> Gestão municipal
A28: 45750.405 | B28: uesley.u@gmail.com | C28: Uesley Souza Silva | D28: 041.510.051-88 | E28: Sim | M28: =IF(E28="Não",H28,VLOOKUP(D28,'Inscrições'!D:G,4,FALSE)) -> Rio Brilhante | N28: =IF(E28="Sim",VLOOKUP(D28,'Inscrições'!D:H,5,FALSE),I28) -> CACS-FUNDEB
A29: 45750.544 | B29: julianimalu@gmail.com | C29: Juliani Cristini Sieve | D29: 045.073.871-08 | E29: Não | F29: 34332 | G29: (67)98119-9686 | H29: Novo Horizonte do Sul | I29: CACS-FUNDEB | L29: Represetante de Pais | M29: =IF(E29="Não",H29,VLOOKUP(D29,'Inscrições'!D:G,4,FALSE)) -> Novo Horizonte do Sul | N29: =IF(E29="Sim",VLOOKUP(D29,'Inscrições'!D:H,5,FALSE),I29) -> CACS-FUNDEB
A30: 45750.543 | B30: anderson-2511@hotmail.com | C30: Anderson Oliveria Souza | D30: 045.727.011-05 | E30: Sim | M30: =IF(E30="Não",H30,VLOOKUP(D30,'Inscrições'!D:G,4,FALSE)) -> Novo Horizonte do Sul | N30: =IF(E30="Sim",VLOOKUP(D30,'Inscrições'!D:H,5,FALSE),I30) -> Gestão municipal
A31: 45750.395 | B31: fagnergalina33@gmail.com | C31: Fagner Rodrigues Galina | D31: 046.804.109-57 | E31: Sim | M31: =IF(E31="Não",H31,VLOOKUP(D31,'Inscrições'!D:G,4,FALSE)) -> Paranhos | N31: =IF(E31="Sim",VLOOKUP(D31,'Inscrições'!D:H,5,FALSE),I31) -> Gestão municipal
A32: 45749.496 | B32: fayane.m@hotmail.com | C32: Fayane Montenegro Gonçalves Paz | D32: 048.862.981-09 | E32: Não | F32: 34577 | G32: (67) 99684-8202 | H32: Douradina | I32: Gestão municipal | J32: Técnica administrativa | M32: =IF(E32="Não",H32,VLOOKUP(D32,'Inscrições'!D:G,4,FALSE)) -> Douradina | N32: =IF(E32="Sim",VLOOKUP(D32,'Inscrições'!D:H,5,FALSE),I32) -> Gestão municipal
A33: 45750.399 | B33: gabrielbarbosa_costa@live.com | C33: Gabriel Barbosa Costa | D33: 050.776.421-84 | E33: Sim | M33: =IF(E33="Não",H33,VLOOKUP(D33,'Inscrições'!D:G,4,FALSE)) -> Maracaju | N33: =IF(E33="Sim",VLOOKUP(D33,'Inscrições'!D:H,5,FALSE),I33) -> Gestão municipal
A34: 45750.405 | B34: analuizavenite@gmail.com | C34: Ana Luiza Venite Gama | D34: 058.764.141-07 | E34: Sim | M34: =IF(E34="Não",H34,VLOOKUP(D34,'Inscrições'!D:G,4,FALSE)) -> Rio Brilhante | N34: =IF(E34="Sim",VLOOKUP(D34,'Inscrições'!D:H,5,FALSE),I34) -> Gestão municipal
A35: 45750.407 | B35: soniareginameireleslago@gmail.com | C35: Sônia Regina Meireles Lago | D35: 063.006.468-74 | E35: Sim | M35: =IF(E35="Não",H35,VLOOKUP(D35,'Inscrições'!D:G,4,FALSE)) -> Laguna Carapã | N35: =IF(E35="Sim",VLOOKUP(D35,'Inscrições'!D:H,5,FALSE),I35) -> CACS-FUNDEB
A36: 45749.401 | B36: luizaquevedonascimento@gmail.com | C36: Luiza Quevedo Nascimento | D36: 065.889.541-90 | E36: Sim | M36: =IF(E36="Não",H36,VLOOKUP(D36,'Inscrições'!D:G,4,FALSE)) -> Dourados | N36: =IF(E36="Sim",VLOOKUP(D36,'Inscrições'!D:H,5,FALSE),I36) -> Gestão municipal
A37: 45750.397 | B37: ricartegv@gmail.com | C37: Gabriel Vinicius Ricarte Pedrozo | D37: 070.184.021-82 | E37: Sim | M37: =IF(E37="Não",H37,VLOOKUP(D37,'Inscrições'!D:G,4,FALSE)) -> Maracaju | N37: =IF(E37="Sim",VLOOKUP(D37,'Inscrições'!D:H,5,FALSE),I37) -> Gestão municipal
A38: 45749.502 | B38: gustavo.texeira33@gmail.com | C38: Gustavo Texeira Silva | D38: 070.308.241-80 | E38: Sim | M38: =IF(E38="Não",H38,VLOOKUP(D38,'Inscrições'!D:G,4,FALSE)) -> Dourados | N38: =IF(E38="Sim",VLOOKUP(D38,'Inscrições'!D:H,5,FALSE),I38) -> Gestão municipal
A39: 45750.398 | B39: augustocesarinformarica@gmail.com | C39: Augusto César Henriques | D39: 080.397.776-07 | E39: Não | F39: 31405 | G39: (67) 998271129 | H39: Maracaju | I39: Gestão municipal | J39: Técnico de Prestação de contas do transporte escolar | M39: =IF(E39="Não",H39,VLOOKUP(D39,'Inscrições'!D:G,4,FALSE)) -> Maracaju | N39: =IF(E39="Sim",VLOOKUP(D39,'Inscrições'!D:H,5,FALSE),I39) -> Gestão municipal
A40: 45750.4 | B40: danimedina826@gmail.com | C40: Daniela Medina | D40: 083.222.581-94 | E40: Não | F40: 36569 | G40: (67) 998523934 | H40: Laguna Carapã | I40: Gestão municipal | J40: Técnica | M40: =IF(E40="Não",H40,VLOOKUP(D40,'Inscrições'!D:G,4,FALSE)) -> Laguna Carapã | N40: =IF(E40="Sim",VLOOKUP(D40,'Inscrições'!D:H,5,FALSE),I40) -> Gestão municipal
...

Sheet Inscrições
A1: Carimbo de data/hora | B1: Endereço de e-mail | C1: Nome Completo: | D1: CPF | E1: Data de Nascimento | F1: Telefone (XX)XXXXX-XXXX | G1: Município que representa: | H1: Você faz parte do: | I1: Que cargo você ocupa na gestão municipal? | J1: Prezado(a) Gestor(a), Se existe algum caso de sucesso da gestão do transporte escolar no seu município, gostaríamos conhecer mais um pouco ao respeito. Por favor, relate de forma sucinta o caso de sucesso no espaço a seguir: | K1: Que cargo você ocupa no CACS-FUNDEB?
A2: 45733.693 | B2: fagnergalina33@gmail.com | C2: Fagner Rodrigues Galina | D2: 046.804.109-57 | E2: 31113 | F2: (67)99653-5397 | G2: Paranhos | H2: Gestão municipal | I2: Diretor de Transporte Escolar
A3: 45733.696 | B3: eliana.quadra@hotmail.com | C3: Eliana lopes Pereira | D3: 942.327.681-49 | E3: 30068 | F3: (67)99913-6007 | G3: Paranhos | H3: CACS-FUNDEB | K3: conselheira
A4: 45733.699 | B4: jaque_hernacki@hotmail.com | C4: Jaqueline Hernacki | D4: 023.145.741-33 | E4: 32243 | F4: (67)99962-9226 | G4: Paranhos | H4: Gestão municipal | I4: Tecnica de prestação de contas
A5: 45734.352 | B5: gabrielbcosta09091994@gmail.com | C5: Gabriel Barbosa Costa | D5: 050.776.421-84 | E5: 34586 | F5: (67)98103-8391 | G5: Maracaju | H5: Gestão municipal | I5: Prestação de Contas | J5: Houve troca de gestão, mas não teve processo de transição, a antiga gestão não nos apresentou nada
A6: 45734.355 | B6: ricartegv@outlook.com.br | C6: Gabriel Vinicius Ricarte Pedrozo | D6: 070.184.021-82 | E6: 36339 | F6: (67)99178-0319 | G6: Maracaju | H6: Gestão municipal | I6: Auxiliar de secretaria do transporte | J6: Mudança de gestão e ingresso de novos servidores
A7: 45734.421 | B7: joaojoao515@gmail.com | C7: João Pereira Alves | D7: 356.418.431-72 | E7: 22821 | F7: (67)99619-8565 | G7: Itaporã | H7: Gestão municipal | I7: Diretor de Departamento deTransporte Escolar
A8: 45734.423 | B8: lucianomorisco@hotmail.com | C8: Luciano Morisco Rapchan | D8: 447.812.531-72 | E8: 26088 | F8: (67)99648-3181 | G8: Ivinhema | H8: Gestão municipal | I8: Assistente de Administração
A9: 45734.426 | B9: Jonsongeduita@gmail.com | C9: Jonson Carvalho Miranda | D9: 814.407.581-15 | E9: 27677 | F9: (67)99624-8316 | G9: Itaporã | H9: Gestão municipal | I9: Diretor de Departamento de Controle e Prestação de Contas
A10: 45734.474 | B10: narahbraguini@gmail.com | C10: Nara Henrique Braguini | D10: 023.395.351-58 | E10: 32021 | F10: (67)99971-3774 | G10: Ivinhema | H10: Gestão municipal | I10: Coordenadora
A11: 45734.488 | B11: ejas.emerson@gmail.com | C11: Emerson José Alves da Silva | D11: 847.122.011-34 | E11: 28948 | F11: (67)99808-1320 | G11: Nova Andradina | H11: Gestão municipal | I11: Diretor transporte escolar
A12: 45734.509 | B12: milton.micco@itapora.ms.gov.br | C12: Milton Cesar de Micco | D12: 437.570.061-00 | E12: 25783 | F12: (67)99643-7631 | G12: Itaporã | H12: CACS-FUNDEB | K12: Conselheiro
A13: 45735.743 | B13: carlosstabenow@hotmail.com | C13: Carlos Eduardo Stabenow Minari | D13: 931.593.741-49 | E13: 30017 | F13: (67)99965-9471 | G13: Naviraí | H13: Gestão municipal | I13: Gerente de equipe de unidades escolares
A14: 45735.863 | B14: silvana.sanches@ifms.edu.br | C14: Silvana Colombelli Parra Sanches | D14: 960.116.021-34 | E14: 30230 | F14: (67)99173-0771 | G14: Nova Andradina | H14: CACS-FUNDEB | K14: Conselheira titutal sociedade civil
A15: 45735.923 | B15: ricardoappaixao1979@gmail.com | C15: Ricardo Aparecido da Paixão | D15: 891.400.791-04 | E15: 28978 | F15: (67)99909-7296 | G15: Nova Andradina | H15: CACS-FUNDEB | K15: Presidente
A16: 45736.619 | B16: josilaineneves01@gmail.com | C16: JOSILÂINE NEVES DA SILVA | D16: 032.679.841-22 | E16: 32569 | F16: (67)99101-5042 | G16: Caarapó | H16: Gestão municipal | I16: CHEFE DE DEPARTAMENTO DO TRANSPORTE ESCOLAR
A17: 45737.402 | B17: smec2018@outlook.com | C17: Adriana Ramos da Silva | D17: 015.884.291-05 | E17: 31964 | F17: (67)99626-6555 | G17: Batayporã | H17: Gestão municipal | I17: Técnica do Transporte Escolar
A18: 45737.415 | B18: cidamirandasilva@gmail.com | C18: Maria Aparecida Miranda da Silva | D18: 481.570.661-15 | E18: 1/15/0069 | F18: (67)99829-2334 | G18: Batayporã | H18: CACS-FUNDEB | K18: Vice presidente
A19: 45737.473 | B19: carmemkaio@hotmail.com | C19: Carmem Lúcia Lopes da Silva | D19: 929.329.591-15 | E19: 29703 | F19: (67)99694-5535 | G19: Amambai | H19: Gestão municipal | I19: Técnica de convênios e prestação de contas/membros do Cacs-Fundeb também | J19: Garantia de transporte a todos
A20: 45737.482 | B20: semecel@jatei.ms.gov.br | C20: RAUL FERNANDO GARCIA | D20: 592.634.901-04 | E20: 26983 | F20: (67)99602-6840 | G20: Jateí | H20: Gestão municipal | I20: SECRETÁRIO MUNICIPAL DE EDUCAÇÃO
A21: 45737.484 | B21: semecel@jatei.ms.gov.br | C21: AUTENIR RODRIGUES DE LIMA | D21: 825.762.621-04 | E21: 28418 | F21: (67)99911-2198 | G21: Jateí | H21: CACS-FUNDEB | K21: MEMBRO
A22: 45737.488 | B22: semecel@jatei.ms.gov.br | C22: THIAGO RODRIGUES DOS REIS | D22: 012.494.461-20 | E22: 31446 | F22: (67)99848-6764 | G22: Jateí | H22: CACS-FUNDEB | K22: MEMBRO
A23: 45737.494 | B23: davi.v.lopes@hotmail.com | C23: Davi Vieira Lopes | D23: 840.823.481-15 | E23: 29349 | F23: (67)99925-9086 | G23: Caarapó | H23: CACS-FUNDEB | K23: Presidente
A24: 45737.543 | B24: profosmar@hotmail.com | C24: Osmar Aparecido Delvecchio | D24: 319.591.219-87 | E24: 21421 | F24: (67)99852-3057 | G24: Amambai | H24: CACS-FUNDEB | K24: Conselheiro
A25: 45737.567 | B25: leiasouzass@hotmail.com | C25: Leia Maria de Jesus Souza | D25: 797.993.701-59 | E25: 28159 | F25: (67)99912-5189 | G25: Batayporã | H25: Gestão municipal | I25: Prestação Contas
A26: 45740.667 | B26: anderson-2511@hotmail.com | C26: Anderson Oliveira Souza | D26: 045.727.011-05 | E26: 34298 | F26: (67)98452-5260 | G26: Novo Horizonte do Sul | H26: Gestão municipal | I26: Técnico Administrativo
A27: 45740.7 | B27: patricnascimentodasilva@gmail.com | C27: Patric Nascimento da Silva | D27: 032.323.241-85 | E27: 32447 | F27: (67)99935-6261 | G27: Maracaju | H27: CACS-FUNDEB | K27: Diretor de transporte
A28: 45740.735 | B28: luzinel01@gmail.com | C28: LUZINEL SOCORRO DO NASCIMENTO | D28: 802.739.041-91 | E28: 28370 | F28: (67)98209-6325 | G28: Itaquiraí | H28: Gestão municipal | I28: AUXILIAR SERVIÇOS TÉCNICOS
A29: 45740.737 | B29: montilegal171@hotmail.com | C29: WAGNER PEREIRA FERNANDES | D29: 555.696.501-30 | E29: 26400 | F29: (67)99657-9030 | G29: Itaquiraí | H29: Gestão municipal | I29: DIRETOR DE TRANSPORTE ESCOLAR
A30: 45740.743 | B30: montilegal171@hotmail.com | C30: Vagner Pereira Fernandes | D30: 555.696.501-30 | E30: 26400 | F30: (67)99657-9030 | G30: Itaquiraí | H30: Gestão municipal | I30: DIRETOR DE TRANSPORTE ESCOLAR
A31: 45740.752 | B31: danimedina826@gmail.com | C31: daniela medina arguelho | D31: 083.222.581-94 | E31: 36569 | F31: (67)99852-3934 | G31: Laguna Carapã | H31: Gestão municipal | I31: técnico
A32: 45740.752 | B32: lucimara260379@gmail.com | C32: Lucimara Caccia Faverssiani | D32: 897.614.721-91 | E32: 28940 | F32: (67)99644-6575 | G32: Nova Andradina | H32: CACS-FUNDEB | K32: Conselheira
A33: 45740.819 | B33: crissfrangiotti@gmail.com | C33: Maria Cristina Frangiotti | D33: 921.493.321-91 | E33: 29058 | F33: (67)98445-1879 | G33: Novo Horizonte do Sul | H33: CACS-FUNDEB | K33: Membro
A34: 45741.346 | B34: danimedina826@gmail.com | C34: ADINEIA APARECIDA ZADROSKI DUARTE | D34: 506.447.341-91 | E34: 27552 | F34: (67)99951-1189 | G34: Laguna Carapã | H34: CACS-FUNDEB | K34: técnico administrativo
A35: 45741.401 | B35: dinamarfreitas@hotmail.com | C35: Dinamar de Souza Freitas | D35: 832.356.201-68 | E35: 24181 | F35: (67)99671-6678 | G35: Maracaju | H35: CACS-FUNDEB | K35: Conselheira Tutelar
A36: 45741.438 | B36: edinaldo_s_silva@hotmail.com | C36: Edinaldo Silva | D36: 830.554.871-68 | E36: 28265 | F36: (67)99649-7035 | G36: Amambai | H36: CACS-FUNDEB | K36: presidente
A37: 45741.448 | B37: danimedina826@gmail.com | C37: Sônia Regina Meireles Lago | D37: 063.006.468-74 | E37: 23435 | F37: (67)99923-8890 | G37: Laguna Carapã | H37: CACS-FUNDEB | K37: técnico
A38: 45741.499 | B38: luciano_mcm@hotmail.com | C38: Luciano Marques da Costa Martins | D38: 899.070.941-53 | E38: 28089 | F38: (67)98419-2006 | G38: Ponta Porã | H38: Gestão municipal | I38: Gerente do Transporte Escolar
A39: 45741.503 | B39: guilhermemateus348@gmail.com | C39: guilherme mateus silva cardoso | D39: 086.228.041-94 | E39: 37837 | F39: (67)99178-8895 | G39: Ponta Porã | H39: Gestão municipal | I39: Assistente no setor de transporte escolar
A40: 45747.456 | B40: educacao.matriculadigital@maracaju.ms.gov.br | C40: Gabriel Barbosa Costa | D40: 050.776.421-84 | E40: 34586 | F40: (67)98103-8391 | G40: Maracaju | H40: Gestão municipal | I40: Diretor de Departamento DAS-4 | J40: Sim, sou da nova gestão desse ano em diante | K40: Conselheira
...

Sheet Controle Presentes
A1: Ordem | B1: Município | C1: Data | D1: Presente? | E1: Presentes | F1: CACS-FUNDEB | G1: Gestão municipal
A2: 1 | B2: Amambai | C2: =VLOOKUP(B2,Tabela_2[],2,FALSE) -> 45749 | D2: =IF(E2>0,"Sim","Não") -> Sim | E2: =COUNTIF(Form_Responses1[[#ALL],[Cidade]],B2) -> 5 | F2: =COUNTIFS('Respostas ao formulário 1'!$N$2:$N$2009,$F$1,'Respostas ao formulário 1'!$M$2:$M$2009,$B2) -> 4 | G2: =COUNTIFS('Respostas ao formulário 1'!$N$2:$N$2009,Tabela_3[[#HEADERS],[Gestão municipal]],'Respostas ao formulário 1'!$M$2:$M$2009,$B2) -> 1
A3: 2 | B3: Anaurilândia | C3: =VLOOKUP(B3,Tabela_2[],2,FALSE) -> 45749 | D3: =IF(E3>0,"Sim","Não") -> Sim | E3: =COUNTIF(Form_Responses1[[#ALL],[Cidade]],B3) -> 2 | F3: =COUNTIFS('Respostas ao formulário 1'!$N$2:$N$2009,$F$1,'Respostas ao formulário 1'!$M$2:$M$2009,$B3) -> 0 | G3: =COUNTIFS('Respostas ao formulário 1'!$N$2:$N$2009,Tabela_3[[#HEADERS],[Gestão municipal]],'Respostas ao formulário 1'!$M$2:$M$2009,$B3) -> 2
A4: 3 | B4: Angélica | C4: =VLOOKUP(B4,Tabela_2[],2,FALSE) -> 45749 | D4: =IF(E4>0,"Sim","Não") -> Sim | E4: =COUNTIF(Form_Responses1[[#ALL],[Cidade]],B4) -> 2 | F4: =COUNTIFS('Respostas ao formulário 1'!$N$2:$N$2009,$F$1,'Respostas ao formulário 1'!$M$2:$M$2009,$B4) -> 0 | G4: =COUNTIFS('Respostas ao formulário 1'!$N$2:$N$2009,Tabela_3[[#HEADERS],[Gestão municipal]],'Respostas ao formulário 1'!$M$2:$M$2009,$B4) -> 2
A5: 4 | B5: Aral Moreira | C5: =VLOOKUP(B5,Tabela_2[],2,FALSE) -> 45749 | D5: =IF(E5>0,"Sim","Não") -> Sim | E5: =COUNTIF(Form_Responses1[[#ALL],[Cidade]],B5) -> 4 | F5: =COUNTIFS('Respostas ao formulário 1'!$N$2:$N$2009,$F$1,'Respostas ao formulário 1'!$M$2:$M$2009,$B5) -> 0 | G5: =COUNTIFS('Respostas ao formulário 1'!$N$2:$N$2009,Tabela_3[[#HEADERS],[Gestão municipal]],'Respostas ao formulário 1'!$M$2:$M$2009,$B5) -> 4
A6: 5 | B6: Bataguassu | C6: =VLOOKUP(B6,Tabela_2[],2,FALSE) -> 45749 | D6: =IF(E6>0,"Sim","Não") -> Sim | E6: =COUNTIF(Form_Responses1[[#ALL],[Cidade]],B6) -> 2 | F6: =COUNTIFS('Respostas ao formulário 1'!$N$2:$N$2009,$F$1,'Respostas ao formulário 1'!$M$2:$M$2009,$B6) -> 0 | G6: =COUNTIFS('Respostas ao formulário 1'!$N$2:$N$2009,Tabela_3[[#HEADERS],[Gestão municipal]],'Respostas ao formulário 1'!$M$2:$M$2009,$B6) -> 2
A7: 6 | B7: Batayporã | C7: =VLOOKUP(B7,Tabela_2[],2,FALSE) -> 45749 | D7: =IF(E7>0,"Sim","Não") -> Sim | E7: =COUNTIF(Form_Responses1[[#ALL],[Cidade]],B7) -> 4 | F7: =COUNTIFS('Respostas ao formulário 1'!$N$2:$N$2009,$F$1,'Respostas ao formulário 1'!$M$2:$M$2009,$B7) -> 2 | G7: =COUNTIFS('Respostas ao formulário 1'!$N$2:$N$2009,Tabela_3[[#HEADERS],[Gestão municipal]],'Respostas ao formulário 1'!$M$2:$M$2009,$B7) -> 2
A8: 7 | B8: Caarapó | C8: =VLOOKUP(B8,Tabela_2[],2,FALSE) -> 45749 | D8: =IF(E8>0,"Sim","Não") -> Sim | E8: =COUNTIF(Form_Responses1[[#ALL],[Cidade]],B8) -> 4 | F8: =COUNTIFS('Respostas ao formulário 1'!$N$2:$N$2009,$F$1,'Respostas ao formulário 1'!$M$2:$M$2009,$B8) -> 1 | G8: =COUNTIFS('Respostas ao formulário 1'!$N$2:$N$2009,Tabela_3[[#HEADERS],[Gestão municipal]],'Respostas ao formulário 1'!$M$2:$M$2009,$B8) -> 3
A9: 8 | B9: Coronel Sapucaia | C9: =VLOOKUP(B9,Tabela_2[],2,FALSE) -> 45749 | D9: =IF(E9>0,"Sim","Não") -> Sim | E9: =COUNTIF(Form_Responses1[[#ALL],[Cidade]],B9) -> 2 | F9: =COUNTIFS('Respostas ao formulário 1'!$N$2:$N$2009,$F$1,'Respostas ao formulário 1'!$M$2:$M$2009,$B9) -> 1 | G9: =COUNTIFS('Respostas ao formulário 1'!$N$2:$N$2009,Tabela_3[[#HEADERS],[Gestão municipal]],'Respostas ao formulário 1'!$M$2:$M$2009,$B9) -> 1
A10: 9 | B10: Deodápolis | C10: =VLOOKUP(B10,Tabela_2[],2,FALSE) -> 45749 | D10: =IF(E10>0,"Sim","Não") -> Sim | E10: =COUNTIF(Form_Responses1[[#ALL],[Cidade]],B10) -> 1 | F10: =COUNTIFS('Respostas ao formulário 1'!$N$2:$N$2009,$F$1,'Respostas ao formulário 1'!$M$2:$M$2009,$B10) -> 0 | G10: =COUNTIFS('Respostas ao formulário 1'!$N$2:$N$2009,Tabela_3[[#HEADERS],[Gestão municipal]],'Respostas ao formulário 1'!$M$2:$M$2009,$B10) -> 1
A11: 10 | B11: Douradina | C11: =VLOOKUP(B11,Tabela_2[],2,FALSE) -> 45749 | D11: =IF(E11>0,"Sim","Não") -> Sim | E11: =COUNTIF(Form_Responses1[[#ALL],[Cidade]],B11) -> 4 | F11: =COUNTIFS('Respostas ao formulário 1'!$N$2:$N$2009,$F$1,'Respostas ao formulário 1'!$M$2:$M$2009,$B11) -> 0 | G11: =COUNTIFS('Respostas ao formulário 1'!$N$2:$N$2009,Tabela_3[[#HEADERS],[Gestão municipal]],'Respostas ao formulário 1'!$M$2:$M$2009,$B11) -> 4
A12: 11 | B12: Dourados | C12: =VLOOKUP(B12,Tabela_2[],2,FALSE) -> 45749 | D12: =IF(E12>0,"Sim","Não") -> Sim | E12: =COUNTIF(Form_Responses1[[#ALL],[Cidade]],B12) -> 6 | F12: =COUNTIFS('Respostas ao formulário 1'!$N$2:$N$2009,$F$1,'Respostas ao formulário 1'!$M$2:$M$2009,$B12) -> 3 | G12: =COUNTIFS('Respostas ao formulário 1'!$N$2:$N$2009,Tabela_3[[#HEADERS],[Gestão municipal]],'Respostas ao formulário 1'!$M$2:$M$2009,$B12) -> 3
A13: 12 | B13: Eldorado | C13: =VLOOKUP(B13,Tabela_2[],2,FALSE) -> 45749 | D13: =IF(E13>0,"Sim","Não") -> Sim | E13: =COUNTIF(Form_Responses1[[#ALL],[Cidade]],B13) -> 4 | F13: =COUNTIFS('Respostas ao formulário 1'!$N$2:$N$2009,$F$1,'Respostas ao formulário 1'!$M$2:$M$2009,$B13) -> 1 | G13: =COUNTIFS('Respostas ao formulário 1'!$N$2:$N$2009,Tabela_3[[#HEADERS],[Gestão municipal]],'Respostas ao formulário 1'!$M$2:$M$2009,$B13) -> 3
... A19: 18 | B19: Ivinhema | C19: =VLOOKUP(B19,Tabela_2[],2,FALSE) -> 45749 | D19: =IF(E19>0,"Sim","Não") -> Sim | E19: =COUNTIF(Form_Responses1[[#ALL],[Cidade]],B19) -> 2 | F19: =COUNTIFS('Respostas ao formulário 1'!$N$2:$N$2009,$F$1,'Respostas ao formulário 1'!$M$2:$M$2009,$B19) -> 0 | G19: =COUNTIFS('Respostas ao formulário 1'!$N$2:$N$2009,Tabela_3[[#HEADERS],[Gestão municipal]],'Respostas ao formulário 1'!$M$2:$M$2009,$B19) -> 2
A20: 19 | B20: Japorã | C20: =VLOOKUP(B20, Tabela_2[], 2, FALSE) -> 45750 | D20: =IF(E20>0,"Sim","Não") -> Sim | E20: =COUNTIF(Form_Responses1[[#ALL],[Cidade]],B20) -> 2 | F20: =COUNTIFS('Respostas ao formulário 1'!$N$2:$N$2009,$F$1,'Respostas ao formulário 1'!$M$2:$M$2009,$B20) -> 1 | G20: =COUNTIFS('Respostas ao formulário 1'!$N$2:$N$2009,Tabela_3[[#HEADERS],[Gestão municipal]],'Respostas ao formulário 1'!$M$2:$M$2009,$B20) -> 1
A21: 20 | B21: Paraíso das Águas | C21: =VLOOKUP(B21, Tabela_2[], 2, FALSE) -> 45749 | D21: =IF(E21>0,"Sim","Não") -> Sim | E21: =COUNTIF(Form_Responses1[[#ALL],[Cidade]],B21) -> 3 | F21: =COUNTIFS('Respostas ao formulário 1'!$N$2:$N$2009,$F$1,'Respostas ao formulário 1'!$M$2:$M$2009,$B21) -> 0 | G21: =COUNTIFS('Respostas ao formulário 1'!$N$2:$N$2009,Tabela_3[[#HEADERS],[Gestão municipal]],'Respostas ao formulário 1'!$M$2:$M$2009,$B21) -> 3
A22: 1 | B22: Jateí | C22: =VLOOKUP(B22,Tabela_2[],2,FALSE) -> 45750 | D22: =IF(E22>0,"Sim","Não") -> Sim | E22: =COUNTIF(Form_Responses1[[#ALL],[Cidade]],B22) -> 2 | F22: =COUNTIFS('Respostas ao formulário 1'!$N$2:$N$2009,$F$1,'Respostas ao formulário 1'!$M$2:$M$2009,$B22) -> 1 | G22: =COUNTIFS('Respostas ao formulário 1'!$N$2:$N$2009,Tabela_3[[#HEADERS],[Gestão municipal]],'Respostas ao formulário 1'!$M$2:$M$2009,$B22) -> 1
A23: 2 | B23: Juti | C23: =VLOOKUP(B23,Tabela_2[],2,FALSE) -> 45750 | D23: =IF(E23>0,"Sim","Não") -> Sim | E23: =COUNTIF(Form_Responses1[[#ALL],[Cidade]],B23) -> 2 | F23: =COUNTIFS('Respostas ao formulário 1'!$N$2:$N$2009,$F$1,'Respostas ao formulário 1'!$M$2:$M$2009,$B23) -> 0 | G23: =COUNTIFS('Respostas ao formulário 1'!$N$2:$N$2009,Tabela_3[[#HEADERS],[Gestão municipal]],'Respostas ao formulário 1'!$M$2:$M$2009,$B23) -> 2
A24: 3 | B24: Laguna Carapã | C24: =VLOOKUP(B24,Tabela_2[],2,FALSE) -> 45750 | D24: =IF(E24>0,"Sim","Não") -> Sim | E24: =COUNTIF(Form_Responses1[[#ALL],[Cidade]],B24) -> 4 | F24: =COUNTIFS('Respostas ao formulário 1'!$N$2:$N$2009,$F$1,'Respostas ao formulário 1'!$M$2:$M$2009,$B24) -> 3 | G24: =COUNTIFS('Respostas ao formulário 1'!$N$2:$N$2009,Tabela_3[[#HEADERS],[Gestão municipal]],'Respostas ao formulário 1'!$M$2:$M$2009,$B24) -> 1
A25: 4 | B25: Maracaju | C25: =VLOOKUP(B25,Tabela_2[],2,FALSE) -> 45750 | D25: =IF(E25>0,"Sim","Não") -> Sim | E25: =COUNTIF(Form_Responses1[[#ALL],[Cidade]],B25) -> 4 | F25: =COUNTIFS('Respostas ao formulário 1'!$N$2:$N$2009,$F$1,'Respostas ao formulário 1'!$M$2:$M$2009,$B25) -> 1 | G25: =COUNTIFS('Respostas ao formulário 1'!$N$2:$N$2009,Tabela_3[[#HEADERS],[Gestão municipal]],'Respostas ao formulário 1'!$M$2:$M$2009,$B25) -> 3
A26: 5 | B26: Mundo Novo | C26: =VLOOKUP(B26,Tabela_2[],2,FALSE) -> 45750 | D26: =IF(E26>0,"Sim","Não") -> Sim | E26: =COUNTIF(Form_Responses1[[#ALL],[Cidade]],B26) -> 1 | F26: =COUNTIFS('Respostas ao formulário 1'!$N$2:$N$2009,$F$1,'Respostas ao formulário 1'!$M$2:$M$2009,$B26) -> 0 | G26: =COUNTIFS('Respostas ao formulário 1'!$N$2:$N$2009,Tabela_3[[#HEADERS],[Gestão municipal]],'Respostas ao formulário 1'!$M$2:$M$2009,$B26) -> 1
A27: 6 | B27: Naviraí | C27: =VLOOKUP(B27,Tabela_2[],2,FALSE) -> 45750 | D27: =IF(E27>0,"Sim","Não") -> Sim | E27: =COUNTIF(Form_Responses1[[#ALL],[Cidade]],B27) -> 3 | F27: =COUNTIFS('Respostas ao formulário 1'!$N$2:$N$2009,$F$1,'Respostas ao formulário 1'!$M$2:$M$2009,$B27) -> 2 | G27: =COUNTIFS('Respostas ao formulário 1'!$N$2:$N$2009,Tabela_3[[#HEADERS],[Gestão municipal]],'Respostas ao formulário 1'!$M$2:$M$2009,$B27) -> 1
A28: 7 | B28: Nova Alvorada do Sul | C28: =VLOOKUP(B28,Tabela_2[],2,FALSE) -> 45750 | D28: =IF(E28>0,"Sim","Não") -> Sim | E28: =COUNTIF(Form_Responses1[[#ALL],[Cidade]],B28) -> 2 | F28: =COUNTIFS('Respostas ao formulário 1'!$N$2:$N$2009,$F$1,'Respostas ao formulário 1'!$M$2:$M$2009,$B28) -> 1 | G28: =COUNTIFS('Respostas ao formulário 1'!$N$2:$N$2009,Tabela_3[[#HEADERS],[Gestão municipal]],'Respostas ao formulário 1'!$M$2:$M$2009,$B28) -> 1
A29: 8 | B29: Nova Andradina | C29: =VLOOKUP(B29,Tabela_2[],2,FALSE) -> 45750 | D29: =IF(E29>0,"Sim","Não") -> Sim | E29: =COUNTIF(Form_Responses1[[#ALL],[Cidade]],B29) -> 3 | F29: =COUNTIFS('Respostas ao formulário 1'!$N$2:$N$2009,$F$1,'Respostas ao formulário 1'!$M$2:$M$2009,$B29) -> 2 | G29: =COUNTIFS('Respostas ao formulário 1'!$N$2:$N$2009,Tabela_3[[#HEADERS],[Gestão municipal]],'Respostas ao formulário 1'!$M$2:$M$2009,$B29) -> 1
A30: 9 | B30: Novo Horizonte do Sul | C30: =VLOOKUP(B30,Tabela_2[],2,FALSE) -> 45750 | D30: =IF(E30>0,"Sim","Não") -> Sim | E30: =COUNTIF(Form_Responses1[[#ALL],[Cidade]],B30) -> 4 | F30: =COUNTIFS('Respostas ao formulário 1'!$N$2:$N$2009,$F$1,'Respostas ao formulário 1'!$M$2:$M$2009,$B30) -> 2 | G30: =COUNTIFS('Respostas ao formulário 1'!$N$2:$N$2009,Tabela_3[[#HEADERS],[Gestão municipal]],'Respostas ao formulário 1'!$M$2:$M$2009,$B30) -> 2
A31: 10 | B31: Paranhos | C31: =VLOOKUP(B31,Tabela_2[],2,FALSE) -> 45750 | D31: =IF(E31>0,"Sim","Não") -> Sim | E31: =COUNTIF(Form_Responses1[[#ALL],[Cidade]],B31) -> 2 | F31: =COUNTIFS('Respostas ao formulário 1'!$N$2:$N$2009,$F$1,'Respostas ao formulário 1'!$M$2:$M$2009,$B31) -> 0 | G31: =COUNTIFS('Respostas ao formulário 1'!$N$2:$N$2009,Tabela_3[[#HEADERS],[Gestão municipal]],'Respostas ao formulário 1'!$M$2:$M$2009,$B31) -> 2
A32: 11 | B32: Ponta Porã | C32: =VLOOKUP(B32,Tabela_2[],2,FALSE) -> 45750 | D32: =IF(E32>0,"Sim","Não") -> Sim | E32: =COUNTIF(Form_Responses1[[#ALL],[Cidade]],B32) -> 3 | F32: =COUNTIFS('Respostas ao formulário 1'!$N$2:$N$2009,$F$1,'Respostas ao formulário 1'!$M$2:$M$2009,$B32) -> 2 | G32: =COUNTIFS('Respostas ao formulário 1'!$N$2:$N$2009,Tabela_3[[#HEADERS],[Gestão municipal]],'Respostas ao formulário 1'!$M$2:$M$2009,$B32) -> 1
A33: 12 | B33: Rio Brilhante | C33: =VLOOKUP(B33,Tabela_2[],2,FALSE) -> 45750 | D33: =IF(E33>0,"Sim","Não") -> Sim | E33: =COUNTIF(Form_Responses1[[#ALL],[Cidade]],B33) -> 4 | F33: =COUNTIFS('Respostas ao formulário 1'!$N$2:$N$2009,$F$1,'Respostas ao formulário 1'!$M$2:$M$2009,$B33) -> 2 | G33: =COUNTIFS('Respostas ao formulário 1'!$N$2:$N$2009,Tabela_3[[#HEADERS],[Gestão municipal]],'Respostas ao formulário 1'!$M$2:$M$2009,$B33) -> 2
... A38: 17 | B38: Cassilândia | C38: =VLOOKUP(B38,Tabela_2[],2,FALSE) -> 45750 | D38: =IF(E38>0,"Sim","Não") -> Sim | E38: =COUNTIF(Form_Responses1[[#ALL],[Cidade]],B38) -> 3 | F38: =COUNTIFS('Respostas ao formulário 1'!$N$2:$N$2009,$F$1,'Respostas ao formulário 1'!$M$2:$M$2009,$B38) -> 0 | G38: =COUNTIFS('Respostas ao formulário 1'!$N$2:$N$2009,Tabela_3[[#HEADERS],[Gestão municipal]],'Respostas ao formulário 1'!$M$2:$M$2009,$B38) -> 3

Sheet Datas
A1: Cidade | B1: Data
A2: Amambai | B2: 45749
A3: Anaurilândia | B3: 45749
A4: Angélica | B4: 45749
A5: Aral Moreira | B5: 45749
A6: Bataguassu | B6: 45749
A7: Batayporã | B7: 45749
A8: Caarapó | B8: 45749
A9: Cassilândia | B9: 45750
A10: Coronel Sapucaia | B10: 45749
A11: Deodápolis | B11: 45749
A12: Douradina | B12: 45749
A13: Dourados | B13: 45749
... A38: Paraíso das Águas | B38: 45749

Sheet Certificado
A1: Carimbo de data/hora | B1: Endereço de e-mail | C1: Nome Completo: | D1: CPF | E1: Você já está inscrito no Curso de Capacitação em Transporte Escolar? | F1: Data de Nascimento | G1: Telefone (XX)XXXXX-XXXX | H1: Município que representa: | I1: Você faz parte do: | J1: Que cargo você ocupa na gestão municipal? | K1: Prezado(a) Gestor(a), Se existe algum caso de sucesso da gestão do transporte escolar no seu município, gostaríamos conhecer mais um pouco ao respeito. Por favor, relate de forma sucinta o caso de sucesso no espaço a seguir: | L1: Que cargo você ocupa no CACS-FUNDEB? | M1: Cidade | N1: Função
A2: 45749.599 | B2: maria_aigustha@hormail.com | C2: Maria Augustha Espíndola Domingues | D2: 000.249.231-84 | E2: Sim | M2: =IF(E2="Não",H2,VLOOKUP(D2,'Inscrições'!D:G,4,FALSE)) -> Dourados | N2: =IF(E2="Sim",VLOOKUP(D2,'Inscrições'!D:H,5,FALSE),I2) -> CACS-FUNDEB | P2: =VLOOKUP(D2,'Inscrições'!D:H,5,FALSE) -> CACS-FUNDEB
A3: 45750.399 | B3: valdineipavanelli@hotmail.com | C3: Valdinei da Silva Pavanelli | D3: 000.371.471-37 | E3: Sim | M3: =IF(E3="Não",H3,VLOOKUP(D3,'Inscrições'!D:G,4,FALSE)) -> Japorã | N3: =IF(E3="Sim",VLOOKUP(D3,'Inscrições'!D:H,5,FALSE),I3) -> Gestão municipal
A4: 45749.406 | B4: geigyson@gmail.com | C4: Geigyson Mendonça Ribeiro | D4: 003.625.511-46 | E4: Não | F4: 30697 | G4: (67)9689-2918 | H4: Caarapó | I4: Gestão municipal | J4: Instrutor de Informática | M4: =IF(E4="Não",H4,VLOOKUP(D4,'Inscrições'!D:G,4,FALSE)) -> Caarapó | N4: =IF(E4="Sim",VLOOKUP(D4,'Inscrições'!D:H,5,FALSE),I4) -> Gestão municipal
A5: 45749.406 | B5: fv747993@gmail.com | C5: José Fernando Vieira da Silva | D5: 005.338.441-50 | E5: Sim | M5: =IF(E5="Não",H5,VLOOKUP(D5,'Inscrições'!D:G,4,FALSE)) -> Angélica | N5: =IF(E5="Sim",VLOOKUP(D5,'Inscrições'!D:H,5,FALSE),I5) -> Gestão municipal
A6: 45750.406 | B6: marisantin6@gmail.com | C6: Marilete Santin | D6: 009.602.231-00 | E6: Sim | M6: =IF(E6="Não",H6,VLOOKUP(D6,'Inscrições'!D:G,4,FALSE)) -> Rio Brilhante | N6: =IF(E6="Sim",VLOOKUP(D6,'Inscrições'!D:H,5,FALSE),I6) -> CACS-FUNDEB
A7: 45750.407 | B7: Transporteescolar@novaalvoradadosul.ms.gov.br | C7: Ozeias Morais da Silva | D7: 014.985.871-00 | E7: Sim | M7: =IF(E7="Não",H7,VLOOKUP(D7,'Inscrições'!D:G,4,FALSE)) -> Nova Alvorada do Sul | N7: =IF(E7="Sim",VLOOKUP(D7,'Inscrições'!D:H,5,FALSE),I7) -> Gestão municipal
A8: 45750.41 | B8: adalbertohonorato@hotmail.com | C8: Adalberto Honorato | D8: 015.174.281-22 | E8: Não | F8: 31509 | G8: (67)99614-9223 | H8: Nova Alvorada do Sul | I8: CACS-FUNDEB | L8: Membro Fundeb | M8: =IF(E8="Não",H8,VLOOKUP(D8,'Inscrições'!D:G,4,FALSE)) -> Nova Alvorada do Sul | N8: =IF(E8="Sim",VLOOKUP(D8,'Inscrições'!D:H,5,FALSE),I8) -> CACS-FUNDEB
A9: 45749.471 | B9: smec2018@outlook.com | C9: Adriana Ramos da Silva | D9: 015.884.291-05 | E9: Sim | M9: =IF(E9="Não",H9,VLOOKUP(D9,'Inscrições'!D:G,4,FALSE)) -> Batayporã | N9: =IF(E9="Sim",VLOOKUP(D9,'Inscrições'!D:H,5,FALSE),I9) -> Gestão municipal
A10: 45749.423 | B10: clariceeducacaof2@gmail.com | C10: Clarice de Almeida Faria | D10: 018.097.781-40 | E10: Não | F10: 31200 | G10: (67)99870-7697 | H10: Paraíso das Águas | I10: Gestão municipal | J10: Chefe da Divisão do transporte escolar | M10: =IF(E10="Não",H10,VLOOKUP(D10,'Inscrições'!D:G,4,FALSE)) -> Paraíso das Águas | N10: =IF(E10="Sim",VLOOKUP(D10,'Inscrições'!D:H,5,FALSE),I10) -> Gestão municipal
A11: 45750.401 | B11: marcio021186@gmail.com | C11: Marcio de Souza Santos | D11: 018.880.441-28 | E11: Sim | M11: =IF(E11="Não",H11,VLOOKUP(D11,'Inscrições'!D:G,4,FALSE)) -> Taquarussu | N11: =IF(E11="Sim",VLOOKUP(D11,'Inscrições'!D:H,5,FALSE),I11) -> Gestão municipal
A12: 45749.469 | B12: vanderleifreitas722@gmail.com | C12: Vanderlei de Freitas Santos | D12: 019.226.361-77 | E12: Sim | M12: =IF(E12="Não",H12,VLOOKUP(D12,'Inscrições'!D:G,4,FALSE)) -> Batayporã | N12: =IF(E12="Sim",VLOOKUP(D12,'Inscrições'!D:H,5,FALSE),I12) -> CACS-FUNDEB
A13: 45749.406 | B13: ricardosm2002@hotmail.com | C13: Ricardo Souza Marchini | D13: 022.616.841-77 | E13: Sim | M13: =IF(E13="Não",H13,VLOOKUP(D13,'Inscrições'!D:G,4,FALSE)) -> Angélica | N13: =IF(E13="Sim",VLOOKUP(D13,'Inscrições'!D:H,5,FALSE),I13) -> Gestão municipal
A14: 45749.409 | B14: anapedrodugordo12@gmail.com | C14: Ana Cecília Santos Oliveira | D14: 022.800.451-92 | E14: Não | F14: 31610 | G14: (67)99901-8178 | H14: Douradina | I14: Gestão municipal | J14: Conselheira Tutelar | M14: =IF(E14="Não",H14,VLOOKUP(D14,'Inscrições'!D:G,4,FALSE)) -> Douradina | N14: =IF(E14="Sim",VLOOKUP(D14,'Inscrições'!D:H,5,FALSE),I14) -> Gestão municipal
A15: 45749.464 | B15: anapedrodugordo12@gmail.com | C15: Ana Cecília Santos Oliveira | D15: 022.800.451-92 | E15: Não | F15: 31610 | G15: (67) 99901-8177 | H15: Douradina | I15: Gestão municipal | J15: Conselheira Tutelar | M15: =IF(E15="Não",H15,VLOOKUP(D15,'Inscrições'!D:G,4,FALSE)) -> Douradina | N15: =IF(E15="Sim",VLOOKUP(D15,'Inscrições'!D:H,5,FALSE),I15) -> Gestão municipal
A16: 45750.395 | B16: jaque_hernacki@hotmail.com | C16: Jaqueline Hernacki | D16: 023.145.741-33 | E16: Sim | M16: =IF(E16="Não",H16,VLOOKUP(D16,'Inscrições'!D:G,4,FALSE)) -> Paranhos | N16: =IF(E16="Sim",VLOOKUP(D16,'Inscrições'!D:H,5,FALSE),I16) -> Gestão municipal
A17: 45749.44 | B17: narahbraguini@gmail.com | C17: Nara Henrique Braguini | D17: 023.395.351-58 | E17: Sim | M17: =IF(E17="Não",H17,VLOOKUP(D17,'Inscrições'!D:G,4,FALSE)) -> Ivinhema | N17: =IF(E17="Sim",VLOOKUP(D17,'Inscrições'!D:H,5,FALSE),I17) -> Gestão municipal
A18: 45749.424 | B18: geovaniamachadolemos@gmail.com | C18: Geovania Machado Lemos | D18: 023.432.791-01 | E18: Não | F18: 31512 | G18: (67)99914-3233 | H18: Paraíso das Águas | I18: Gestão municipal | J18: Diretora de apoio administrativo | M18: =IF(E18="Não",H18,VLOOKUP(D18,'Inscrições'!D:G,4,FALSE)) -> Paraíso das Águas | N18: =IF(E18="Sim",VLOOKUP(D18,'Inscrições'!D:H,5,FALSE),I18) -> Gestão municipal
A19: 45749.498 | B19: rafaelfilho.sofia@gmail.com | C19: Rafael Aparecido da Silva Bezerra | D19: 028.916.671-31 | E19: Não | F19: 32475 | G19: (67) 98182-7265 | H19: Bataguassu | I19: Gestão municipal | J19: Coordenador do Transporte Escolar | M19: =IF(E19="Não",H19,VLOOKUP(D19,'Inscrições'!D:G,4,FALSE)) -> Bataguassu | N19: =IF(E19="Sim",VLOOKUP(D19,'Inscrições'!D:H,5,FALSE),I19) -> Gestão municipal
A20: 45749.399 | B20: prof_jcarvalho@outlook.com | C20: Jucimar Carvalho Chaves | D20: 031.051.231-05 | E20: Sim | M20: =IF(E20="Não",H20,VLOOKUP(D20,'Inscrições'!D:G,4,FALSE)) -> Coronel Sapucaia | N20: =IF(E20="Sim",VLOOKUP(D20,'Inscrições'!D:H,5,FALSE),I20) -> CACS-FUNDEB
A21: 45749.405 | B21: josilaineneves01@gmail.com | C21: Josilâine Neves da Silva | D21: 032.679.841-22 | E21: Sim | M21: =IF(E21="Não",H21,VLOOKUP(D21,'Inscrições'!D:G,4,FALSE)) -> Caarapó | N21: =IF(E21="Sim",VLOOKUP(D21,'Inscrições'!D:H,5,FALSE),I21) -> Gestão municipal
A22: 45750.537 | B22: simaoschuh1@gmail.com | C22: Simão Sirineu Schuh Dias | D22: 033.593.471-45 | E22: Sim | M22: =IF(E22="Não",H22,VLOOKUP(D22,'Inscrições'!D:G,4,FALSE)) -> #N/A | N22: =IF(E22="Sim",VLOOKUP(D22,'Inscrições'!D:H,5,FALSE),I22) -> #N/A
A23: 45750.405 | B23: thaine.stefani@gmail.com | C23: Thaine Stefani | D23: 034.548.621-83 | E23: Sim | M23: =IF(E23="Não",H23,VLOOKUP(D23,'Inscrições'!D:G,4,FALSE)) -> Rio Brilhante | N23: =IF(E23="Sim",VLOOKUP(D23,'Inscrições'!D:H,5,FALSE),I23) -> Gestão municipal
A24: 45749.861 | B24: profnunes11@gmail.com | C24: Claudineis Nunes | D24: 035.212.591-88 | E24: Sim | M24: =IF(E24="Não",H24,VLOOKUP(D24,'Inscrições'!D:G,4,FALSE)) -> Eldorado | N24: =IF(E24="Sim",VLOOKUP(D24,'Inscrições'!D:H,5,FALSE),I24) -> CACS-FUNDEB
A25: 45750.462 | B25: murillolima12@gmail.com | C25: Amanda Gonsales de lima | D25: 035.584.901-18 | E25: Sim | M25: =IF(E25="Não",H25,VLOOKUP(D25,'Inscrições'!D:G,4,FALSE)) -> Taquarussu | N25: =IF(E25="Sim",VLOOKUP(D25,'Inscrições'!D:H,5,FALSE),I25) -> Gestão municipal
A26: 45749.499 | B26: maurosanp_@hotmail.com | C26: Mauro San pereira da silva | D26: 038.697.801-85 | E26: Sim | M26: =IF(E26="Não",H26,VLOOKUP(D26,'Inscrições'!D:G,4,FALSE)) -> Iguatemi | N26: =IF(E26="Sim",VLOOKUP(D26,'Inscrições'!D:H,5,FALSE),I26) -> Gestão municipal
A27: 45750.413 | B27: andreluizgomes5691@gmail.com | C27: André Luiz Gomes da Silva | D27: 038.713.231-79 | E27: Sim | M27: =IF(E27="Não",H27,VLOOKUP(D27,'Inscrições'!D:G,4,FALSE)) -> Juti | N27: =IF(E27="Sim",VLOOKUP(D27,'Inscrições'!D:H,5,FALSE),I27) -> Gestão municipal
A28: 45750.405 | B28: uesley.u@gmail.com | C28: Uesley Souza Silva | D28: 041.510.051-88 | E28: Sim | M28: =IF(E28="Não",H28,VLOOKUP(D28,'Inscrições'!D:G,4,FALSE)) -> Rio Brilhante | N28: =IF(E28="Sim",VLOOKUP(D28,'Inscrições'!D:H,5,FALSE),I28) -> CACS-FUNDEB
A29: 45750.544 | B29: julianimalu@gmail.com | C29: Juliani Cristini Sieve | D29: 045.073.871-08 | E29: Não | F29: 34332 | G29: (67)98119-9686 | H29: Novo Horizonte do Sul | I29: CACS-FUNDEB | L29: Represetante de Pais | M29: =IF(E29="Não",H29,VLOOKUP(D29,'Inscrições'!D:G,4,FALSE)) -> Novo Horizonte do Sul | N29: =IF(E29="Sim",VLOOKUP(D29,'Inscrições'!D:H,5,FALSE),I29) -> CACS-FUNDEB
A30: 45750.543 | B30: anderson-2511@hotmail.com | C30: Anderson Oliveria Souza | D30: 045.727.011-05 | E30: Sim | M30: =IF(E30="Não",H30,VLOOKUP(D30,'Inscrições'!D:G,4,FALSE)) -> Novo Horizonte do Sul | N30: =IF(E30="Sim",VLOOKUP(D30,'Inscrições'!D:H,5,FALSE),I30) -> Gestão municipal
A31: 45750.395 | B31: fagnergalina33@gmail.com | C31: Fagner Rodrigues Galina | D31: 046.804.109-57 | E31: Sim | M31: =IF(E31="Não",H31,VLOOKUP(D31,'Inscrições'!D:G,4,FALSE)) -> Paranhos | N31: =IF(E31="Sim",VLOOKUP(D31,'Inscrições'!D:H,5,FALSE),I31) -> Gestão municipal
A32: 45749.496 | B32: fayane.m@hotmail.com | C32: Fayane Montenegro Gonçalves Paz | D32: 048.862.981-09 | E32: Não | F32: 34577 | G32: (67) 99684-8202 | H32: Douradina | I32: Gestão municipal | J32: Técnica administrativa | M32: =IF(E32="Não",H32,VLOOKUP(D32,'Inscrições'!D:G,4,FALSE)) -> Douradina | N32: =IF(E32="Sim",VLOOKUP(D32,'Inscrições'!D:H,5,FALSE),I32) -> Gestão municipal
A33: 45750.399 | B33: gabrielbarbosa_costa@live.com | C33: Gabriel Barbosa Costa | D33: 050.776.421-84 | E33: Sim | M33: =IF(E33="Não",H33,VLOOKUP(D33,'Inscrições'!D:G,4,FALSE)) -> Maracaju | N33: =IF(E33="Sim",VLOOKUP(D33,'Inscrições'!D:H,5,FALSE),I33) -> Gestão municipal
A34: 45750.405 | B34: analuizavenite@gmail.com | C34: Ana Luiza Venite Gama | D34: 058.764.141-07 | E34: Sim | M34: =IF(E34="Não",H34,VLOOKUP(D34,'Inscrições'!D:G,4,FALSE)) -> Rio Brilhante | N34: =IF(E34="Sim",VLOOKUP(D34,'Inscrições'!D:H,5,FALSE),I34) -> Gestão municipal
A35: 45750.407 | B35: soniareginameireleslago@gmail.com | C35: Sônia Regina Meireles Lago | D35: 063.006.468-74 | E35: Sim | M35: =IF(E35="Não",H35,VLOOKUP(D35,'Inscrições'!D:G,4,FALSE)) -> Laguna Carapã | N35: =IF(E35="Sim",VLOOKUP(D35,'Inscrições'!D:H,5,FALSE),I35) -> CACS-FUNDEB
A36: 45749.401 | B36: luizaquevedonascimento@gmail.com | C36: Luiza Quevedo Nascimento | D36: 065.889.541-90 | E36: Sim | M36: =IF(E36="Não",H36,VLOOKUP(D36,'Inscrições'!D:G,4,FALSE)) -> Dourados | N36: =IF(E36="Sim",VLOOKUP(D36,'Inscrições'!D:H,5,FALSE),I36) -> Gestão municipal
A37: 45750.397 | B37: ricartegv@gmail.com | C37: Gabriel Vinicius Ricarte Pedrozo | D37: 070.184.021-82 | E37: Sim | M37: =IF(E37="Não",H37,VLOOKUP(D37,'Inscrições'!D:G,4,FALSE)) -> Maracaju | N37: =IF(E37="Sim",VLOOKUP(D37,'Inscrições'!D:H,5,FALSE),I37) -> Gestão municipal
A38: 45749.502 | B38: gustavo.texeira33@gmail.com | C38: Gustavo Texeira Silva | D38: 070.308.241-80 | E38: Sim | M38: =IF(E38="Não",H38,VLOOKUP(D38,'Inscrições'!D:G,4,FALSE)) -> Dourados | N38: =IF(E38="Sim",VLOOKUP(D38,'Inscrições'!D:H,5,FALSE),I38) -> Gestão municipal
A39: 45750.398 | B39: augustocesarinformarica@gmail.com | C39: Augusto César Henriques | D39: 080.397.776-07 | E39: Não | F39: 31405 | G39: (67) 998271129 | H39: Maracaju | I39: Gestão municipal | J39: Técnico de Prestação de contas do transporte escolar | M39: =IF(E39="Não",H39,VLOOKUP(D39,'Inscrições'!D:G,4,FALSE)) -> Maracaju | N39: =IF(E39="Sim",VLOOKUP(D39,'Inscrições'!D:H,5,FALSE),I39) -> Gestão municipal
A40: 45750.4 | B40: danimedina826@gmail.com | C40: Daniela Medina | D40: 083.222.581-94 | E40: Não | F40: 36569 | G40: (67) 998523934 | H40: Laguna Carapã | I40: Gestão municipal | J40: Técnica | M40: =IF(E40="Não",H40,VLOOKUP(D40,'Inscrições'!D:G,4,FALSE)) -> Laguna Carapã | N40: =IF(E40="Sim",VLOOKUP(D40,'Inscrições'!D:H,5,FALSE),I40) -> Gestão municipal
...
