Workbook

Sheet Respostas ao formulário 1
A1: Carimbo de data/hora | B1: Endereço de e-mail | C1: Nome Completo: | D1: CPF: XXX.XXX.XXX-XX | E1: Você já está inscrito no Curso de Capacitação em Transporte Escolar? | F1: Data de Nascimento | G1: Telefone (XX)XXXXX-XXXX | H1: Município que representa: | I1: Você faz parte do: | J1: Que cargo você ocupa na gestão municipal? | K1: Prezado(a) Gestor(a), Se existe algum caso de sucesso da gestão do transporte escolar no seu município, gostaríamos conhecer mais um pouco ao respeito. Por favor, relate de forma sucinta o caso de sucesso no espaço a seguir: | L1: Que cargo você ocupa no CACS-FUNDEB? | M1: Telefone: (DD)XXXXX-XXXX | N1: #### | O1: Data de Nascimento 2 | P1: Telefone (XX)XXXXX-XXXX 2 | Q1: Município que representa: 2 | R1: Você faz parte do: 2
A2: 45838.342 | B2: aldenimachado2@gmail.com | C2: Aldeni Morais Machado santana | D2: 042.871.251-77 | E2: Sim | M2: (66)99931-4023 | O2: =IF(E2="Sim",VLOOKUP(D2,Tabela_1[[#ALL],[CPF]:[Que cargo você ocupa no CACS-FUNDEB?]],2,FALSE),F2) -> 34644 | P2: =IF(E2="Sim",VLOOKUP(D2,Tabela_1[[#ALL],[CPF]:[Que cargo você ocupa no CACS-FUNDEB?]],3,FALSE),G2) -> (66)99931-4023 | Q2: =IF(E2="Sim",VLOOKUP(D2,Tabela_1[[#ALL],[CPF]:[Que cargo você ocupa no CACS-FUNDEB?]],4,FALSE),H2) -> COLÍDER | R2: =IF(E2="Sim",VLOOKUP(D2,Tabela_1[[#ALL],[CPF]:[Que cargo você ocupa no CACS-FUNDEB?]],5,FALSE),I2) -> Gestão municipal
A3: 45834.377 | B3: anaclaudiadalmolin1@gmail.com | C3: Ana Claudia Dalmolin | D3: 039.487.011-56 | E3: Sim | M3: (66)99660-6600 | O3: =IF(E3="Sim",VLOOKUP(D3,Tabela_1[[#ALL],[CPF]:[Que cargo você ocupa no CACS-FUNDEB?]],2,FALSE),F3) -> 33322 | P3: =IF(E3="Sim",VLOOKUP(D3,Tabela_1[[#ALL],[CPF]:[Que cargo você ocupa no CACS-FUNDEB?]],3,FALSE),G3) -> (66)99660-6600 | Q3: =IF(E3="Sim",VLOOKUP(D3,Tabela_1[[#ALL],[CPF]:[Que cargo você ocupa no CACS-FUNDEB?]],4,FALSE),H3) -> MARCELÂNDIA | R3: =IF(E3="Sim",VLOOKUP(D3,Tabela_1[[#ALL],[CPF]:[Que cargo você ocupa no CACS-FUNDEB?]],5,FALSE),I3) -> CACS-FUNDEB
A4: 45833.404 | B4: anaclaudiagermano26@gmail.com | C4: Ana Claudia Germano Alves | D4: 047.152.811-04 | E4: Sim | O4: =IF(E4="Sim",VLOOKUP(D4,Tabela_1[[#ALL],[CPF]:[Que cargo você ocupa no CACS-FUNDEB?]],2,FALSE),F4) -> 35610 | P4: =IF(E4="Sim",VLOOKUP(D4,Tabela_1[[#ALL],[CPF]:[Que cargo você ocupa no CACS-FUNDEB?]],3,FALSE),G4) -> (66)98470-1708 | Q4: =IF(E4="Sim",VLOOKUP(D4,Tabela_1[[#ALL],[CPF]:[Que cargo você ocupa no CACS-FUNDEB?]],4,FALSE),H4) -> ITANHANGÁ | R4: =IF(E4="Sim",VLOOKUP(D4,Tabela_1[[#ALL],[CPF]:[Que cargo você ocupa no CACS-FUNDEB?]],5,FALSE),I4) -> CACS-FUNDEB
A5: 45833.404 | B5: cristinabryan140@gmail.com | C5: Ana Cristina Silva valente | D5: 011.159.092-23 | E5: Sim | O5: =IF(E5="Sim",VLOOKUP(D5,Tabela_1[[#ALL],[CPF]:[Que cargo você ocupa no CACS-FUNDEB?]],2,FALSE),F5) -> 34236 | P5: =IF(E5="Sim",VLOOKUP(D5,Tabela_1[[#ALL],[CPF]:[Que cargo você ocupa no CACS-FUNDEB?]],3,FALSE),G5) -> (66)99256-4288 | Q5: =IF(E5="Sim",VLOOKUP(D5,Tabela_1[[#ALL],[CPF]:[Que cargo você ocupa no CACS-FUNDEB?]],4,FALSE),H5) -> MATUPÁ | R5: =IF(E5="Sim",VLOOKUP(D5,Tabela_1[[#ALL],[CPF]:[Que cargo você ocupa no CACS-FUNDEB?]],5,FALSE),I5) -> Gestão municipal
A6: 45833.41 | B6: pereiraanaesther184@gmail.com | C6: ANA ESTHER PEREIRA MENDONÇA | D6: 110.018.751-09 | E6: Não | F6: 37684 | G6: (66)99256-8735 | H6: Guarantã do Norte | I6: Gestão municipal | J6: Técnica de sistemas | O6: =IF(E6="Sim",VLOOKUP(D6,Tabela_1[[#ALL],[CPF]:[Que cargo você ocupa no CACS-FUNDEB?]],2,FALSE),F6) -> 37684 | P6: =IF(E6="Sim",VLOOKUP(D6,Tabela_1[[#ALL],[CPF]:[Que cargo você ocupa no CACS-FUNDEB?]],3,FALSE),G6) -> (66)99256-8735 | Q6: =IF(E6="Sim",VLOOKUP(D6,Tabela_1[[#ALL],[CPF]:[Que cargo você ocupa no CACS-FUNDEB?]],4,FALSE),H6) -> Guarantã do Norte | R6: =IF(E6="Sim",VLOOKUP(D6,Tabela_1[[#ALL],[CPF]:[Que cargo você ocupa no CACS-FUNDEB?]],5,FALSE),I6) -> Gestão municipal
A7: 45834.372 | B7: anapaulatavarescamara@hotmail.com | C7: Ana Paula Tavares da Câmara Canguçu | D7: 031.269.751-19 | E7: Sim | M7: (66)99724-7789 | O7: =IF(E7="Sim",VLOOKUP(D7,Tabela_1[[#ALL],[CPF]:[Que cargo você ocupa no CACS-FUNDEB?]],2,FALSE),F7) -> 32799 | P7: =IF(E7="Sim",VLOOKUP(D7,Tabela_1[[#ALL],[CPF]:[Que cargo você ocupa no CACS-FUNDEB?]],3,FALSE),G7) -> (66)99724-7789 | Q7: =IF(E7="Sim",VLOOKUP(D7,Tabela_1[[#ALL],[CPF]:[Que cargo você ocupa no CACS-FUNDEB?]],4,FALSE),H7) -> MARCELÂNDIA | R7: =IF(E7="Sim",VLOOKUP(D7,Tabela_1[[#ALL],[CPF]:[Que cargo você ocupa no CACS-FUNDEB?]],5,FALSE),I7) -> CACS-FUNDEB
A8: 45834.417 | B8: andreikrasowski3@gmail.com | C8: Andrei de Jesus krasowski | D8: 054.353.841-92 | E8: Sim | M8: (66)99716-0375 | O8: =IF(E8="Sim",VLOOKUP(D8,Tabela_1[[#ALL],[CPF]:[Que cargo você ocupa no CACS-FUNDEB?]],2,FALSE),F8) -> 36982 | P8: =IF(E8="Sim",VLOOKUP(D8,Tabela_1[[#ALL],[CPF]:[Que cargo você ocupa no CACS-FUNDEB?]],3,FALSE),G8) -> (66)99716-0375 | Q8: =IF(E8="Sim",VLOOKUP(D8,Tabela_1[[#ALL],[CPF]:[Que cargo você ocupa no CACS-FUNDEB?]],4,FALSE),H8) -> VERA | R8: =IF(E8="Sim",VLOOKUP(D8,Tabela_1[[#ALL],[CPF]:[Que cargo você ocupa no CACS-FUNDEB?]],5,FALSE),I8) -> Gestão municipal
A9: 45834.41 | B9: romancamili91@gmail.com | C9: Camili Roman Gomes | D9: 062.818.251-10 | E9: Sim | M9: (65)99223-4880 | O9: =IF(E9="Sim",VLOOKUP(D9,Tabela_1[[#ALL],[CPF]:[Que cargo você ocupa no CACS-FUNDEB?]],2,FALSE),F9) -> 38145 | P9: =IF(E9="Sim",VLOOKUP(D9,Tabela_1[[#ALL],[CPF]:[Que cargo você ocupa no CACS-FUNDEB?]],3,FALSE),G9) -> (65)99223-4880 | Q9: =IF(E9="Sim",VLOOKUP(D9,Tabela_1[[#ALL],[CPF]:[Que cargo você ocupa no CACS-FUNDEB?]],4,FALSE),H9) -> SÃO JOSÉ DO RIO CLARO | R9: =IF(E9="Sim",VLOOKUP(D9,Tabela_1[[#ALL],[CPF]:[Que cargo você ocupa no CACS-FUNDEB?]],5,FALSE),I9) -> Gestão municipal
A10: 45833.407 | B10: carlim.albsilva@gmail.com | C10: Carlos Alberto Silva | D10: 032.805.231-09 | E10: Sim | O10: =IF(E10="Sim",VLOOKUP(D10,Tabela_1[[#ALL],[CPF]:[Que cargo você ocupa no CACS-FUNDEB?]],2,FALSE),F10) -> 32218 | P10: =IF(E10="Sim",VLOOKUP(D10,Tabela_1[[#ALL],[CPF]:[Que cargo você ocupa no CACS-FUNDEB?]],3,FALSE),G10) -> (66)99658-2531 | Q10: =IF(E10="Sim",VLOOKUP(D10,Tabela_1[[#ALL],[CPF]:[Que cargo você ocupa no CACS-FUNDEB?]],4,FALSE),H10) -> COLÍDER | R10: =IF(E10="Sim",VLOOKUP(D10,Tabela_1[[#ALL],[CPF]:[Que cargo você ocupa no CACS-FUNDEB?]],5,FALSE),I10) -> CACS-FUNDEB
A11: 45833.403 | B11: catheachapla@gmail.com | C11: Cathea chapla | D11: 019.896.331-96 | E11: Sim | O11: =IF(E11="Sim",VLOOKUP(D11,Tabela_1[[#ALL],[CPF]:[Que cargo você ocupa no CACS-FUNDEB?]],2,FALSE),F11) -> 32228 | P11: =IF(E11="Sim",VLOOKUP(D11,Tabela_1[[#ALL],[CPF]:[Que cargo você ocupa no CACS-FUNDEB?]],3,FALSE),G11) -> (66)99637-6598 | Q11: =IF(E11="Sim",VLOOKUP(D11,Tabela_1[[#ALL],[CPF]:[Que cargo você ocupa no CACS-FUNDEB?]],4,FALSE),H11) -> SORRISO | R11: =IF(E11="Sim",VLOOKUP(D11,Tabela_1[[#ALL],[CPF]:[Que cargo você ocupa no CACS-FUNDEB?]],5,FALSE),I11) -> Gestão municipal
A12: 45833.404 | B12: celia_ometto@hotmail.com | C12: Célia Pereira Bueno da Silva | D12: 001.549.211-73 | E12: Não | F12: 27549 | G12: (66)99613-2253 | H12: Matupá | I12: Gestão Municipal | J12: Secretaria Adjunta | O12: =IF(E12="Sim",VLOOKUP(D12,Tabela_1[[#ALL],[CPF]:[Que cargo você ocupa no CACS-FUNDEB?]],2,FALSE),F12) -> 27549 | P12: =IF(E12="Sim",VLOOKUP(D12,Tabela_1[[#ALL],[CPF]:[Que cargo você ocupa no CACS-FUNDEB?]],3,FALSE),G12) -> (66)99613-2253 | Q12: =IF(E12="Sim",VLOOKUP(D12,Tabela_1[[#ALL],[CPF]:[Que cargo você ocupa no CACS-FUNDEB?]],4,FALSE),H12) -> Matupá | R12: =IF(E12="Sim",VLOOKUP(D12,Tabela_1[[#ALL],[CPF]:[Que cargo você ocupa no CACS-FUNDEB?]],5,FALSE),I12) -> Gestão Municipal
A13: 45834.41 | B13: claudimiro.freitas@edu.mt.gov.br | C13: Claudimiro Neves de Freitas | D13: 021.934.271-78 | E13: Sim | M13: (66)99997-2630 | O13: =IF(E13="Sim",VLOOKUP(D13,Tabela_1[[#ALL],[CPF]:[Que cargo você ocupa no CACS-FUNDEB?]],2,FALSE),F13) -> 32244 | P13: =IF(E13="Sim",VLOOKUP(D13,Tabela_1[[#ALL],[CPF]:[Que cargo você ocupa no CACS-FUNDEB?]],3,FALSE),G13) -> (66)99997-2630 | Q13: =IF(E13="Sim",VLOOKUP(D13,Tabela_1[[#ALL],[CPF]:[Que cargo você ocupa no CACS-FUNDEB?]],4,FALSE),H13) -> SINOP | R13: =IF(E13="Sim",VLOOKUP(D13,Tabela_1[[#ALL],[CPF]:[Que cargo você ocupa no CACS-FUNDEB?]],5,FALSE),I13) -> Gestão municipal
A14: 45833.408 | B14: cleuseteulsenheimer@gmail.com | C14: Cleusete Aparecida Ulsenheimer | D14: 756.971.499-72 | E14: Não | F14: 25999 | G14: (66)98420-5653 | H14: ITANHANGÁ | I14: Gestão municipal | J14: Assessora Pedagógica | O14: =IF(E14="Sim",VLOOKUP(D14,Tabela_1[[#ALL],[CPF]:[Que cargo você ocupa no CACS-FUNDEB?]],2,FALSE),F14) -> 25999 | P14: =IF(E14="Sim",VLOOKUP(D14,Tabela_1[[#ALL],[CPF]:[Que cargo você ocupa no CACS-FUNDEB?]],3,FALSE),G14) -> (66)98420-5653 | Q14: =IF(E14="Sim",VLOOKUP(D14,Tabela_1[[#ALL],[CPF]:[Que cargo você ocupa no CACS-FUNDEB?]],4,FALSE),H14) -> ITANHANGÁ | R14: =IF(E14="Sim",VLOOKUP(D14,Tabela_1[[#ALL],[CPF]:[Que cargo você ocupa no CACS-FUNDEB?]],5,FALSE),I14) -> Gestão municipal
A15: 45833.404 | B15: daianar775@gmail.com | C15: Daiana Ribeiro Reis Barbosa | D15: 058.310.541-60 | E15: Sim | O15: =IF(E15="Sim",VLOOKUP(D15,Tabela_1[[#ALL],[CPF]:[Que cargo você ocupa no CACS-FUNDEB?]],2,FALSE),F15) -> 35992 | P15: =IF(E15="Sim",VLOOKUP(D15,Tabela_1[[#ALL],[CPF]:[Que cargo você ocupa no CACS-FUNDEB?]],3,FALSE),G15) -> (66)99622-4787 | Q15: =IF(E15="Sim",VLOOKUP(D15,Tabela_1[[#ALL],[CPF]:[Que cargo você ocupa no CACS-FUNDEB?]],4,FALSE),H15) -> MATUPÁ | R15: =IF(E15="Sim",VLOOKUP(D15,Tabela_1[[#ALL],[CPF]:[Que cargo você ocupa no CACS-FUNDEB?]],5,FALSE),I15) -> Gestão municipal
A16: 45834.412 | B16: debora_ge11@hotmail.com | C16: Débora Gonçalves Lopes Nogueira | D16: 038.659.701-41 | E16: Sim | M16: (66)99979-9337 | O16: =IF(E16="Sim",VLOOKUP(D16,Tabela_1[[#ALL],[CPF]:[Que cargo você ocupa no CACS-FUNDEB?]],2,FALSE),F16) -> 32880 | P16: =IF(E16="Sim",VLOOKUP(D16,Tabela_1[[#ALL],[CPF]:[Que cargo você ocupa no CACS-FUNDEB?]],3,FALSE),G16) -> (66)99979-9337 | Q16: =IF(E16="Sim",VLOOKUP(D16,Tabela_1[[#ALL],[CPF]:[Que cargo você ocupa no CACS-FUNDEB?]],4,FALSE),H16) -> PEIXOTO DE AZEVEDO | R16: =IF(E16="Sim",VLOOKUP(D16,Tabela_1[[#ALL],[CPF]:[Que cargo você ocupa no CACS-FUNDEB?]],5,FALSE),I16) -> CACS-FUNDEB
A17: 45833.404 | B17: deibsoncampos@hotmail.com | C17: Deibson Clei de Campos | D17: 000.733.161-48 | E17: Sim | O17: =IF(E17="Sim",VLOOKUP(D17,Tabela_1[[#ALL],[CPF]:[Que cargo você ocupa no CACS-FUNDEB?]],2,FALSE),F17) -> 30887 | P17: =IF(E17="Sim",VLOOKUP(D17,Tabela_1[[#ALL],[CPF]:[Que cargo você ocupa no CACS-FUNDEB?]],3,FALSE),G17) -> (66)98115-9365 | Q17: =IF(E17="Sim",VLOOKUP(D17,Tabela_1[[#ALL],[CPF]:[Que cargo você ocupa no CACS-FUNDEB?]],4,FALSE),H17) -> NOVA MARINGÁ | R17: =IF(E17="Sim",VLOOKUP(D17,Tabela_1[[#ALL],[CPF]:[Que cargo você ocupa no CACS-FUNDEB?]],5,FALSE),I17) -> Gestão municipal
A18: 45834.376 | B18: dbdalazen@gmail.com | C18: Denise Bortolozzo Dalazen | D18: 534.183.109-82 | E18: Sim | M18: (66)99292-5879 | O18: =IF(E18="Sim",VLOOKUP(D18,Tabela_1[[#ALL],[CPF]:[Que cargo você ocupa no CACS-FUNDEB?]],2,FALSE),F18) -> 24068 | P18: =IF(E18="Sim",VLOOKUP(D18,Tabela_1[[#ALL],[CPF]:[Que cargo você ocupa no CACS-FUNDEB?]],3,FALSE),G18) -> (66)99292-5879 | Q18: =IF(E18="Sim",VLOOKUP(D18,Tabela_1[[#ALL],[CPF]:[Que cargo você ocupa no CACS-FUNDEB?]],4,FALSE),H18) -> NOVO MUNDO | R18: =IF(E18="Sim",VLOOKUP(D18,Tabela_1[[#ALL],[CPF]:[Que cargo você ocupa no CACS-FUNDEB?]],5,FALSE),I18) -> Gestão municipal
A19: 45833.377 | B19: dianbattisti@hotmail.com | C19: Dian Carla Battisti Pit | D19: 031.367.381-01 | E19: Sim | O19: =IF(E19="Sim",VLOOKUP(D19,Tabela_1[[#ALL],[CPF]:[Que cargo você ocupa no CACS-FUNDEB?]],2,FALSE),F19) -> 32723 | P19: =IF(E19="Sim",VLOOKUP(D19,Tabela_1[[#ALL],[CPF]:[Que cargo você ocupa no CACS-FUNDEB?]],3,FALSE),G19) -> (66)98433-1211 | Q19: =IF(E19="Sim",VLOOKUP(D19,Tabela_1[[#ALL],[CPF]:[Que cargo você ocupa no CACS-FUNDEB?]],4,FALSE),H19) -> NOVA GUARITA | R19: =IF(E19="Sim",VLOOKUP(D19,Tabela_1[[#ALL],[CPF]:[Que cargo você ocupa no CACS-FUNDEB?]],5,FALSE),I19) -> Gestão municipal
A20: 45833.403 | B20: dianbattisti@hotmail.com | C20: Dian Carla Battisti Pit | D20: 031.367.381-01 | E20: Sim | O20: =IF(E20="Sim",VLOOKUP(D20,Tabela_1[[#ALL],[CPF]:[Que cargo você ocupa no CACS-FUNDEB?]],2,FALSE),F20) -> 32723 | P20: =IF(E20="Sim",VLOOKUP(D20,Tabela_1[[#ALL],[CPF]:[Que cargo você ocupa no CACS-FUNDEB?]],3,FALSE),G20) -> (66)98433-1211 | Q20: =IF(E20="Sim",VLOOKUP(D20,Tabela_1[[#ALL],[CPF]:[Que cargo você ocupa no CACS-FUNDEB?]],4,FALSE),H20) -> NOVA GUARITA | R20: =IF(E20="Sim",VLOOKUP(D20,Tabela_1[[#ALL],[CPF]:[Que cargo você ocupa no CACS-FUNDEB?]],5,FALSE),I20) -> Gestão municipal
A21: 45833.407 | B21: dorivalgomesmot17@gmail.com | C21: Dorival Gomes de Souza | D21: 925.508.511-53 | E21: Sim | O21: =IF(E21="Sim",VLOOKUP(D21,Tabela_1[[#ALL],[CPF]:[Que cargo você ocupa no CACS-FUNDEB?]],2,FALSE),F21) -> 28797 | P21: =IF(E21="Sim",VLOOKUP(D21,Tabela_1[[#ALL],[CPF]:[Que cargo você ocupa no CACS-FUNDEB?]],3,FALSE),G21) -> (66)98427-1575 | Q21: =IF(E21="Sim",VLOOKUP(D21,Tabela_1[[#ALL],[CPF]:[Que cargo você ocupa no CACS-FUNDEB?]],4,FALSE),H21) -> ITANHANGÁ | R21: =IF(E21="Sim",VLOOKUP(D21,Tabela_1[[#ALL],[CPF]:[Que cargo você ocupa no CACS-FUNDEB?]],5,FALSE),I21) -> CACS-FUNDEB
A22: 45833.411 | B22: dulcisec@gmail.com | C22: Dulcineia MATHIAS CABRAL | D22: 023.068.921-30 | E22: Sim | O22: =IF(E22="Sim",VLOOKUP(D22,Tabela_1[[#ALL],[CPF]:[Que cargo você ocupa no CACS-FUNDEB?]],2,FALSE),F22) -> 29775 | P22: =IF(E22="Sim",VLOOKUP(D22,Tabela_1[[#ALL],[CPF]:[Que cargo você ocupa no CACS-FUNDEB?]],3,FALSE),G22) -> (66)98467-3867 | Q22: =IF(E22="Sim",VLOOKUP(D22,Tabela_1[[#ALL],[CPF]:[Que cargo você ocupa no CACS-FUNDEB?]],4,FALSE),H22) -> GUARANTÃ DO NORTE | R22: =IF(E22="Sim",VLOOKUP(D22,Tabela_1[[#ALL],[CPF]:[Que cargo você ocupa no CACS-FUNDEB?]],5,FALSE),I22) -> Gestão municipal
A23: 45833.377 | B23: edelsonsousa_@hotmail.com | C23: Edelson manoel de sousa | D23: 299.445.031-34 | E23: Não | F23: 23793 | G23: (66)99665-9475 | H23: NOVA GUARITA | I23: Gestão municipal | J23: Motorista e responsável pela frota escolar | O23: =IF(E23="Sim",VLOOKUP(D23,Tabela_1[[#ALL],[CPF]:[Que cargo você ocupa no CACS-FUNDEB?]],2,FALSE),F23) -> 23793 | P23: =IF(E23="Sim",VLOOKUP(D23,Tabela_1[[#ALL],[CPF]:[Que cargo você ocupa no CACS-FUNDEB?]],3,FALSE),G23) -> (66)99665-9475 | Q23: =IF(E23="Sim",VLOOKUP(D23,Tabela_1[[#ALL],[CPF]:[Que cargo você ocupa no CACS-FUNDEB?]],4,FALSE),H23) -> NOVA GUARITA | R23: =IF(E23="Sim",VLOOKUP(D23,Tabela_1[[#ALL],[CPF]:[Que cargo você ocupa no CACS-FUNDEB?]],5,FALSE),I23) -> Gestão municipal
A24: 45833.405 | B24: edelsonsousa_@hotmail.com | C24: Edelson manoel de sousa | D24: 299.445.031-34 | E24: Não | F24: 23793 | G24: (66)99665-9475 | H24: NOVA GUARITA | I24: Gestão municipal | J24: Motorista e responsável pela frota escolar | O24: =IF(E24="Sim",VLOOKUP(D24,Tabela_1[[#ALL],[CPF]:[Que cargo você ocupa no CACS-FUNDEB?]],2,FALSE),F24) -> 23793 | P24: =IF(E24="Sim",VLOOKUP(D24,Tabela_1[[#ALL],[CPF]:[Que cargo você ocupa no CACS-FUNDEB?]],3,FALSE),G24) -> (66)99665-9475 | Q24: =IF(E24="Sim",VLOOKUP(D24,Tabela_1[[#ALL],[CPF]:[Que cargo você ocupa no CACS-FUNDEB?]],4,FALSE),H24) -> NOVA GUARITA | R24: =IF(E24="Sim",VLOOKUP(D24,Tabela_1[[#ALL],[CPF]:[Que cargo você ocupa no CACS-FUNDEB?]],5,FALSE),I24) -> Gestão municipal
A25: 45833.411 | B25: ricardo.felipeom@gmail.com | C25: Felipe Ricardo de Oliveira Morais | D25: 061.514.082-33 | E25: Sim | O25: =IF(E25="Sim",VLOOKUP(D25,Tabela_1[[#ALL],[CPF]:[Que cargo você ocupa no CACS-FUNDEB?]],2,FALSE),F25) -> 38133 | P25: =IF(E25="Sim",VLOOKUP(D25,Tabela_1[[#ALL],[CPF]:[Que cargo você ocupa no CACS-FUNDEB?]],3,FALSE),G25) -> (66)99213-0672 | Q25: =IF(E25="Sim",VLOOKUP(D25,Tabela_1[[#ALL],[CPF]:[Que cargo você ocupa no CACS-FUNDEB?]],4,FALSE),H25) -> ALTA FLORESTA | R25: =IF(E25="Sim",VLOOKUP(D25,Tabela_1[[#ALL],[CPF]:[Que cargo você ocupa no CACS-FUNDEB?]],5,FALSE),I25) -> Gestão municipal
A26: 45833.408 | B26: flavia.lopes@edu.colider.mt.gov.br | C26: Flávia Corrêa da Silveira Lopes | D26: 963.391.101-00 | E26: Sim | O26: =IF(E26="Sim",VLOOKUP(D26,Tabela_1[[#ALL],[CPF]:[Que cargo você ocupa no CACS-FUNDEB?]],2,FALSE),F26) -> 30267 | P26: =IF(E26="Sim",VLOOKUP(D26,Tabela_1[[#ALL],[CPF]:[Que cargo você ocupa no CACS-FUNDEB?]],3,FALSE),G26) -> (66)99625-9414 | Q26: =IF(E26="Sim",VLOOKUP(D26,Tabela_1[[#ALL],[CPF]:[Que cargo você ocupa no CACS-FUNDEB?]],4,FALSE),H26) -> COLÍDER | R26: =IF(E26="Sim",VLOOKUP(D26,Tabela_1[[#ALL],[CPF]:[Que cargo você ocupa no CACS-FUNDEB?]],5,FALSE),I26) -> CACS-FUNDEB
A27: 45834.398 | B27: sme.transporteescolarsinop@gmail.com | C27: Francieli Maria Hammes | D27: 042.524.451-24 | E27: Não | F27: 33857 | G27: (66)99914-1672 | H27: Sinop | I27: Gestão municipal | J27: Analista administrativo | M27: (66)99914-1672 | O27: =IF(E27="Sim",VLOOKUP(D27,Tabela_1[[#ALL],[CPF]:[Que cargo você ocupa no CACS-FUNDEB?]],2,FALSE),F27) -> 33857 | P27: =IF(E27="Sim",VLOOKUP(D27,Tabela_1[[#ALL],[CPF]:[Que cargo você ocupa no CACS-FUNDEB?]],3,FALSE),G27) -> (66)99914-1672 | Q27: =IF(E27="Sim",VLOOKUP(D27,Tabela_1[[#ALL],[CPF]:[Que cargo você ocupa no CACS-FUNDEB?]],4,FALSE),H27) -> Sinop | R27: =IF(E27="Sim",VLOOKUP(D27,Tabela_1[[#ALL],[CPF]:[Que cargo você ocupa no CACS-FUNDEB?]],5,FALSE),I27) -> Gestão municipal
A28: 45834.375 | B28: gisellifujimori@gmail.com | C28: Giselli Satiko Toyomoto Fujimori | D28: 064.633.091-84 | E28: Sim | M28: (66)99221-0876 | O28: =IF(E28="Sim",VLOOKUP(D28,Tabela_1[[#ALL],[CPF]:[Que cargo você ocupa no CACS-FUNDEB?]],2,FALSE),F28) -> 38376 | P28: =IF(E28="Sim",VLOOKUP(D28,Tabela_1[[#ALL],[CPF]:[Que cargo você ocupa no CACS-FUNDEB?]],3,FALSE),G28) -> (66)99221-0876 | Q28: =IF(E28="Sim",VLOOKUP(D28,Tabela_1[[#ALL],[CPF]:[Que cargo você ocupa no CACS-FUNDEB?]],4,FALSE),H28) -> SINOP | R28: =IF(E28="Sim",VLOOKUP(D28,Tabela_1[[#ALL],[CPF]:[Que cargo você ocupa no CACS-FUNDEB?]],5,FALSE),I28) -> Gestão municipal
A29: 45834.411 | B29: matosjarlene5@gmail.com | C29: Jarlene maria silva matos | D29: 049.578.646-97 | E29: Não | F29: 28458 | G29: (66)99966-6774 | H29: Peixoto de azevedo | I29: Gestão municipal | J29: técnico do transporte escolar | M29: (66)99966-6774 | O29: =IF(E29="Sim",VLOOKUP(D29,Tabela_1[[#ALL],[CPF]:[Que cargo você ocupa no CACS-FUNDEB?]],2,FALSE),F29) -> 28458 | P29: =IF(E29="Sim",VLOOKUP(D29,Tabela_1[[#ALL],[CPF]:[Que cargo você ocupa no CACS-FUNDEB?]],3,FALSE),G29) -> (66)99966-6774 | Q29: =IF(E29="Sim",VLOOKUP(D29,Tabela_1[[#ALL],[CPF]:[Que cargo você ocupa no CACS-FUNDEB?]],4,FALSE),H29) -> Peixoto de azevedo | R29: =IF(E29="Sim",VLOOKUP(D29,Tabela_1[[#ALL],[CPF]:[Que cargo você ocupa no CACS-FUNDEB?]],5,FALSE),I29) -> Gestão municipal
A30: 45834.443 | B30: jeffersonmarcolinii@hotmail.com | C30: Jefferson Henkes Marcolini | D30: 039.855.061-16 | E30: Sim | M30: (66)99624-2997 | O30: =IF(E30="Sim",VLOOKUP(D30,Tabela_1[[#ALL],[CPF]:[Que cargo você ocupa no CACS-FUNDEB?]],2,FALSE),F30) -> 33795 | P30: =IF(E30="Sim",VLOOKUP(D30,Tabela_1[[#ALL],[CPF]:[Que cargo você ocupa no CACS-FUNDEB?]],3,FALSE),G30) -> (66)99624-2997 | Q30: =IF(E30="Sim",VLOOKUP(D30,Tabela_1[[#ALL],[CPF]:[Que cargo você ocupa no CACS-FUNDEB?]],4,FALSE),H30) -> TERRA NOVA DO NORTE | R30: =IF(E30="Sim",VLOOKUP(D30,Tabela_1[[#ALL],[CPF]:[Que cargo você ocupa no CACS-FUNDEB?]],5,FALSE),I30) -> Gestão municipal
A31: 45833.733 | B31: joaomarquesdacosta25@gmail.com | C31: João Marques da Costa | D31: 403.447.891-87 | E31: Sim | M31: (66)99662-4168 | O31: =IF(E31="Sim",VLOOKUP(D31,Tabela_1[[#ALL],[CPF]:[Que cargo você ocupa no CACS-FUNDEB?]],2,FALSE),F31) -> 24163 | P31: =IF(E31="Sim",VLOOKUP(D31,Tabela_1[[#ALL],[CPF]:[Que cargo você ocupa no CACS-FUNDEB?]],3,FALSE),G31) -> (66)99662-4168 | Q31: =IF(E31="Sim",VLOOKUP(D31,Tabela_1[[#ALL],[CPF]:[Que cargo você ocupa no CACS-FUNDEB?]],4,FALSE),H31) -> GUARANTÃ DO NORTE | R31: =IF(E31="Sim",VLOOKUP(D31,Tabela_1[[#ALL],[CPF]:[Que cargo você ocupa no CACS-FUNDEB?]],5,FALSE),I31) -> CACS-FUNDEB
A32: 45833.382 | B32: julianamazei@hotmail.com | C32: Juliana Mazei Silva | D32: 021.159.381-86 | E32: Não | F32: 32228 | G32: (66)999513-1479 | H32: Feliz Natal | I32: Gestão municipal | J32: Secretária de Educação | O32: =IF(E32="Sim",VLOOKUP(D32,Tabela_1[[#ALL],[CPF]:[Que cargo você ocupa no CACS-FUNDEB?]],2,FALSE),F32) -> 32228 | P32: =IF(E32="Sim",VLOOKUP(D32,Tabela_1[[#ALL],[CPF]:[Que cargo você ocupa no CACS-FUNDEB?]],3,FALSE),G32) -> (66)999513-1479 | Q32: =IF(E32="Sim",VLOOKUP(D32,Tabela_1[[#ALL],[CPF]:[Que cargo você ocupa no CACS-FUNDEB?]],4,FALSE),H32) -> Feliz Natal | R32: =IF(E32="Sim",VLOOKUP(D32,Tabela_1[[#ALL],[CPF]:[Que cargo você ocupa no CACS-FUNDEB?]],5,FALSE),I32) -> Gestão municipal
A33: 45833.405 | B33: kamilareislima@hotmail.com | C33: Kamila De Almeida Reis | D33: 718.028.431-91 | E33: Sim | O33: =IF(E33="Sim",VLOOKUP(D33,Tabela_1[[#ALL],[CPF]:[Que cargo você ocupa no CACS-FUNDEB?]],2,FALSE),F33) -> 29455 | P33: =IF(E33="Sim",VLOOKUP(D33,Tabela_1[[#ALL],[CPF]:[Que cargo você ocupa no CACS-FUNDEB?]],3,FALSE),G33) -> (66)99986-6165 | Q33: =IF(E33="Sim",VLOOKUP(D33,Tabela_1[[#ALL],[CPF]:[Que cargo você ocupa no CACS-FUNDEB?]],4,FALSE),H33) -> SORRISO | R33: =IF(E33="Sim",VLOOKUP(D33,Tabela_1[[#ALL],[CPF]:[Que cargo você ocupa no CACS-FUNDEB?]],5,FALSE),I33) -> CACS-FUNDEB
A34: 45833.404 | B34: karinabarros772@gmail.com | C34: KARINA RITA DE BARROS | D34: 062.569.491-02 | E34: Sim | O34: =IF(E34="Sim",VLOOKUP(D34,Tabela_1[[#ALL],[CPF]:[Que cargo você ocupa no CACS-FUNDEB?]],2,FALSE),F34) -> 35517 | P34: =IF(E34="Sim",VLOOKUP(D34,Tabela_1[[#ALL],[CPF]:[Que cargo você ocupa no CACS-FUNDEB?]],3,FALSE),G34) -> (66)98128-9477 | Q34: =IF(E34="Sim",VLOOKUP(D34,Tabela_1[[#ALL],[CPF]:[Que cargo você ocupa no CACS-FUNDEB?]],4,FALSE),H34) -> NOVA MARINGÁ | R34: =IF(E34="Sim",VLOOKUP(D34,Tabela_1[[#ALL],[CPF]:[Que cargo você ocupa no CACS-FUNDEB?]],5,FALSE),I34) -> CACS-FUNDEB
A35: 45833.376 | B35: katia_nervis@hotmail.com | C35: Katia nervis guedes | D35: 059.504.181-74 | E35: Sim | O35: =IF(E35="Sim",VLOOKUP(D35,Tabela_1[[#ALL],[CPF]:[Que cargo você ocupa no CACS-FUNDEB?]],2,FALSE),F35) -> 34437 | P35: =IF(E35="Sim",VLOOKUP(D35,Tabela_1[[#ALL],[CPF]:[Que cargo você ocupa no CACS-FUNDEB?]],3,FALSE),G35) -> (66)98443-1093 | Q35: =IF(E35="Sim",VLOOKUP(D35,Tabela_1[[#ALL],[CPF]:[Que cargo você ocupa no CACS-FUNDEB?]],4,FALSE),H35) -> NOVA GUARITA | R35: =IF(E35="Sim",VLOOKUP(D35,Tabela_1[[#ALL],[CPF]:[Que cargo você ocupa no CACS-FUNDEB?]],5,FALSE),I35) -> CACS-FUNDEB
A36: 45833.403 | B36: katia_nervis@hotmail.com | C36: Katia nervis guedes | D36: 059.504.181-74 | E36: Sim | O36: =IF(E36="Sim",VLOOKUP(D36,Tabela_1[[#ALL],[CPF]:[Que cargo você ocupa no CACS-FUNDEB?]],2,FALSE),F36) -> 34437 | P36: =IF(E36="Sim",VLOOKUP(D36,Tabela_1[[#ALL],[CPF]:[Que cargo você ocupa no CACS-FUNDEB?]],3,FALSE),G36) -> (66)98443-1093 | Q36: =IF(E36="Sim",VLOOKUP(D36,Tabela_1[[#ALL],[CPF]:[Que cargo você ocupa no CACS-FUNDEB?]],4,FALSE),H36) -> NOVA GUARITA | R36: =IF(E36="Sim",VLOOKUP(D36,Tabela_1[[#ALL],[CPF]:[Que cargo você ocupa no CACS-FUNDEB?]],5,FALSE),I36) -> CACS-FUNDEB
A37: 45834.377 | B37: lilianclaudia77@gmail.com | C37: Lilian Cláudia Pereira de Oliveira | D37: 036.728.641-61 | E37: Sim | M37: (66)99641-2813 | O37: =IF(E37="Sim",VLOOKUP(D37,Tabela_1[[#ALL],[CPF]:[Que cargo você ocupa no CACS-FUNDEB?]],2,FALSE),F37) -> 32554 | P37: =IF(E37="Sim",VLOOKUP(D37,Tabela_1[[#ALL],[CPF]:[Que cargo você ocupa no CACS-FUNDEB?]],3,FALSE),G37) -> (66)99641-2813 | Q37: =IF(E37="Sim",VLOOKUP(D37,Tabela_1[[#ALL],[CPF]:[Que cargo você ocupa no CACS-FUNDEB?]],4,FALSE),H37) -> NOVO MUNDO | R37: =IF(E37="Sim",VLOOKUP(D37,Tabela_1[[#ALL],[CPF]:[Que cargo você ocupa no CACS-FUNDEB?]],5,FALSE),I37) -> CACS-FUNDEB
A38: 45834.375 | B38: liliqnclaudia77@gmail.com | C38: Lilian Claudia Pereira de Oliveira | D38: 036.728.641-61 | E38: Sim | M38: (66)99641-2813 | O38: =IF(E38="Sim",VLOOKUP(D38,Tabela_1[[#ALL],[CPF]:[Que cargo você ocupa no CACS-FUNDEB?]],2,FALSE),F38) -> 32554 | P38: =IF(E38="Sim",VLOOKUP(D38,Tabela_1[[#ALL],[CPF]:[Que cargo você ocupa no CACS-FUNDEB?]],3,FALSE),G38) -> (66)99641-2813 | Q38: =IF(E38="Sim",VLOOKUP(D38,Tabela_1[[#ALL],[CPF]:[Que cargo você ocupa no CACS-FUNDEB?]],4,FALSE),H38) -> NOVO MUNDO | R38: =IF(E38="Sim",VLOOKUP(D38,Tabela_1[[#ALL],[CPF]:[Que cargo você ocupa no CACS-FUNDEB?]],5,FALSE),I38) -> CACS-FUNDEB
A39: 45833.416 | B39: onolisayuri@hotmail.com | C39: Lilian Sayuri Ono | D39: 830.654.741-15 | E39: Sim | O39: =IF(E39="Sim",VLOOKUP(D39,Tabela_1[[#ALL],[CPF]:[Que cargo você ocupa no CACS-FUNDEB?]],2,FALSE),F39) -> 29016 | P39: =IF(E39="Sim",VLOOKUP(D39,Tabela_1[[#ALL],[CPF]:[Que cargo você ocupa no CACS-FUNDEB?]],3,FALSE),G39) -> (66)99283-0493 | Q39: =IF(E39="Sim",VLOOKUP(D39,Tabela_1[[#ALL],[CPF]:[Que cargo você ocupa no CACS-FUNDEB?]],4,FALSE),H39) -> ALTA FLORESTA | R39: =IF(E39="Sim",VLOOKUP(D39,Tabela_1[[#ALL],[CPF]:[Que cargo você ocupa no CACS-FUNDEB?]],5,FALSE),I39) -> CACS-FUNDEB
A40: 45833.382 | B40: lilianekovaleski_fn@hotmail.com | C40: LILIANE KOVALESKI DEVETAK | D40: 003.644.911-32 | E40: Sim | O40: =IF(E40="Sim",VLOOKUP(D40,Tabela_1[[#ALL],[CPF]:[Que cargo você ocupa no CACS-FUNDEB?]],2,FALSE),F40) -> 30103 | P40: =IF(E40="Sim",VLOOKUP(D40,Tabela_1[[#ALL],[CPF]:[Que cargo você ocupa no CACS-FUNDEB?]],3,FALSE),G40) -> (66)99959-7479 | Q40: =IF(E40="Sim",VLOOKUP(D40,Tabela_1[[#ALL],[CPF]:[Que cargo você ocupa no CACS-FUNDEB?]],4,FALSE),H40) -> FELIZ NATAL | R40: =IF(E40="Sim",VLOOKUP(D40,Tabela_1[[#ALL],[CPF]:[Que cargo você ocupa no CACS-FUNDEB?]],5,FALSE),I40) -> CACS-FUNDEB
...

Sheet Emissão de certificado
A1: CPF | B1: Nome | C1: E-mail | D1: Data | E1: Cidade | F1: Função
A2: =Form_Responses1[CPF: XXX.XXX.XXX-XX] -> 042.871.251-77 | B2: ='Respostas ao formulário 1'!C2 -> Aldeni Morais Machado santana | C2: ='Respostas ao formulário 1'!B2 -> aldenimachado2@gmail.com | D2: ='Respostas ao formulário 1'!O25 -> 38133 | E2: ='Respostas ao formulário 1'!Q25 -> ALTA FLORESTA | F2: ='Respostas ao formulário 1'!R25 -> Gestão municipal
A3: =Form_Responses1[CPF: XXX.XXX.XXX-XX] -> 039.487.011-56 | B3: ='Respostas ao formulário 1'!C3 -> Ana Claudia Dalmolin | C3: ='Respostas ao formulário 1'!B3 -> anaclaudiadalmolin1@gmail.com | D3: ='Respostas ao formulário 1'!O39 -> 29016 | E3: ='Respostas ao formulário 1'!Q39 -> ALTA FLORESTA | F3: ='Respostas ao formulário 1'!R39 -> CACS-FUNDEB
A4: =Form_Responses1[CPF: XXX.XXX.XXX-XX] -> 047.152.811-04 | B4: ='Respostas ao formulário 1'!C4 -> Ana Claudia Germano Alves | C4: ='Respostas ao formulário 1'!B4 -> anaclaudiagermano26@gmail.com | D4: ='Respostas ao formulário 1'!O45 -> 28454 | E4: ='Respostas ao formulário 1'!Q45 -> ALTA FLORESTA | F4: ='Respostas ao formulário 1'!R45 -> CACS-FUNDEB
A5: =Form_Responses1[CPF: XXX.XXX.XXX-XX] -> 011.159.092-23 | B5: ='Respostas ao formulário 1'!C5 -> Ana Cristina Silva valente | C5: ='Respostas ao formulário 1'!B5 -> cristinabryan140@gmail.com | D5: ='Respostas ao formulário 1'!O56 -> 38133 | E5: ='Respostas ao formulário 1'!Q56 -> ALTA FLORESTA | F5: ='Respostas ao formulário 1'!R56 -> Gestão municipal
A6: =Form_Responses1[CPF: XXX.XXX.XXX-XX] -> 110.018.751-09 | B6: ='Respostas ao formulário 1'!C6 -> ANA ESTHER PEREIRA MENDONÇA | C6: ='Respostas ao formulário 1'!B6 -> pereiraanaesther184@gmail.com | D6: ='Respostas ao formulário 1'!O2 -> 34644 | E6: ='Respostas ao formulário 1'!Q2 -> COLÍDER | F6: ='Respostas ao formulário 1'!R2 -> Gestão municipal
A7: =Form_Responses1[CPF: XXX.XXX.XXX-XX] -> 031.269.751-19 | B7: ='Respostas ao formulário 1'!C7 -> Ana Paula Tavares da Câmara Canguçu | C7: ='Respostas ao formulário 1'!B7 -> anapaulatavarescamara@hotmail.com | D7: ='Respostas ao formulário 1'!O10 -> 32218 | E7: ='Respostas ao formulário 1'!Q10 -> COLÍDER | F7: ='Respostas ao formulário 1'!R10 -> CACS-FUNDEB
A8: =Form_Responses1[CPF: XXX.XXX.XXX-XX] -> 054.353.841-92 | B8: ='Respostas ao formulário 1'!C8 -> Andrei de Jesus krasowski | C8: ='Respostas ao formulário 1'!B8 -> andreikrasowski3@gmail.com | D8: ='Respostas ao formulário 1'!O42 -> 29502 | E8: ='Respostas ao formulário 1'!Q42 -> COLÍDER | F8: ='Respostas ao formulário 1'!R42 -> Gestão municipal
A9: =Form_Responses1[CPF: XXX.XXX.XXX-XX] -> 062.818.251-10 | B9: ='Respostas ao formulário 1'!C9 -> Camili Roman Gomes | C9: ='Respostas ao formulário 1'!B9 -> romancamili91@gmail.com | D9: ='Respostas ao formulário 1'!O32 -> 32228 | E9: ='Respostas ao formulário 1'!Q32 -> Feliz Natal | F9: ='Respostas ao formulário 1'!R32 -> Gestão municipal
A10: =Form_Responses1[CPF: XXX.XXX.XXX-XX] -> 032.805.231-09 | B10: ='Respostas ao formulário 1'!C10 -> Carlos Alberto Silva | C10: ='Respostas ao formulário 1'!B10 -> carlim.albsilva@gmail.com | D10: ='Respostas ao formulário 1'!O26 -> 30267 | E10: ='Respostas ao formulário 1'!Q26 -> COLÍDER | F10: ='Respostas ao formulário 1'!R26 -> CACS-FUNDEB
A11: =Form_Responses1[CPF: XXX.XXX.XXX-XX] -> 019.896.331-96 | B11: ='Respostas ao formulário 1'!C11 -> Cathea chapla | C11: ='Respostas ao formulário 1'!B11 -> catheachapla@gmail.com | D11: ='Respostas ao formulário 1'!O6 -> 37684 | E11: ='Respostas ao formulário 1'!Q6 -> Guarantã do Norte | F11: ='Respostas ao formulário 1'!R6 -> Gestão municipal
A12: =Form_Responses1[CPF: XXX.XXX.XXX-XX] -> 001.549.211-73 | B12: ='Respostas ao formulário 1'!C12 -> Célia Pereira Bueno da Silva | C12: ='Respostas ao formulário 1'!B12 -> celia_ometto@hotmail.com | D12: ='Respostas ao formulário 1'!O22 -> 29775 | E12: ='Respostas ao formulário 1'!Q22 -> GUARANTÃ DO NORTE | F12: ='Respostas ao formulário 1'!R22 -> Gestão municipal
A13: =Form_Responses1[CPF: XXX.XXX.XXX-XX] -> 021.934.271-78 | B13: ='Respostas ao formulário 1'!C13 -> Claudimiro Neves de Freitas | C13: ='Respostas ao formulário 1'!B13 -> claudimiro.freitas@edu.mt.gov.br | D13: ='Respostas ao formulário 1'!O49 -> 37484 | E13: ='Respostas ao formulário 1'!Q49 -> GUARANTÃ DO NORTE | F13: ='Respostas ao formulário 1'!R49 -> Gestão municipal
A14: =Form_Responses1[CPF: XXX.XXX.XXX-XX] -> 756.971.499-72 | B14: ='Respostas ao formulário 1'!C14 -> Cleusete Aparecida Ulsenheimer | C14: ='Respostas ao formulário 1'!B14 -> cleuseteulsenheimer@gmail.com | D14: ='Respostas ao formulário 1'!O55 -> 32075 | E14: ='Respostas ao formulário 1'!Q55 -> GUARANTÃ DO NORTE | F14: ='Respostas ao formulário 1'!R55 -> Gestão municipal
A15: =Form_Responses1[CPF: XXX.XXX.XXX-XX] -> 058.310.541-60 | B15: ='Respostas ao formulário 1'!C15 -> Daiana Ribeiro Reis Barbosa | C15: ='Respostas ao formulário 1'!B15 -> daianar775@gmail.com | D15: ='Respostas ao formulário 1'!O14 -> 25999 | E15: ='Respostas ao formulário 1'!Q14 -> ITANHANGÁ | F15: ='Respostas ao formulário 1'!R14 -> Gestão municipal
A16: =Form_Responses1[CPF: XXX.XXX.XXX-XX] -> 038.659.701-41 | B16: ='Respostas ao formulário 1'!C16 -> Débora Gonçalves Lopes Nogueira | C16: ='Respostas ao formulário 1'!B16 -> debora_ge11@hotmail.com | D16: ='Respostas ao formulário 1'!O40 -> 30103 | E16: ='Respostas ao formulário 1'!Q40 -> FELIZ NATAL | F16: ='Respostas ao formulário 1'!R40 -> CACS-FUNDEB
A17: =Form_Responses1[CPF: XXX.XXX.XXX-XX] -> 000.733.161-48 | B17: ='Respostas ao formulário 1'!C17 -> Deibson Clei de Campos | C17: ='Respostas ao formulário 1'!B17 -> deibsoncampos@hotmail.com | D17: ='Respostas ao formulário 1'!O44 -> 29275 | E17: ='Respostas ao formulário 1'!Q44 -> ITANHANGÁ | F17: ='Respostas ao formulário 1'!R44 -> Gestão municipal
A18: =Form_Responses1[CPF: XXX.XXX.XXX-XX] -> 534.183.109-82 | B18: ='Respostas ao formulário 1'!C18 -> Denise Bortolozzo Dalazen | C18: ='Respostas ao formulário 1'!B18 -> dbdalazen@gmail.com | D18: ='Respostas ao formulário 1'!O54 -> 28551 | E18: ='Respostas ao formulário 1'!Q54 -> MARCELÂNDIA | F18: ='Respostas ao formulário 1'!R54 -> Gestão municipal
A19: =Form_Responses1[CPF: XXX.XXX.XXX-XX] -> 031.367.381-01 | B19: ='Respostas ao formulário 1'!C19 -> Dian Carla Battisti Pit | C19: ='Respostas ao formulário 1'!B19 -> dianbattisti@hotmail.com | D19: ='Respostas ao formulário 1'!O5 -> 34236 | E19: ='Respostas ao formulário 1'!Q5 -> MATUPÁ | F19: ='Respostas ao formulário 1'!R5 -> Gestão municipal
A20: =Form_Responses1[CPF: XXX.XXX.XXX-XX] -> 031.367.381-01 | B20: ='Respostas ao formulário 1'!C20 -> Dian Carla Battisti Pit | C20: ='Respostas ao formulário 1'!B20 -> dianbattisti@hotmail.com | D20: ='Respostas ao formulário 1'!O15 -> 35992 | E20: ='Respostas ao formulário 1'!Q15 -> MATUPÁ | F20: ='Respostas ao formulário 1'!R15 -> Gestão municipal
A21: =Form_Responses1[CPF: XXX.XXX.XXX-XX] -> 925.508.511-53 | B21: ='Respostas ao formulário 1'!C21 -> Dorival Gomes de Souza | C21: ='Respostas ao formulário 1'!B21 -> dorivalgomesmot17@gmail.com | D21: ='Respostas ao formulário 1'!O51 -> 31063 | E21: ='Respostas ao formulário 1'!Q51 -> FELIZ NATAL | F21: ='Respostas ao formulário 1'!R51 -> CACS-FUNDEB
A22: =Form_Responses1[CPF: XXX.XXX.XXX-XX] -> 023.068.921-30 | B22: ='Respostas ao formulário 1'!C22 -> Dulcineia MATHIAS CABRAL | C22: ='Respostas ao formulário 1'!B22 -> dulcisec@gmail.com | D22: ='Respostas ao formulário 1'!O12 -> 27549 | E22: ='Respostas ao formulário 1'!Q12 -> Matupá | F22: ='Respostas ao formulário 1'!R12 -> Gestão Municipal
A23: =Form_Responses1[CPF: XXX.XXX.XXX-XX] -> 299.445.031-34 | B23: ='Respostas ao formulário 1'!C23 -> Edelson manoel de sousa | C23: ='Respostas ao formulário 1'!B23 -> edelsonsousa_@hotmail.com | D23: ='Respostas ao formulário 1'!O19 -> 32723 | E23: ='Respostas ao formulário 1'!Q19 -> NOVA GUARITA | F23: ='Respostas ao formulário 1'!R19 -> Gestão municipal
A24: =Form_Responses1[CPF: XXX.XXX.XXX-XX] -> 299.445.031-34 | B24: ='Respostas ao formulário 1'!C24 -> Edelson manoel de sousa | C24: ='Respostas ao formulário 1'!B24 -> edelsonsousa_@hotmail.com | D24: ='Respostas ao formulário 1'!O20 -> 32723 | E24: ='Respostas ao formulário 1'!Q20 -> NOVA GUARITA | F24: ='Respostas ao formulário 1'!R20 -> Gestão municipal
A25: =Form_Responses1[CPF: XXX.XXX.XXX-XX] -> 061.514.082-33 | B25: ='Respostas ao formulário 1'!C25 -> Felipe Ricardo de Oliveira Morais | C25: ='Respostas ao formulário 1'!B25 -> ricardo.felipeom@gmail.com | D25: ='Respostas ao formulário 1'!O23 -> 23793 | E25: ='Respostas ao formulário 1'!Q23 -> NOVA GUARITA | F25: ='Respostas ao formulário 1'!R23 -> Gestão municipal
A26: =Form_Responses1[CPF: XXX.XXX.XXX-XX] -> 963.391.101-00 | B26: ='Respostas ao formulário 1'!C26 -> Flávia Corrêa da Silveira Lopes | C26: ='Respostas ao formulário 1'!B26 -> flavia.lopes@edu.colider.mt.gov.br | D26: ='Respostas ao formulário 1'!O31 -> 24163 | E26: ='Respostas ao formulário 1'!Q31 -> GUARANTÃ DO NORTE | F26: ='Respostas ao formulário 1'!R31 -> CACS-FUNDEB
A27: =Form_Responses1[CPF: XXX.XXX.XXX-XX] -> 042.524.451-24 | B27: ='Respostas ao formulário 1'!C27 -> Francieli Maria Hammes | C27: ='Respostas ao formulário 1'!B27 -> sme.transporteescolarsinop@gmail.com | D27: ='Respostas ao formulário 1'!O24 -> 23793 | E27: ='Respostas ao formulário 1'!Q24 -> NOVA GUARITA | F27: ='Respostas ao formulário 1'!R24 -> Gestão municipal
A28: =Form_Responses1[CPF: XXX.XXX.XXX-XX] -> 064.633.091-84 | B28: ='Respostas ao formulário 1'!C28 -> Giselli Satiko Toyomoto Fujimori | C28: ='Respostas ao formulário 1'!B28 -> gisellifujimori@gmail.com | D28: ='Respostas ao formulário 1'!O17 -> 30887 | E28: ='Respostas ao formulário 1'!Q17 -> NOVA MARINGÁ | F28: ='Respostas ao formulário 1'!R17 -> Gestão municipal
A29: =Form_Responses1[CPF: XXX.XXX.XXX-XX] -> 049.578.646-97 | B29: ='Respostas ao formulário 1'!C29 -> Jarlene maria silva matos | C29: ='Respostas ao formulário 1'!B29 -> matosjarlene5@gmail.com | D29: ='Respostas ao formulário 1'!O18 -> 24068 | E29: ='Respostas ao formulário 1'!Q18 -> NOVO MUNDO | F29: ='Respostas ao formulário 1'!R18 -> Gestão municipal
A30: =Form_Responses1[CPF: XXX.XXX.XXX-XX] -> 039.855.061-16 | B30: ='Respostas ao formulário 1'!C30 -> Jefferson Henkes Marcolini | C30: ='Respostas ao formulário 1'!B30 -> jeffersonmarcolinii@hotmail.com | D30: ='Respostas ao formulário 1'!O47 -> 30249 | E30: ='Respostas ao formulário 1'!Q47 -> NOVO MUNDO | F30: ='Respostas ao formulário 1'!R47 -> Gestão municipal
A31: =Form_Responses1[CPF: XXX.XXX.XXX-XX] -> 403.447.891-87 | B31: ='Respostas ao formulário 1'!C31 -> João Marques da Costa | C31: ='Respostas ao formulário 1'!B31 -> joaomarquesdacosta25@gmail.com | D31: ='Respostas ao formulário 1'!O4 -> 35610 | E31: ='Respostas ao formulário 1'!Q4 -> ITANHANGÁ | F31: ='Respostas ao formulário 1'!R4 -> CACS-FUNDEB
A32: =Form_Responses1[CPF: XXX.XXX.XXX-XX] -> 021.159.381-86 | B32: ='Respostas ao formulário 1'!C32 -> Juliana Mazei Silva | C32: ='Respostas ao formulário 1'!B32 -> julianamazei@hotmail.com | D32: ='Respostas ao formulário 1'!O29 -> 28458 | E32: ='Respostas ao formulário 1'!Q29 -> Peixoto de azevedo | F32: ='Respostas ao formulário 1'!R29 -> Gestão municipal
A33: =Form_Responses1[CPF: XXX.XXX.XXX-XX] -> 718.028.431-91 | B33: ='Respostas ao formulário 1'!C33 -> Kamila De Almeida Reis | C33: ='Respostas ao formulário 1'!B33 -> kamilareislima@hotmail.com | D33: ='Respostas ao formulário 1'!O21 -> 28797 | E33: ='Respostas ao formulário 1'!Q21 -> ITANHANGÁ | F33: ='Respostas ao formulário 1'!R21 -> CACS-FUNDEB
A34: =Form_Responses1[CPF: XXX.XXX.XXX-XX] -> 062.569.491-02 | B34: ='Respostas ao formulário 1'!C34 -> KARINA RITA DE BARROS | C34: ='Respostas ao formulário 1'!B34 -> karinabarros772@gmail.com | D34: ='Respostas ao formulário 1'!O3 -> 33322 | E34: ='Respostas ao formulário 1'!Q3 -> MARCELÂNDIA | F34: ='Respostas ao formulário 1'!R3 -> CACS-FUNDEB
A35: =Form_Responses1[CPF: XXX.XXX.XXX-XX] -> 059.504.181-74 | B35: ='Respostas ao formulário 1'!C35 -> Katia nervis guedes | C35: ='Respostas ao formulário 1'!B35 -> katia_nervis@hotmail.com | D35: ='Respostas ao formulário 1'!O7 -> 32799 | E35: ='Respostas ao formulário 1'!Q7 -> MARCELÂNDIA | F35: ='Respostas ao formulário 1'!R7 -> CACS-FUNDEB
A36: =Form_Responses1[CPF: XXX.XXX.XXX-XX] -> 059.504.181-74 | B36: ='Respostas ao formulário 1'!C36 -> Katia nervis guedes | C36: ='Respostas ao formulário 1'!B36 -> katia_nervis@hotmail.com | D36: ='Respostas ao formulário 1'!O35 -> 34437 | E36: ='Respostas ao formulário 1'!Q35 -> NOVA GUARITA | F36: ='Respostas ao formulário 1'!R35 -> CACS-FUNDEB
A37: =Form_Responses1[CPF: XXX.XXX.XXX-XX] -> 036.728.641-61 | B37: ='Respostas ao formulário 1'!C37 -> Lilian Cláudia Pereira de Oliveira | C37: ='Respostas ao formulário 1'!B37 -> lilianclaudia77@gmail.com | D37: ='Respostas ao formulário 1'!O36 -> 34437 | E37: ='Respostas ao formulário 1'!Q36 -> NOVA GUARITA | F37: ='Respostas ao formulário 1'!R36 -> CACS-FUNDEB
A38: =Form_Responses1[CPF: XXX.XXX.XXX-XX] -> 036.728.641-61 | B38: ='Respostas ao formulário 1'!C38 -> Lilian Claudia Pereira de Oliveira | C38: ='Respostas ao formulário 1'!B38 -> liliqnclaudia77@gmail.com | D38: ='Respostas ao formulário 1'!O34 -> 35517 | E38: ='Respostas ao formulário 1'!Q34 -> NOVA MARINGÁ | F38: ='Respostas ao formulário 1'!R34 -> CACS-FUNDEB
A39: =Form_Responses1[CPF: XXX.XXX.XXX-XX] -> 830.654.741-15 | B39: ='Respostas ao formulário 1'!C39 -> Lilian Sayuri Ono | C39: ='Respostas ao formulário 1'!B39 -> onolisayuri@hotmail.com | D39: ='Respostas ao formulário 1'!O37 -> 32554 | E39: ='Respostas ao formulário 1'!Q37 -> NOVO MUNDO | F39: ='Respostas ao formulário 1'!R37 -> CACS-FUNDEB
A40: =Form_Responses1[CPF: XXX.XXX.XXX-XX] -> 003.644.911-32 | B40: ='Respostas ao formulário 1'!C40 -> LILIANE KOVALESKI DEVETAK | C40: ='Respostas ao formulário 1'!B40 -> lilianekovaleski_fn@hotmail.com | D40: ='Respostas ao formulário 1'!O38 -> 32554 | E40: ='Respostas ao formulário 1'!Q38 -> NOVO MUNDO | F40: ='Respostas ao formulário 1'!R38 -> CACS-FUNDEB
...

Sheet Página1
A1: Carimbo de data/hora | B1: Endereço de e-mail | C1: Nome Completo: | D1: CPF | E1: Data de Nascimento | F1: Telefone (XX)XXXXX-XXXX | G1: Município que representa: | H1: Você faz parte do: | I1: Que cargo você ocupa na gestão municipal? | J1: Prezado(a) Gestor(a), Se existe algum caso de sucesso da gestão do transporte escolar no seu município, gostaríamos conhecer mais um pouco ao respeito. Por favor, relate de forma sucinta o caso de sucesso no espaço a seguir: | K1: Que cargo você ocupa no CACS-FUNDEB? | L1: Coluna 11
A2: 45811.455 | B2: marinaldo_bio@hotmail.com | C2: MARINALDO BATISTA SILVA | D2: 631.914.661-34 | E2: 27050 | F2: (66)99663-1117 | G2: SANTA CARMEM | H2: CACS-FUNDEB | K2: PRESIDENTE
A3: 45811.601 | B3: lilianekovaleski_fn@hotmail.com | C3: LILIANE KOVALESKI DEVETAK | D3: 003.644.911-32 | E3: 30103 | F3: (66)99959-7479 | G3: FELIZ NATAL | H3: CACS-FUNDEB | K3: MEMBRO
A4: 45811.602 | B4: rosangelatricolman@gmail.com | C4: Rosangela Triburtino Colman Barbiero | D4: 019.191.411-89 | E4: 31063 | F4: (66)99630-2479 | G4: FELIZ NATAL | H4: CACS-FUNDEB | K4: Presidente
A5: 45811.615 | B5: irafsilva@hotmail.com | C5: Iracema de Fatima da Silva | D5: 435.059.379-91 | E5: 22243 | F5: (66)99684-9622 | G5: FELIZ NATAL | H5: Gestão municipal | I5: tecnica | K5: membro
A6: 45811.671 | B6: cristinabryan140@gmail.com | C6: Ana Cristina Silva valente | D6: 011.159.092-23 | E6: 34236 | F6: (66)99256-4288 | G6: MATUPÁ | H6: Gestão municipal | I6: supervisora do transporte escolar | J6: o nosso sucesso e estar atingindo o numero da nossa frota todos os veiculos com ar-condicionado, sendo que todos e frota própria.
A7: 45811.695 | B7: daianar775@gmail.com | C7: Daiana Ribeiro Reis Barbosa | D7: 058.310.541-60 | E7: 35992 | F7: (66)99622-4787 | G7: MATUPÁ | H7: Gestão municipal | I7: Coordenador de departamento
A8: 45812.712 | B8: lucivanimarangoniperuzzo@yahoo.com.br | C8: Lucivani Marangoni Peruzzo | D8: 031.834.809-80 | E8: 30134 | F8: (66)99205-3703 | G8: UNIÃO DO SUL | H8: Gestão municipal | I8: Gestão do Transcolar | J8: Em parceria com os motoristas do transporte escolar, gestão, direção, coordenação, secretaria escolar, pais de alunos conseguimos georreferenciar 100% dos alunos.
A9: 45812.735 | B9: dianbattisti@hotmail.com | C9: DIAN CARLA BATTISTI PIT | D9: 031.367.381-01 | E9: 32723 | F9: (66)98433-1211 | G9: NOVA GUARITA | H9: Gestão municipal | I9: Assistente Administrativo e técnica educacional
A10: 45812.738 | B10: rosiane.lima@edu.mt.gov.br | C10: Rosiane Aparecida Pereira de Lima | D10: 048.622.131-89 | E10: 34262 | F10: (66)99248-5664 | G10: UNIÃO DO SUL | H10: CACS-FUNDEB | K10: Presidente do Conselho CASC-FUNDEB
A11: 45812.741 | B11: chambo_@hotmail.com | C11: VANIA CONCEIÇÃO DE SOUZA CHAMBO | D11: 915.060.421-04 | E11: 27524 | F11: (66)99956-2229 | G11: PEIXOTO DE AZEVEDO | H11: CACS-FUNDEB | K11: PRESIDENTE
A12: 45812.741 | B12: debora_ge11@hotmail.com | C12: Debora Goncalves Lopes Nogueira | D12: 038.659.701-41 | E12: 32880 | F12: (66)99979-9337 | G12: PEIXOTO DE AZEVEDO | H12: CACS-FUNDEB | K12: Representante do poder executivo municipal
A13: 45812.743 | B13: rosieiredevianavitor@gmail.com | C13: ROSIE IREDE VIANA VITOR | D13: 928.811.491-20 | E13: 29671 | F13: (66)99662-5421 | G13: PEIXOTO DE AZEVEDO | H13: Gestão municipal | I13: TÉCNICA ADMINISTRATIVA
A14: 45812.744 | B14: matosjarlene5@gmail.com | C14: Jarlene Maria Silva Matos | D14: 044.378.578-97 | E14: 28458 | F14: (66)99966-6774 | G14: PEIXOTO DE AZEVEDO | H14: Gestão municipal | I14: Técnica do transporte escolar | J14: Alcance no georefeciamento com exito com 100% na rede municipal e estadual.
A15: 45812.8 | B15: rosangelatricolman@gmail.com | C15: Rosangela Triburtino Colman Barbiero | D15: 019.191.411-89 | E15: 31063 | F15: (66)99630-2479 | G15: FELIZ NATAL | H15: CACS-FUNDEB | K15: Presidente
A16: 45813.371 | B16: antoniolopesdepaulanatan@gmail.com | C16: Natan Antonio Lopes de Paula | D16: 062.166.941-54 | E16: 36348 | F16: (66)99257-6097 | G16: SINOP | H16: Gestão municipal | I16: tecnico administrativo
A17: 45813.422 | B17: karinabarros772@gmail.com | C17: KARINA RITA DE BARROS | D17: 062.569.491-02 | E17: 35517 | F17: (66)98128-9477 | G17: NOVA MARINGÁ | H17: CACS-FUNDEB | K17: REPRESENTANTE TÉCNICO ADMINISTRATIVO
A18: 45813.442 | B18: deibsoncampos@hotmail.com | C18: Deibson Clei de Campos | D18: 000.733.161-48 | E18: 30887 | F18: (66)98115-9365 | G18: NOVA MARINGÁ | H18: Gestão municipal | I18: Gerente de Frotas
A19: 45815.708 | B19: anaclaudiagermano26@gmail.com | C19: Ana Claudia Germano Alves | D19: 047.152.811-04 | E19: 35610 | F19: (66)98470-1708 | G19: ITANHANGÁ | H19: CACS-FUNDEB | K19: Presidente
A20: 45817.407 | B20: pauloslped@hotmail.com | C20: Paulo Sérgio leite | D20: 655.744.511-15 | E20: 26517 | F20: (66)99999-0901 | G20: TERRA NOVA DO NORTE | H20: CACS-FUNDEB | K20: Presidente
A21: 45817.409 | B21: neussania.oliveira@itanhanga.edu.mt.gov.br | C21: Neussania Silva de Oliveira | D21: 818.354.421-53 | E21: 29275 | F21: (66)98453-5699 | G21: ITANHANGÁ | H21: Gestão municipal | I21: técnico transcolar
A22: 45817.584 | B22: adriana.aparecida1213@gmail.com | C22: Adriana Aparecida da Silva | D22: 046.567.311-29 | E22: 35021 | F22: (66)98405-5326 | G22: ITANHANGÁ | H22: Gestão municipal | I22: DIRETOR DE DEPARTAMENTO
A23: 45817.747 | B23: jeffersonmarcolinii@hotmail.com | C23: Jefferson Henkes Marcolini | D23: 039.855.061-16 | E23: 33795 | F23: (66)99624-2997 | G23: TERRA NOVA DO NORTE | H23: Gestão municipal | I23: Secretário Adjunto
A24: 45818.597 | B24: dulcineia.cabral@guarantadonorte.edu.mt.gov.br | C24: DULCINEIA MATHIAS CABRAL | D24: 023.068.921-30 | E24: 29775 | F24: (66)98467-3867 | G24: GUARANTÃ DO NORTE | H24: Gestão municipal | I24: TEC administrativa responsável pelo sistema
A25: 45819.423 | B25: veruskagoncalves@hotmail.com | C25: Veruska Aparecida Gonçalves | D25: 592.558.971-87 | E25: 26682 | F25: (66)99906-1722 | G25: NOVA UBIRATÃ | H25: Gestão municipal | I25: GESTÃO TRANSPORTE
A26: 45819.551 | B26: gisellifujimori@gmail.com | C26: Giselli Satiko Toyomoto Fujimori | D26: 064.633.091-84 | E26: 38376 | F26: (66)99221-0876 | G26: SINOP | H26: Gestão municipal | I26: Técnico do transcolar
A27: 45819.65 | B27: ivetebergamini@hotmail.com | C27: IVETE SCHNEIDER BERGAMINI | D27: 905.312.641-49 | E27: 27047 | F27: (66)99917-4443 | G27: SANTA CARMEM | H27: Gestão municipal | I27: SECRETÁRIA DE EDUCAÇÃO | J27: ônibus quase todos novos
A28: 45819.686 | B28: claudimiro.freitas@edu.mt.gov.br | C28: Claudimiro Neves de Freitas | D28: 021.934.271-78 | E28: 32244 | F28: (66)99997-2630 | G28: SINOP | H28: Gestão municipal | I28: Professor Técnico de Regime de colaboração com os Municípios
A29: 45819.687 | B29: mony.fer@hotmail.com | C29: Simony Fernanda Fontana Palenschi | D29: 016.236.381-86 | E29: 32075 | F29: (66)99657-2254 | G29: GUARANTÃ DO NORTE | H29: Gestão municipal | I29: Técnica de Prestação de contas PNATE e Caminho da Escola | J29: Não
A30: 45820.699 | B30: educacao@marcelandia.mt.gov.br | C30: Sandra Borsari | D30: 029.829.039-11 | E30: 28627 | F30: (66)99673-4425 | G30: MARCELÂNDIA | H30: Gestão municipal | I30: Secretária de Educação
A31: 45820.701 | B31: educacao@marcelandia.mt.gov.br | C31: Sandra Belusso Casagrande | D31: 933.784.590-34 | E31: 28551 | F31: (66)99969-8914 | G31: MARCELÂNDIA | H31: Gestão municipal | I31: Técnica Administrativa Educacional
A32: 45820.707 | B32: educacao@marcelandia.mt.gov.br | C32: Ana Claudia Dalmolin | D32: 039.487.011-56 | E32: 33322 | F32: (66)99660-6600 | G32: MARCELÂNDIA | H32: CACS-FUNDEB | K32: Presidente do Conselho do FUNDEB
A33: 45820.712 | B33: educacao@marcelandia.mt.gov.br | C33: Ana Paula Tavares da Camara Canguçu | D33: 031.269.751-19 | E33: 32799 | F33: (66)99724-7789 | G33: MARCELÂNDIA | H33: CACS-FUNDEB | K33: Técnica Administrativa Educacional
A34: 45820.83 | B34: noadir.funez@edu.mt.gov.br | C34: Noadir Josenira Tedesco Funez | D34: 768.855.340-00 | E34: 25882 | F34: (66)99985-6712 | G34: SORRISO | H34: CACS-FUNDEB | K34: Secretaria executiva
A35: 45821.305 | B35: se.educa@itanhanga.mt.gov.br | C35: Silvana Maria Dalmolin Wöhl | D35: 019.526.759-10 | E35: 27696 | F35: (66)98412-4026 | G35: ITANHANGÁ | H35: Gestão municipal | I35: Secretária | J35: Ainda não...
A36: 45821.41 | B36: transporte@educa.novomundo.mt.gov.br | C36: Oteniel de Jesus Santos | D36: 740.979.112-87 | E36: 30249 | F36: (66)99202-8229 | G36: NOVO MUNDO | H36: Gestão municipal | I36: Chefe da Divisão do Transporte Escolar | J36: Em relação a comunicação com os pais dos alunos na captura da geolocalização. Nosso município desenvolveu um sistema para capturar automaticamente todas as informações do aluno e responsável e sua geolocalização. Enviamos para os pais um link de um formulário, onde os responsáveis preenchem com nome completo, nome do aluno, nome da escola e turma. O próprio formulário captura a localização atual no ato do preenchimento. Quando o formulário é submetido, todas as informações são enviadas para o WhatsApp do gestor agilizando a comunicação e atualização das informações no sistema. Antes as conversas do WhatsApp eram relativamente longas, onde pediamos o nome, depois de obter a resposta era nos eviado a escola e turma e assim por diante. Com o formulário tudo é enviado de uma só vez. Caso queiram conferir o link é: https://transporte-escolar-2025.vercel.app
A37: 45824.423 | B37: sec.educacao@novomundo.mt.gov.br | C37: Denise Bortolozzo Dalazen | D37: 534.183.109-82 | E37: 24068 | F37: (66)99292-5879 | G37: NOVO MUNDO | H37: Gestão municipal | I37: Técnica Prestação de Contas PDDE
A38: 45825.457 | B38: aldenimachado2@gmail.com | C38: aldeni morais machado santana | D38: 042.871.251-77 | E38: 34644 | F38: (66)99931-4023 | G38: COLÍDER | H38: Gestão municipal | I38: assesor de gabinete
A39: 45825.459 | B39: gersoncandidoribeiro1425@gmail.com | C39: Gerson Cândido Ribeiro | D39: 625.283.431-91 | E39: 26853 | F39: (66)99649-4549 | G39: SORRISO | H39: Gestão municipal | I39: Diretor de departamento
A40: 45825.459 | B40: marcelo.gemeos@outlook.com | C40: MARCELO VACARO DE AQUINO | D40: 972.706.101-00 | E40: 29502 | F40: (66)99675-7252 | G40: COLÍDER | H40: Gestão municipal | I40: COMPRAS/ TRANSCOLAR
...
